Workbook

Sheet 0
A1: sausio | B1: Sausis | C1: I | D1: 2025 | I1: 1 | AG1: 0 | AH1: ale | AI1: Jurijus Aleksejevas, D.
A2: vasario | B2: Vasaris | C2: II | D2: 2026 | I2: 16 | AG2: 0 | AH2: ale | AI2: Jurijus Aleksejevas, N.
A3: kovo | B3: Kovas | C3: III | D3: 2027 | I3: 11 | K3: =IF(B29=3,B28,"") | AG3: 0 | AH3: bac | AI3: Dalius Bacevičius, D.
A4: balandžio | B4: Balandis | C4: IV | D4: 2028 | K4: =IF(B29=4,B28,IF(K3=31,1,"")) -> 5 | AG4: 0 | AH4: bac | AI4: Dalius Bacevičius, N.
A5: gegužės | B5: Gegužė | D5: 2029 | I5: 1 | AG5: 0 | AH5: čep | AI5: Agnė Čepukė, D.
A6: birželio | B6: Birželis | D6: 2030 | I6: 26 | AG6: 0 | AH6: čep | AI6: Agnė Čepukė, N.
A7: liepos | B7: Liepa | D7: 2031 | I7: 6 | AG7: 0 | AH7: jok | AI7: Vitalija Jokubynienė, D.
A8: rugpjūčio | B8: Rugpjūtis | D8: 2032 | I8: 15 | AG8: 0 | AH8: jok | AI8: Vitalija Jokubynienė, N.
A9: rugsėjo | B9: Rugsėjis | D9: 2033 | AG9: 0 | AH9: kiu | AI9: Aidas Kiukys, D.
A10: spalio | B10: Spalis | D10: 2034 | AG10: 0 | AH10: kiu | AI10: Aidas Kiukys, N.
A11: lapkričio | B11: Lapkritis | D11: 2035 | I11: 1 | J11: 2 | AG11: 0 | AH11: mas | AI11: Evaldas Maskeliūnas, D.
A12: gruodžio | B12: Gruodis | D12: 2036 | I12: 24 | J12: 25 | K12: 26 | AG12: 0 | AH12: mas | AI12: Evaldas Maskeliūnas, N.
D13: 2037 | AG13: 0 | AH13: men | AI13: Laura Mendelienė, D.
D14: 2038 | AG14: 0 | AH14: men | AI14: Laura Mendelienė, N.
D15: 2039 | AG15: 0 | AH15: mer | AI15: Saulius Merkininkas, D.
D16: PASAULIO PAB. | AG16: 0 | AH16: mer | AI16: Saulius Merkininkas, N.
A17: Velyku skaiciuokle | AG17: 0 | AH17: pil | AI17: Jurgita Pilypaitienė, D.
AG18: 0 | AH18: pil | AI18: Jurgita Pilypaitienė, N.
A19: Metai | B19: =Dinamika!$B$1 -> 2026 | D19: Dienos eilutes | E19: 8 | AG19: 0 | AH19: saj | AI19: Giedrė Sajetaitė, D.
A20: a | B20: =MOD(B19,19) -> 12 | AG20: 0 | AH20: saj | AI20: Giedrė Sajetaitė, N.
A21: b | B21: =TRUNC(B19/4) -> 506 | AG21: 0 | AH21: šed | AI21: Vaidas Šeduikis, D.
A22: c | B22: =TRUNC(B21/25)+1 -> 21 | AG22: 0 | AH22: šed | AI22: Vaidas Šeduikis, N.
A23: d | B23: =TRUNC(B22*3/4) -> 15 | AG23: 0 | AH23: žur | AI23: Tomas Žuramskas, D.
A24: e1 | B24: =MOD((B20*19)-(TRUNC((B22*8+5)/25)+B23+15),30) -> 12 | AG24: 0 | AH24: žur | AI24: Tomas Žuramskas, N.
A25: e2 | B25: =B24+TRUNC((29578-B20-B24*32)/1024) -> 40 | AG25: 9 | AH25: kau | AI25: Kauno apskr. VPK
A26: e3 | B26: =B25-MOD((MOD(B19,7)+B21-B23+B25+2),7) -> 36 | AG26: 9 | AH26: mar | AI26: Marijampolės apskr. VPK Vilkaviškio r. PK
A27: d | B27: =TRUNC(B26/32) -> 1 | AG27: 9 | AH27: pan | AI27: Panevėžio apskr. VPK
A28: diena | B28: =B26-B27*31 -> 5 | AG28: 9 | AH28: vil | AI28: Vilniaus apskr. VPK
A29: menuo | B29: =B27+3 -> 4
A31: Velykos | B31: =DATE(B19,B29,B28) -> 46117
A109: Metai | B109: Menuo skaičium | C109: Dienų sk. | F109: Menuo
A110: =Dinamika!$B$1 -> 2026 | B110: 1 | C110: =DAY(EOMONTH(DATE(A110,B110,1),0)) -> 31 | F110: =CHOOSE($B110,$B$1,$B$2,$B$3,$B$4,$B$5,$B$6,$B$7,$B$8,$B$9,$B$10,$B$11,$B$12) -> Sausis
A111: =CHOOSE($B110,$B$1,$B$2,$B$3,$B$4,$B$5,$B$6,$B$7,$B$8,$B$9,$B$10,$B$11,$B$12) -> Sausis | B111: 1 | C111: =B111+1 -> 2 | D111: =C111+1 -> 3 | E111: =D111+1 -> 4 | F111: =E111+1 -> 5 | G111: =F111+1 -> 6 | H111: =G111+1 -> 7 | I111: =H111+1 -> 8 | J111: =I111+1 -> 9 | ... AC111: =AB111+1 -> 28 | AD111: =IF(ABS(AC111)<$C110,AC111+1,-AC111+1) -> 29 | AE111: =IF(ABS(AD111)<$C110,AD111+1,-AD111+1) -> 30 | AF111: =IF(ABS(AE111)<$C110,AE111+1,-AE111+1) -> 31
A112: =A111 -> Sausis | B112: =IF(B111>0,IF(OR(OFFSET($I$1,$B110-1,0)=B111,OFFSET($I$1,$B110-1,1)=B111,OFFSET($I$1,$B110-1,2)=B111),"SV",CHOOSE(WEEKDAY(DATE($A110,$B110,B111),2),"--","--","--","--","--","SS","SK")),"XX") -> SV | C112: =IF(C111>0,IF(OR(OFFSET($I$1,$B110-1,0)=C111,OFFSET($I$1,$B110-1,1)=C111,OFFSET($I$1,$B110-1,2)=C111),"SV",CHOOSE(WEEKDAY(DATE($A110,$B110,C111),2),"--","--","--","--","--","SS","SK")),"XX") -> -- | D112: =IF(D111>0,IF(OR(OFFSET($I$1,$B110-1,0)=D111,OFFSET($I$1,$B110-1,1)=D111,OFFSET($I$1,$B110-1,2)=D111),"SV",CHOOSE(WEEKDAY(DATE($A110,$B110,D111),2),"--","--","--","--","--","SS","SK")),"XX") -> SS | E112: =IF(E111>0,IF(OR(OFFSET($I$1,$B110-1,0)=E111,OFFSET($I$1,$B110-1,1)=E111,OFFSET($I$1,$B110-1,2)=E111),"SV",CHOOSE(WEEKDAY(DATE($A110,$B110,E111),2),"--","--","--","--","--","SS","SK")),"XX") -> SK | F112: =IF(F111>0,IF(OR(OFFSET($I$1,$B110-1,0)=F111,OFFSET($I$1,$B110-1,1)=F111,OFFSET($I$1,$B110-1,2)=F111),"SV",CHOOSE(WEEKDAY(DATE($A110,$B110,F111),2),"--","--","--","--","--","SS","SK")),"XX") -> -- | G112: =IF(G111>0,IF(OR(OFFSET($I$1,$B110-1,0)=G111,OFFSET($I$1,$B110-1,1)=G111,OFFSET($I$1,$B110-1,2)=G111),"SV",CHOOSE(WEEKDAY(DATE($A110,$B110,G111),2),"--","--","--","--","--","SS","SK")),"XX") -> -- | H112: =IF(H111>0,IF(OR(OFFSET($I$1,$B110-1,0)=H111,OFFSET($I$1,$B110-1,1)=H111,OFFSET($I$1,$B110-1,2)=H111),"SV",CHOOSE(WEEKDAY(DATE($A110,$B110,H111),2),"--","--","--","--","--","SS","SK")),"XX") -> -- | I112: =IF(I111>0,IF(OR(OFFSET($I$1,$B110-1,0)=I111,OFFSET($I$1,$B110-1,1)=I111,OFFSET($I$1,$B110-1,2)=I111),"SV",CHOOSE(WEEKDAY(DATE($A110,$B110,I111),2),"--","--","--","--","--","SS","SK")),"XX") -> -- | ... AF112: =IF(AF111>0,IF(OR(OFFSET($I$1,$B110-1,0)=AF111,OFFSET($I$1,$B110-1,1)=AF111,OFFSET($I$1,$B110-1,2)=AF111),"SV",CHOOSE(WEEKDAY(DATE($A110,$B110,AF111),2),"--","--","--","--","--","SS","SK")),"XX") -> SS
A113: =ROW(#REF!)-1 -> #REF! | B113: =ROW(#REF!)-1 -> #REF! | C113: =ROW(#REF!)-1 -> #REF! | D113: =ROW(#REF!)-1 -> #REF! | E113: =ROW(#REF!)-1 -> #REF! | F113: =ROW(#REF!)-1 -> #REF! | G113: =ROW(#REF!)-1 -> #REF! | H113: =ROW(#REF!)-1 -> #REF! | ... AF113: =ROW(#REF!)-1 -> #REF!
A119: Metai | B119: Menuo skaičium | C119: Dienų sk. | F119: Menuo
A120: =Dinamika!$B$1 -> 2026 | B120: 2 | C120: =DAY(EOMONTH(DATE(A120,B120,1),0)) -> 28 | F120: =CHOOSE($B120,$B$1,$B$2,$B$3,$B$4,$B$5,$B$6,$B$7,$B$8,$B$9,$B$10,$B$11,$B$12) -> Vasaris
A121: =CHOOSE($B120,$B$1,$B$2,$B$3,$B$4,$B$5,$B$6,$B$7,$B$8,$B$9,$B$10,$B$11,$B$12) -> Vasaris | B121: 1 | C121: =B121+1 -> 2 | D121: =C121+1 -> 3 | E121: =D121+1 -> 4 | F121: =E121+1 -> 5 | G121: =F121+1 -> 6 | H121: =G121+1 -> 7 | I121: =H121+1 -> 8 | J121: =I121+1 -> 9 | ... AC121: =AB121+1 -> 28 | AD121: =IF(ABS(AC121)<$C120,AC121+1,-AC121+1) -> -27 | AE121: =IF(ABS(AD121)<$C120,AD121+1,-AD121+1) -> -26 | AF121: =IF(ABS(AE121)<$C120,AE121+1,-AE121+1) -> -25
A122: =A121 -> Vasaris | B122: =IF(B121>0,IF(OR(OFFSET($I$1,$B120-1,0)=B121,OFFSET($I$1,$B120-1,1)=B121,OFFSET($I$1,$B120-1,2)=B121),"SV",CHOOSE(WEEKDAY(DATE($A120,$B120,B121),2),"--","--","--","--","--","SS","SK")),"XX") -> SK | C122: =IF(C121>0,IF(OR(OFFSET($I$1,$B120-1,0)=C121,OFFSET($I$1,$B120-1,1)=C121,OFFSET($I$1,$B120-1,2)=C121),"SV",CHOOSE(WEEKDAY(DATE($A120,$B120,C121),2),"--","--","--","--","--","SS","SK")),"XX") -> -- | D122: =IF(D121>0,IF(OR(OFFSET($I$1,$B120-1,0)=D121,OFFSET($I$1,$B120-1,1)=D121,OFFSET($I$1,$B120-1,2)=D121),"SV",CHOOSE(WEEKDAY(DATE($A120,$B120,D121),2),"--","--","--","--","--","SS","SK")),"XX") -> -- | E122: =IF(E121>0,IF(OR(OFFSET($I$1,$B120-1,0)=E121,OFFSET($I$1,$B120-1,1)=E121,OFFSET($I$1,$B120-1,2)=E121),"SV",CHOOSE(WEEKDAY(DATE($A120,$B120,E121),2),"--","--","--","--","--","SS","SK")),"XX") -> -- | F122: =IF(F121>0,IF(OR(OFFSET($I$1,$B120-1,0)=F121,OFFSET($I$1,$B120-1,1)=F121,OFFSET($I$1,$B120-1,2)=F121),"SV",CHOOSE(WEEKDAY(DATE($A120,$B120,F121),2),"--","--","--","--","--","SS","SK")),"XX") -> -- | G122: =IF(G121>0,IF(OR(OFFSET($I$1,$B120-1,0)=G121,OFFSET($I$1,$B120-1,1)=G121,OFFSET($I$1,$B120-1,2)=G121),"SV",CHOOSE(WEEKDAY(DATE($A120,$B120,G121),2),"--","--","--","--","--","SS","SK")),"XX") -> -- | H122: =IF(H121>0,IF(OR(OFFSET($I$1,$B120-1,0)=H121,OFFSET($I$1,$B120-1,1)=H121,OFFSET($I$1,$B120-1,2)=H121),"SV",CHOOSE(WEEKDAY(DATE($A120,$B120,H121),2),"--","--","--","--","--","SS","SK")),"XX") -> SS | I122: =IF(I121>0,IF(OR(OFFSET($I$1,$B120-1,0)=I121,OFFSET($I$1,$B120-1,1)=I121,OFFSET($I$1,$B120-1,2)=I121),"SV",CHOOSE(WEEKDAY(DATE($A120,$B120,I121),2),"--","--","--","--","--","SS","SK")),"XX") -> SK | ... AF122: =IF(AF121>0,IF(OR(OFFSET($I$1,$B120-1,0)=AF121,OFFSET($I$1,$B120-1,1)=AF121,OFFSET($I$1,$B120-1,2)=AF121),"SV",CHOOSE(WEEKDAY(DATE($A120,$B120,AF121),2),"--","--","--","--","--","SS","SK")),"XX") -> XX
A123: =ROW(#REF!)-1 -> #REF! | B123: =ROW(#REF!)-1 -> #REF! | C123: =ROW(#REF!)-1 -> #REF! | D123: =ROW(#REF!)-1 -> #REF! | E123: =ROW(#REF!)-1 -> #REF! | F123: =ROW(#REF!)-1 -> #REF! | G123: =ROW(#REF!)-1 -> #REF! | H123: =ROW(#REF!)-1 -> #REF! | ... AF123: =ROW(#REF!)-1 -> #REF!
...

Sheet Bendras metų
Q1: Psw:sukciai
D3: <== + - prie šiandienos | U3: Praeitų mėn. Žalos | V3: =SUM(V6:V16,L253) -> #REF!
B4: Sukčiavimo pranešimų apdorojimas
B5: =CONCATENATE(YEAR(NOW()+C3)," m. ",OFFSET('0'!A1,MONTH(NOW()+C3)-1,0)," mėn. ",DAY(NOW()+C3)," d.") -> 2026 m. sausio mėn. 1 d. | U5: mėn.
C6: per praėjusią parą | D6: Iš viso nuo 2026-01-01 d. | U6: 1 | V6: =#REF! -> #REF!
B7: Paimti ROIK pranešimai (skaičius) | C7: =INDIRECT(ADDRESS(OFFSET('0'!$B$113,(MONTH(NOW()+C3)-1)*10,DAY(NOW()+C3)-1)+1,4,4,TRUE,OFFSET('0'!$B$1,MONTH(NOW()+C3)-1,0))) -> #REF! | D7: =Q23 -> #REF! | F7: C5, C7, C8, C9, C10, C11, C12, C13, C14, C15, C16, C17, C18 | I7: langelius nepildyti naktį dirbančiam darbuotojui nuo 00 val iki 5 val ryto | U7: 2 | V7: =#REF! -> #REF!
B8: Apdorota įvykių nuotoliu | C8: =INDIRECT(ADDRESS(OFFSET('0'!$B$113,(MONTH(NOW()+C3)-1)*10,DAY(NOW()+C3)-1)+1,5,4,TRUE,OFFSET('0'!$B$1,MONTH(NOW()+C3)-1,0))) -> #REF! | D8: =Q24 -> #REF! | F8: Duomenys automatiškai persikelia iš kitų lentelių | U8: 3 | V8: =#REF! -> #REF!
B9: Tikslinamos aplinkybės (M) | C9: =INDIRECT(ADDRESS(OFFSET('0'!$B$113,(MONTH(NOW()+C3)-1)*10,DAY(NOW()+C3)-1)+1,15,4,TRUE,OFFSET('0'!$B$1,MONTH(NOW()+C3)-1,0))) -> #REF! | D9: =Q25 -> #REF! | U9: 4 | V9: =#REF! -> #REF!
B10: Pradėta IT | C10: =INDIRECT(ADDRESS(OFFSET('0'!$B$113,(MONTH(NOW()+C3)-1)*10,DAY(NOW()+C3)-1)+1,16,4,TRUE,OFFSET('0'!$B$1,MONTH(NOW()+C3)-1,0))) -> #REF! | D10: =Q26 -> #REF! | U10: 5 | V10: =#REF! -> #REF!
B11: Informuotos kitos institucijos, iš jų: | C11: =INDIRECT(ADDRESS(OFFSET('0'!$B$113,(MONTH(NOW()+C3)-1)*10,DAY(NOW()+C3)-1)+1,6,4,TRUE,OFFSET('0'!$B$1,MONTH(NOW()+C3)-1,0))) -> #REF! | D11: =Q27 -> #REF! | U11: 6 | V11: =#REF! -> #REF!
B12: Bankas | C12: =INDIRECT(ADDRESS(OFFSET('0'!$B$113,(MONTH(NOW()+C3)-1)*10,DAY(NOW()+C3)-1),6,4,TRUE,OFFSET('0'!$B$1,MONTH(NOW()+C3)-1,0))) -> #REF! | D12: =Q28 -> #REF! | U12: 7 | V12: =#REF! -> #REF!
B13: RRT | C13: =INDIRECT(ADDRESS(OFFSET('0'!$B$113,(MONTH(NOW()+C3)-1)*10,DAY(NOW()+C3)-1),7,4,TRUE,OFFSET('0'!$B$1,MONTH(NOW()+C3)-1,0))) -> #REF! | D13: =Q29 -> #REF! | U13: 8 | V13: =#REF! -> #REF!
B14: FNTT | C14: =INDIRECT(ADDRESS(OFFSET('0'!$B$113,(MONTH(NOW()+C3)-1)*10,DAY(NOW()+C3)-1),8,4,TRUE,OFFSET('0'!$B$1,MONTH(NOW()+C3)-1,0))) -> #REF! | D14: =Q30 -> #REF! | U14: 9 | V14: =#REF! -> #REF!
B15: NKSC | C15: =INDIRECT(ADDRESS(OFFSET('0'!$B$113,(MONTH(NOW()+C3)-1)*10,DAY(NOW()+C3)-1),9,4,TRUE,OFFSET('0'!$B$1,MONTH(NOW()+C3)-1,0))) -> #REF! | D15: =Q31 -> #REF! | U15: 10 | V15: =#REF! -> #REF!
B16: Facebook | C16: =INDIRECT(ADDRESS(OFFSET('0'!$B$113,(MONTH(NOW()+C3)-1)*10,DAY(NOW()+C3)-1),10,4,TRUE,OFFSET('0'!$B$1,MONTH(NOW()+C3)-1,0))) -> #REF! | D16: =Q32 -> #REF! | U16: 11 | V16: =#REF! -> #REF!
B17: Kita | C17: =INDIRECT(ADDRESS(OFFSET('0'!$B$113,(MONTH(NOW()+C3)-1)*10,DAY(NOW()+C3)-1),11,4,TRUE,OFFSET('0'!$B$1,MONTH(NOW()+C3)-1,0))) -> #REF! | D17: =Q33 -> #REF!
B18: Pasisavintų lėšų suma, Eur (visų pranešimų) * | C18: =INDIRECT(ADDRESS(OFFSET('0'!$B$113,(MONTH(NOW()+C3)-1)*10,DAY(NOW()+C3)-1)+1,12,4,TRUE,OFFSET('0'!$B$1,MONTH(NOW()+C3)-1,0))) -> #REF! | D18: =Q34 -> #REF!
B19: * Preliminari žala, pateikta pagal pirminę pranešėjų informaciją
D21: METŲ REZULTATAS
E22: Sausis | F22: Vasaris | G22: Kovas | H22: Balandis | I22: Gegužė | J22: Birželis | K22: Liepa | L22: Rugpjūtis | M22: Rugsėjis | N22: Spalis | O22: Lapkritis | P22: Gruodis | Q22: VISO | R22: VISO ANKŠČIAU
D23: Paimti ROIK pranešimai (skaičius) | E23: =#REF! -> #REF! | F23: =#REF! -> #REF! | G23: =#REF! -> #REF! | H23: =#REF! -> #REF! | I23: =#REF! -> #REF! | J23: =#REF! -> #REF! | K23: =#REF! -> #REF! | L23: =#REF! -> #REF! | ... P23: =#REF! -> #REF! | Q23: =SUM(E23:P23,R23) -> #REF!
D24: Apdorota įvykių nuotoliu | E24: =#REF! -> #REF! | F24: =#REF! -> #REF! | G24: =#REF! -> #REF! | H24: =#REF! -> #REF! | I24: =#REF! -> #REF! | J24: =#REF! -> #REF! | K24: =#REF! -> #REF! | L24: =#REF! -> #REF! | ... P24: =#REF! -> #REF! | Q24: =SUM(E24:P24,R24) -> #REF!
D25: Tikslinamos aplinkybės (M) | E25: =#REF! -> #REF! | F25: =#REF! -> #REF! | G25: =#REF! -> #REF! | H25: =#REF! -> #REF! | I25: =#REF! -> #REF! | J25: =#REF! -> #REF! | K25: =#REF! -> #REF! | L25: =#REF! -> #REF! | ... P25: =#REF! -> #REF! | Q25: =SUM(E25:P25,R25) -> #REF!
D26: Pradėta IT | E26: =#REF! -> #REF! | F26: =#REF! -> #REF! | G26: =#REF! -> #REF! | H26: =#REF! -> #REF! | I26: =#REF! -> #REF! | J26: =#REF! -> #REF! | K26: =#REF! -> #REF! | L26: =#REF! -> #REF! | ... P26: =#REF! -> #REF! | Q26: =SUM(E26:P26,R26) -> #REF!
D27: Informuotos kitos institucijos | E27: =#REF! -> #REF! | F27: =#REF! -> #REF! | G27: =#REF! -> #REF! | H27: =#REF! -> #REF! | I27: =#REF! -> #REF! | J27: =#REF! -> #REF! | K27: =#REF! -> #REF! | L27: =#REF! -> #REF! | ... P27: =#REF! -> #REF! | Q27: =SUM(E27:P27,R27) -> #REF!
D28: Bankas | E28: =#REF! -> #REF! | F28: =#REF! -> #REF! | G28: =#REF! -> #REF! | H28: =#REF! -> #REF! | I28: =#REF! -> #REF! | J28: =#REF! -> #REF! | K28: =#REF! -> #REF! | L28: =#REF! -> #REF! | ... P28: =#REF! -> #REF! | Q28: =SUM(E28:P28,R28) -> #REF!
D29: RRT | E29: =#REF! -> #REF! | F29: =#REF! -> #REF! | G29: =#REF! -> #REF! | H29: =#REF! -> #REF! | I29: =#REF! -> #REF! | J29: =#REF! -> #REF! | K29: =#REF! -> #REF! | L29: =#REF! -> #REF! | ... P29: =#REF! -> #REF! | Q29: =SUM(E29:P29,R29) -> #REF!
D30: FNTT | E30: =#REF! -> #REF! | F30: =#REF! -> #REF! | G30: =#REF! -> #REF! | H30: =#REF! -> #REF! | I30: =#REF! -> #REF! | J30: =#REF! -> #REF! | K30: =#REF! -> #REF! | L30: =#REF! -> #REF! | ... P30: =#REF! -> #REF! | Q30: =SUM(E30:P30,R30) -> #REF!
D31: NKSC | E31: =#REF! -> #REF! | F31: =#REF! -> #REF! | G31: =#REF! -> #REF! | H31: =#REF! -> #REF! | I31: =#REF! -> #REF! | J31: =#REF! -> #REF! | K31: =#REF! -> #REF! | L31: =#REF! -> #REF! | ... P31: =#REF! -> #REF! | Q31: =SUM(E31:P31,R31) -> #REF!
D32: Facebook | E32: =#REF! -> #REF! | F32: =#REF! -> #REF! | G32: =#REF! -> #REF! | H32: =#REF! -> #REF! | I32: =#REF! -> #REF! | J32: =#REF! -> #REF! | K32: =#REF! -> #REF! | L32: =#REF! -> #REF! | ... P32: =#REF! -> #REF! | Q32: =SUM(E32:P32,R32) -> #REF!
D33: Kita | E33: =#REF! -> #REF! | F33: =#REF! -> #REF! | G33: =#REF! -> #REF! | H33: =#REF! -> #REF! | I33: =#REF! -> #REF! | J33: =#REF! -> #REF! | K33: =#REF! -> #REF! | L33: =#REF! -> #REF! | ... P33: =#REF! -> #REF! | Q33: =SUM(E33:P33,R33) -> #REF!
D34: Pasisavintų lėšų suma (visų pranešimų) | E34: =#REF! -> #REF! | F34: =#REF! -> #REF! | G34: =#REF! -> #REF! | H34: =#REF! -> #REF! | I34: =#REF! -> #REF! | J34: =#REF! -> #REF! | K34: =#REF! -> #REF! | L34: =#REF! -> #REF! | ... P34: =#REF! -> #REF! | Q34: =SUM(E34:P34,R34) -> #REF!
K36: METŲ REZULTATŲ LENTELĖS PVV3 DARBUOTOJAMS NEPILDYTI (turėtų skaičiuoti automatiškai)

Sheet Sausis
A1: 1
B2: Mėnesio diena | C2: Vardas, pavardė. Pamaina D/N | D2: Paimti ROIK pranešimai (skaičius) | E2: Apdorota | F2: INFORMUOTA | L2: Pasisavintų lėšų suma (visų pranešimų) | M2: Neapdorota (siųstos pajėgos) | N2: Kontrolinis | O2: Tikslinamos aplinkybės (M) | P2: Pradėta IT | Q2: Pastabos | T2: Kontr. Kasdienė eilutė (Žalos)
F3: Bankas | G3: RRT | H3: FNTT | I3: NKSC | J3: Facebook | K3: Kita/įrašyti | U3: Praeitų mėn. Žalos | V3: 0
A4: =OFFSET('0'!$B$112,($A$1-1)*10,$B4-1) -> SV | B4: =OFFSET('0'!$B$111,($A$1-1)*10,0) -> 1 | L4: 1 | M4: =SUM(D4-E4) -> 0 | N4: =SUM(E4,M4) -> 0
M5: =SUM(D5-E5) -> 0 | N5: =SUM(E5,M5) -> 0 | U5: mėn.
M6: =SUM(D6-E6) -> 0 | N6: =SUM(E6,M6) -> 0 | U6: 1 | V6: =Sausis!L254 -> 1
M7: =SUM(D7-E7) -> 0 | N7: =SUM(E7,M7) -> 0 | U7: 2
M8: =SUM(D8-E8) -> 0 | N8: =SUM(E8,M8) -> 0 | U8: 3
M9: =SUM(D9-E9) -> 0 | N9: =SUM(E9,M9) -> 0 | U9: 4
C10: Iš viso Lietuvoje: | D10: =SUM(D4:D9) -> 0 | E10: =SUM(E4:E9) -> 0 | F10: =SUM(F4:F9) -> 0 | G10: =SUM(G4:G9) -> 0 | H10: =SUM(H4:H9) -> 0 | I10: =SUM(I4:I9) -> 0 | J10: =SUM(J4:J9) -> 0 | K10: =SUM(K4:K9) -> 0 | ... N10: =SUM(N4:N9) -> 0 | U10: 5
C11: dienos foto | D11: =SUM(D4:D9) -> 0 | E11: =SUM(E4:E9) -> 0 | F11: =SUM(F10:K10) -> 0 | L11: =SUM(L4:L9) -> 1 | M11: =SUM(M4:M9) -> 0 | N11: =SUM(N4:N9) -> 0 | O11: =SUM(O4) -> 0 | P11: =SUM(P4) -> 0 | T11: =$V$3+L11 -> 1 | U11: 6
A12: =OFFSET('0'!$B$112,($A$1-1)*10,$B12-1) -> -- | B12: =OFFSET('0'!$B$111,($A$1-1)*10,1) -> 2 | M12: =SUM(D12-E12) -> 0 | N12: =SUM(E12,M12) -> 0 | U12: 7
M13: =SUM(D13-E13) -> 0 | N13: =SUM(E13,M13) -> 0 | U13: 8
M14: =SUM(D14-E14) -> 0 | N14: =SUM(E14,M14) -> 0 | U14: 9
M15: =SUM(D15-E15) -> 0 | N15: =SUM(E15,M15) -> 0 | U15: 10
M16: =SUM(D16-E16) -> 0 | N16: =SUM(E16,M16) -> 0 | U16: 11
M17: =SUM(D17-E17) -> 0 | N17: =SUM(E17,M17) -> 0
C18: Iš viso Lietuvoje: | D18: =SUM(D12:D17) -> 0 | E18: =SUM(E12:E17) -> 0 | F18: =SUM(F12:F17) -> 0 | G18: =SUM(G12:G17) -> 0 | H18: =SUM(H12:H17) -> 0 | I18: =SUM(I12:I17) -> 0 | J18: =SUM(J12:J17) -> 0 | K18: =SUM(K12:K17) -> 0 | ... N18: =SUM(N12:N17) -> 0
C19: dienos foto | D19: =SUM(D12:D17) -> 0 | E19: =SUM(E12:E17) -> 0 | F19: =SUM(F18:K18) -> 0 | L19: =SUM(L12:L17) -> 0 | M19: =SUM(M12:M17) -> 0 | N19: =SUM(N12:N17) -> 0 | O19: =SUM(O12) -> 0 | P19: =SUM(P12) -> 0 | T19: =$V$3+L11+L19 -> 1
A20: =OFFSET('0'!$B$112,($A$1-1)*10,$B20-1) -> SS | B20: =OFFSET('0'!$B$111,($A$1-1)*10,2) -> 3 | M20: =SUM(D20-E20) -> 0 | N20: =SUM(E20,M20) -> 0
M21: =SUM(D21-E21) -> 0 | N21: =SUM(E21,M21) -> 0
M22: =SUM(D22-E22) -> 0 | N22: =SUM(E22,M22) -> 0
M23: =SUM(D23-E23) -> 0 | N23: =SUM(E23,M23) -> 0
M24: =SUM(D24-E24) -> 0 | N24: =SUM(E24,M24) -> 0
M25: =SUM(D25-E25) -> 0 | N25: =SUM(E25,M25) -> 0
C26: Iš viso Lietuvoje: | D26: =SUM(D20:D25) -> 0 | E26: =SUM(E20:E25) -> 0 | F26: =SUM(F20:F25) -> 0 | G26: =SUM(G20:G25) -> 0 | H26: =SUM(H20:H25) -> 0 | I26: =SUM(I20:I25) -> 0 | J26: =SUM(J20:J25) -> 0 | K26: =SUM(K20:K25) -> 0 | ... N26: =SUM(N20:N25) -> 0
C27: dienos foto | D27: =SUM(D20:D25) -> 0 | E27: =SUM(E20:E25) -> 0 | F27: =SUM(F26:K26) -> 0 | L27: =SUM(L20:L25) -> 0 | M27: =SUM(M20:M25) -> 0 | N27: =SUM(N20:N25) -> 0 | O27: =SUM(O20) -> 0 | P27: =SUM(P20) -> 0 | T27: =$V$3++L11+L19+L27 -> 1
A28: =OFFSET('0'!$B$112,($A$1-1)*10,$B28-1) -> SK | B28: =OFFSET('0'!$B$111,($A$1-1)*10,3) -> 4 | M28: =SUM(D28-E28) -> 0 | N28: =SUM(E28,M28) -> 0
M29: =SUM(D29-E29) -> 0 | N29: =SUM(E29,M29) -> 0
M30: =SUM(D30-E30) -> 0 | N30: =SUM(E30,M30) -> 0
M31: =SUM(D31-E31) -> 0 | N31: =SUM(E31,M31) -> 0
M32: =SUM(D32-E32) -> 0 | N32: =SUM(E32,M32) -> 0
M33: =SUM(D33-E33) -> 0 | N33: =SUM(E33,M33) -> 0
C34: Iš viso Lietuvoje: | D34: =SUM(D28:D33) -> 0 | E34: =SUM(E28:E33) -> 0 | F34: =SUM(F28:F33) -> 0 | G34: =SUM(G28:G33) -> 0 | H34: =SUM(H28:H33) -> 0 | I34: =SUM(I28:I33) -> 0 | J34: =SUM(J28:J33) -> 0 | K34: =SUM(K28:K33) -> 0 | ... N34: =SUM(N28:N33) -> 0
C35: dienos foto | D35: =SUM(D28:D33) -> 0 | E35: =SUM(E28:E33) -> 0 | F35: =SUM(F34:K34) -> 0 | L35: =SUM(L28:L33) -> 0 | M35: =SUM(M28:M33) -> 0 | N35: =SUM(N28:N33) -> 0 | O35: =SUM(O28) -> 0 | P35: =SUM(P28) -> 0 | T35: =$V$3+L11+L19+L27+L35 -> 1
A36: =OFFSET('0'!$B$112,($A$1-1)*10,$B36-1) -> -- | B36: =OFFSET('0'!$B$111,($A$1-1)*10,4) -> 5 | M36: =SUM(D36-E36) -> 0 | N36: =SUM(E36,M36) -> 0
M37: =SUM(D37-E37) -> 0 | N37: =SUM(E37,M37) -> 0
M38: =SUM(D38-E38) -> 0 | N38: =SUM(E38,M38) -> 0
M39: =SUM(D39-E39) -> 0 | N39: =SUM(E39,M39) -> 0
M40: =SUM(D40-E40) -> 0 | N40: =SUM(E40,M40) -> 0
...

Sheet Vasaris
A1: 2
B2: Mėnesio diena | C2: Vardas, pavardė. Pamaina D/N | D2: Paimti ROIK pranešimai (skaičius) | E2: Apdorota | F2: INFORMUOTA | L2: Pasisavintų lėšų suma (visų pranešimų) | M2: Neapdorota (siųstos pajėgos) | N2: Kontrolinis | O2: Tikslinamos aplinkybės (M) | P2: Pradėta IT | Q2: Pastabos | T2: Kontr. Kasdienė eilutė (Žalos)
F3: Bankas | G3: RRT | H3: FNTT | I3: NKSC | J3: Facebook | K3: Kita/įrašyti | U3: Praeitų mėn. Žalos | V3: =SUM(V6:V6) -> 1
A4: =OFFSET('0'!$B$112,($A$1-1)*10,$B4-1) -> SK | B4: =OFFSET('0'!$B$111,($A$1-1)*10,0) -> 1 | L4: 2 | M4: =SUM(D4-E4) -> 0 | N4: =SUM(E4,M4) -> 0
M5: =SUM(D5-E5) -> 0 | N5: =SUM(E5,M5) -> 0 | U5: mėn.
M6: =SUM(D6-E6) -> 0 | N6: =SUM(E6,M6) -> 0 | U6: 1 | V6: =Sausis!L254 -> 1
M7: =SUM(D7-E7) -> 0 | N7: =SUM(E7,M7) -> 0 | U7: 2 | V7: =Vasaris!L254 -> 2
M8: =SUM(D8-E8) -> 0 | N8: =SUM(E8,M8) -> 0 | U8: 3
M9: =SUM(D9-E9) -> 0 | N9: =SUM(E9,M9) -> 0 | U9: 4
C10: Iš viso Lietuvoje: | D10: =SUM(D4:D9) -> 0 | E10: =SUM(E4:E9) -> 0 | F10: =SUM(F4:F9) -> 0 | G10: =SUM(G4:G9) -> 0 | H10: =SUM(H4:H9) -> 0 | I10: =SUM(I4:I9) -> 0 | J10: =SUM(J4:J9) -> 0 | K10: =SUM(K4:K9) -> 0 | ... N10: =SUM(N4:N9) -> 0 | U10: 5
C11: dienos foto | D11: =SUM(D4:D9) -> 0 | E11: =SUM(E4:E9) -> 0 | F11: =SUM(F10:K10) -> 0 | L11: =SUM(L4:L9) -> 2 | M11: =SUM(M4:M9) -> 0 | N11: =SUM(N4:N9) -> 0 | O11: =SUM(O4) -> 0 | P11: =SUM(P4) -> 0 | T11: =$V$3+L11 -> 3 | U11: 6
A12: =OFFSET('0'!$B$112,($A$1-1)*10,$B12-1) -> -- | B12: =OFFSET('0'!$B$111,($A$1-1)*10,1) -> 2 | M12: =SUM(D12-E12) -> 0 | N12: =SUM(E12,M12) -> 0 | U12: 7
M13: =SUM(D13-E13) -> 0 | N13: =SUM(E13,M13) -> 0 | U13: 8
M14: =SUM(D14-E14) -> 0 | N14: =SUM(E14,M14) -> 0 | U14: 9
M15: =SUM(D15-E15) -> 0 | N15: =SUM(E15,M15) -> 0 | U15: 10
M16: =SUM(D16-E16) -> 0 | N16: =SUM(E16,M16) -> 0 | U16: 11
M17: =SUM(D17-E17) -> 0 | N17: =SUM(E17,M17) -> 0
C18: Iš viso Lietuvoje: | D18: =SUM(D12:D17) -> 0 | E18: =SUM(E12:E17) -> 0 | F18: =SUM(F12:F17) -> 0 | G18: =SUM(G12:G17) -> 0 | H18: =SUM(H12:H17) -> 0 | I18: =SUM(I12:I17) -> 0 | J18: =SUM(J12:J17) -> 0 | K18: =SUM(K12:K17) -> 0 | ... N18: =SUM(N12:N17) -> 0
C19: dienos foto | D19: =SUM(D12:D17) -> 0 | E19: =SUM(E12:E17) -> 0 | F19: =SUM(F18:K18) -> 0 | L19: =SUM(L12:L17) -> 0 | M19: =SUM(M12:M17) -> 0 | N19: =SUM(N12:N17) -> 0 | O19: =SUM(O12) -> 0 | P19: =SUM(P12) -> 0 | T19: =$V$3+L11+L19 -> 3
A20: =OFFSET('0'!$B$112,($A$1-1)*10,$B20-1) -> -- | B20: =OFFSET('0'!$B$111,($A$1-1)*10,2) -> 3 | M20: =SUM(D20-E20) -> 0 | N20: =SUM(E20,M20) -> 0
M21: =SUM(D21-E21) -> 0 | N21: =SUM(E21,M21) -> 0
M22: =SUM(D22-E22) -> 0 | N22: =SUM(E22,M22) -> 0
M23: =SUM(D23-E23) -> 0 | N23: =SUM(E23,M23) -> 0
M24: =SUM(D24-E24) -> 0 | N24: =SUM(E24,M24) -> 0
M25: =SUM(D25-E25) -> 0 | N25: =SUM(E25,M25) -> 0
C26: Iš viso Lietuvoje: | D26: =SUM(D20:D25) -> 0 | E26: =SUM(E20:E25) -> 0 | F26: =SUM(F20:F25) -> 0 | G26: =SUM(G20:G25) -> 0 | H26: =SUM(H20:H25) -> 0 | I26: =SUM(I20:I25) -> 0 | J26: =SUM(J20:J25) -> 0 | K26: =SUM(K20:K25) -> 0 | ... N26: =SUM(N20:N25) -> 0
C27: dienos foto | D27: =SUM(D20:D25) -> 0 | E27: =SUM(E20:E25) -> 0 | F27: =SUM(F26:K26) -> 0 | L27: =SUM(L20:L25) -> 0 | M27: =SUM(M20:M25) -> 0 | N27: =SUM(N20:N25) -> 0 | O27: =SUM(O20) -> 0 | P27: =SUM(P20) -> 0 | T27: =$V$3++L11+L19+L27 -> 3
A28: =OFFSET('0'!$B$112,($A$1-1)*10,$B28-1) -> -- | B28: =OFFSET('0'!$B$111,($A$1-1)*10,3) -> 4 | M28: =SUM(D28-E28) -> 0 | N28: =SUM(E28,M28) -> 0
M29: =SUM(D29-E29) -> 0 | N29: =SUM(E29,M29) -> 0
M30: =SUM(D30-E30) -> 0 | N30: =SUM(E30,M30) -> 0
M31: =SUM(D31-E31) -> 0 | N31: =SUM(E31,M31) -> 0
M32: =SUM(D32-E32) -> 0 | N32: =SUM(E32,M32) -> 0
M33: =SUM(D33-E33) -> 0 | N33: =SUM(E33,M33) -> 0
C34: Iš viso Lietuvoje: | D34: =SUM(D28:D33) -> 0 | E34: =SUM(E28:E33) -> 0 | F34: =SUM(F28:F33) -> 0 | G34: =SUM(G28:G33) -> 0 | H34: =SUM(H28:H33) -> 0 | I34: =SUM(I28:I33) -> 0 | J34: =SUM(J28:J33) -> 0 | K34: =SUM(K28:K33) -> 0 | ... N34: =SUM(N28:N33) -> 0
C35: dienos foto | D35: =SUM(D28:D33) -> 0 | E35: =SUM(E28:E33) -> 0 | F35: =SUM(F34:K34) -> 0 | L35: =SUM(L28:L33) -> 0 | M35: =SUM(M28:M33) -> 0 | N35: =SUM(N28:N33) -> 0 | O35: =SUM(O28) -> 0 | P35: =SUM(P28) -> 0 | T35: =$V$3+L11+L19+L27+L35 -> 3
A36: =OFFSET('0'!$B$112,($A$1-1)*10,$B36-1) -> -- | B36: =OFFSET('0'!$B$111,($A$1-1)*10,4) -> 5 | M36: =SUM(D36-E36) -> 0 | N36: =SUM(E36,M36) -> 0
M37: =SUM(D37-E37) -> 0 | N37: =SUM(E37,M37) -> 0
M38: =SUM(D38-E38) -> 0 | N38: =SUM(E38,M38) -> 0
M39: =SUM(D39-E39) -> 0 | N39: =SUM(E39,M39) -> 0
M40: =SUM(D40-E40) -> 0 | N40: =SUM(E40,M40) -> 0
...

Sheet Kovas
A1: 3
B2: Mėnesio diena | C2: Vardas, pavardė. Pamaina D/N | D2: Paimti ROIK pranešimai (skaičius) | E2: Apdorota | F2: INFORMUOTA | L2: Pasisavintų lėšų suma (visų pranešimų) | M2: Neapdorota (siųstos pajėgos) | N2: Kontrolinis | O2: Tikslinamos aplinkybės (M) | P2: Pradėta IT | Q2: Pastabos | T2: Kontr. Kasdienė eilutė (Žalos)
F3: Bankas | G3: RRT | H3: FNTT | I3: NKSC | J3: Facebook | K3: Kita/įrašyti | U3: Praeitų mėn. Žalos | V3: =SUM(V6:V7) -> 3
A4: =OFFSET('0'!$B$112,($A$1-1)*10,$B4-1) -> SK | B4: =OFFSET('0'!$B$111,($A$1-1)*10,0) -> 1 | L4: 3 | M4: =SUM(D4-E4) -> 0 | N4: =SUM(E4,M4) -> 0
M5: =SUM(D5-E5) -> 0 | N5: =SUM(E5,M5) -> 0 | U5: mėn.
M6: =SUM(D6-E6) -> 0 | N6: =SUM(E6,M6) -> 0 | U6: 1 | V6: =Sausis!L254 -> 1
M7: =SUM(D7-E7) -> 0 | N7: =SUM(E7,M7) -> 0 | U7: 2 | V7: =Vasaris!L254 -> 2
M8: =SUM(D8-E8) -> 0 | N8: =SUM(E8,M8) -> 0 | U8: 3 | V8: =Kovas!L254 -> 3
M9: =SUM(D9-E9) -> 0 | N9: =SUM(E9,M9) -> 0 | U9: 4
C10: Iš viso Lietuvoje: | D10: =SUM(D4:D9) -> 0 | E10: =SUM(E4:E9) -> 0 | F10: =SUM(F4:F9) -> 0 | G10: =SUM(G4:G9) -> 0 | H10: =SUM(H4:H9) -> 0 | I10: =SUM(I4:I9) -> 0 | J10: =SUM(J4:J9) -> 0 | K10: =SUM(K4:K9) -> 0 | ... N10: =SUM(N4:N9) -> 0 | U10: 5
C11: dienos foto | D11: =SUM(D4:D9) -> 0 | E11: =SUM(E4:E9) -> 0 | F11: =SUM(F10:K10) -> 0 | L11: =SUM(L4:L9) -> 3 | M11: =SUM(M4:M9) -> 0 | N11: =SUM(N4:N9) -> 0 | O11: =SUM(O4) -> 0 | P11: =SUM(P4) -> 0 | T11: =$V$3+L11 -> 6 | U11: 6
A12: =OFFSET('0'!$B$112,($A$1-1)*10,$B12-1) -> -- | B12: =OFFSET('0'!$B$111,($A$1-1)*10,1) -> 2 | M12: =SUM(D12-E12) -> 0 | N12: =SUM(E12,M12) -> 0 | U12: 7
M13: =SUM(D13-E13) -> 0 | N13: =SUM(E13,M13) -> 0 | U13: 8
M14: =SUM(D14-E14) -> 0 | N14: =SUM(E14,M14) -> 0 | U14: 9
M15: =SUM(D15-E15) -> 0 | N15: =SUM(E15,M15) -> 0 | U15: 10
M16: =SUM(D16-E16) -> 0 | N16: =SUM(E16,M16) -> 0 | U16: 11
M17: =SUM(D17-E17) -> 0 | N17: =SUM(E17,M17) -> 0
C18: Iš viso Lietuvoje: | D18: =SUM(D12:D17) -> 0 | E18: =SUM(E12:E17) -> 0 | F18: =SUM(F12:F17) -> 0 | G18: =SUM(G12:G17) -> 0 | H18: =SUM(H12:H17) -> 0 | I18: =SUM(I12:I17) -> 0 | J18: =SUM(J12:J17) -> 0 | K18: =SUM(K12:K17) -> 0 | ... N18: =SUM(N12:N17) -> 0
C19: dienos foto | D19: =SUM(D12:D17) -> 0 | E19: =SUM(E12:E17) -> 0 | F19: =SUM(F18:K18) -> 0 | L19: =SUM(L12:L17) -> 0 | M19: =SUM(M12:M17) -> 0 | N19: =SUM(N12:N17) -> 0 | O19: =SUM(O12) -> 0 | P19: =SUM(P12) -> 0 | T19: =$V$3+L11+L19 -> 6
A20: =OFFSET('0'!$B$112,($A$1-1)*10,$B20-1) -> -- | B20: =OFFSET('0'!$B$111,($A$1-1)*10,2) -> 3 | M20: =SUM(D20-E20) -> 0 | N20: =SUM(E20,M20) -> 0
M21: =SUM(D21-E21) -> 0 | N21: =SUM(E21,M21) -> 0
M22: =SUM(D22-E22) -> 0 | N22: =SUM(E22,M22) -> 0
M23: =SUM(D23-E23) -> 0 | N23: =SUM(E23,M23) -> 0
M24: =SUM(D24-E24) -> 0 | N24: =SUM(E24,M24) -> 0
M25: =SUM(D25-E25) -> 0 | N25: =SUM(E25,M25) -> 0
C26: Iš viso Lietuvoje: | D26: =SUM(D20:D25) -> 0 | E26: =SUM(E20:E25) -> 0 | F26: =SUM(F20:F25) -> 0 | G26: =SUM(G20:G25) -> 0 | H26: =SUM(H20:H25) -> 0 | I26: =SUM(I20:I25) -> 0 | J26: =SUM(J20:J25) -> 0 | K26: =SUM(K20:K25) -> 0 | ... N26: =SUM(N20:N25) -> 0
C27: dienos foto | D27: =SUM(D20:D25) -> 0 | E27: =SUM(E20:E25) -> 0 | F27: =SUM(F26:K26) -> 0 | L27: =SUM(L20:L25) -> 0 | M27: =SUM(M20:M25) -> 0 | N27: =SUM(N20:N25) -> 0 | O27: =SUM(O20) -> 0 | P27: =SUM(P20) -> 0 | T27: =$V$3++L11+L19+L27 -> 6
A28: =OFFSET('0'!$B$112,($A$1-1)*10,$B28-1) -> -- | B28: =OFFSET('0'!$B$111,($A$1-1)*10,3) -> 4 | M28: =SUM(D28-E28) -> 0 | N28: =SUM(E28,M28) -> 0
M29: =SUM(D29-E29) -> 0 | N29: =SUM(E29,M29) -> 0
M30: =SUM(D30-E30) -> 0 | N30: =SUM(E30,M30) -> 0
M31: =SUM(D31-E31) -> 0 | N31: =SUM(E31,M31) -> 0
M32: =SUM(D32-E32) -> 0 | N32: =SUM(E32,M32) -> 0
M33: =SUM(D33-E33) -> 0 | N33: =SUM(E33,M33) -> 0
C34: Iš viso Lietuvoje: | D34: =SUM(D28:D33) -> 0 | E34: =SUM(E28:E33) -> 0 | F34: =SUM(F28:F33) -> 0 | G34: =SUM(G28:G33) -> 0 | H34: =SUM(H28:H33) -> 0 | I34: =SUM(I28:I33) -> 0 | J34: =SUM(J28:J33) -> 0 | K34: =SUM(K28:K33) -> 0 | ... N34: =SUM(N28:N33) -> 0
C35: dienos foto | D35: =SUM(D28:D33) -> 0 | E35: =SUM(E28:E33) -> 0 | F35: =SUM(F34:K34) -> 0 | L35: =SUM(L28:L33) -> 0 | M35: =SUM(M28:M33) -> 0 | N35: =SUM(N28:N33) -> 0 | O35: =SUM(O28) -> 0 | P35: =SUM(P28) -> 0 | T35: =$V$3+L11+L19+L27+L35 -> 6
A36: =OFFSET('0'!$B$112,($A$1-1)*10,$B36-1) -> -- | B36: =OFFSET('0'!$B$111,($A$1-1)*10,4) -> 5 | M36: =SUM(D36-E36) -> 0 | N36: =SUM(E36,M36) -> 0
M37: =SUM(D37-E37) -> 0 | N37: =SUM(E37,M37) -> 0
M38: =SUM(D38-E38) -> 0 | N38: =SUM(E38,M38) -> 0
M39: =SUM(D39-E39) -> 0 | N39: =SUM(E39,M39) -> 0
M40: =SUM(D40-E40) -> 0 | N40: =SUM(E40,M40) -> 0
...

Sheet Balandis
A1: 4
B2: Mėnesio diena | C2: Vardas, pavardė. Pamaina D/N | D2: Paimti ROIK pranešimai (skaičius) | E2: Apdorota | F2: INFORMUOTA | L2: Pasisavintų lėšų suma (visų pranešimų) | M2: Neapdorota (siųstos pajėgos) | N2: Kontrolinis | O2: Tikslinamos aplinkybės (M) | P2: Pradėta IT | Q2: Pastabos | T2: Kontr. Kasdienė eilutė (Žalos)
F3: Bankas | G3: RRT | H3: FNTT | I3: NKSC | J3: Facebook | K3: Kita/įrašyti | U3: Praeitų mėn. Žalos | V3: =SUM(V6:V8) -> 6
A4: =OFFSET('0'!$B$112,($A$1-1)*10,$B4-1) -> -- | B4: =OFFSET('0'!$B$111,($A$1-1)*10,0) -> 1 | L4: 4 | M4: =SUM(D4-E4) -> 0 | N4: =SUM(E4,M4) -> 0
M5: =SUM(D5-E5) -> 0 | N5: =SUM(E5,M5) -> 0 | U5: mėn.
M6: =SUM(D6-E6) -> 0 | N6: =SUM(E6,M6) -> 0 | U6: 1 | V6: =Sausis!L254 -> 1
M7: =SUM(D7-E7) -> 0 | N7: =SUM(E7,M7) -> 0 | U7: 2 | V7: =Vasaris!L254 -> 2
M8: =SUM(D8-E8) -> 0 | N8: =SUM(E8,M8) -> 0 | U8: 3 | V8: =Kovas!L254 -> 3
M9: =SUM(D9-E9) -> 0 | N9: =SUM(E9,M9) -> 0 | U9: 4 | V9: =Balandis!L254 -> 4
C10: Iš viso Lietuvoje: | D10: =SUM(D4:D9) -> 0 | E10: =SUM(E4:E9) -> 0 | F10: =SUM(F4:F9) -> 0 | G10: =SUM(G4:G9) -> 0 | H10: =SUM(H4:H9) -> 0 | I10: =SUM(I4:I9) -> 0 | J10: =SUM(J4:J9) -> 0 | K10: =SUM(K4:K9) -> 0 | ... N10: =SUM(N4:N9) -> 0 | U10: 5
C11: dienos foto | D11: =SUM(D4:D9) -> 0 | E11: =SUM(E4:E9) -> 0 | F11: =SUM(F10:K10) -> 0 | L11: =SUM(L4:L9) -> 4 | M11: =SUM(M4:M9) -> 0 | N11: =SUM(N4:N9) -> 0 | O11: =SUM(O4) -> 0 | P11: =SUM(P4) -> 0 | T11: =$V$3+L11 -> 10 | U11: 6
A12: =OFFSET('0'!$B$112,($A$1-1)*10,$B12-1) -> -- | B12: =OFFSET('0'!$B$111,($A$1-1)*10,1) -> 2 | M12: =SUM(D12-E12) -> 0 | N12: =SUM(E12,M12) -> 0 | U12: 7
M13: =SUM(D13-E13) -> 0 | N13: =SUM(E13,M13) -> 0 | U13: 8
M14: =SUM(D14-E14) -> 0 | N14: =SUM(E14,M14) -> 0 | U14: 9
M15: =SUM(D15-E15) -> 0 | N15: =SUM(E15,M15) -> 0 | U15: 10
M16: =SUM(D16-E16) -> 0 | N16: =SUM(E16,M16) -> 0 | U16: 11
M17: =SUM(D17-E17) -> 0 | N17: =SUM(E17,M17) -> 0
C18: Iš viso Lietuvoje: | D18: =SUM(D12:D17) -> 0 | E18: =SUM(E12:E17) -> 0 | F18: =SUM(F12:F17) -> 0 | G18: =SUM(G12:G17) -> 0 | H18: =SUM(H12:H17) -> 0 | I18: =SUM(I12:I17) -> 0 | J18: =SUM(J12:J17) -> 0 | K18: =SUM(K12:K17) -> 0 | ... N18: =SUM(N12:N17) -> 0
C19: dienos foto | D19: =SUM(D12:D17) -> 0 | E19: =SUM(E12:E17) -> 0 | F19: =SUM(F18:K18) -> 0 | L19: =SUM(L12:L17) -> 0 | M19: =SUM(M12:M17) -> 0 | N19: =SUM(N12:N17) -> 0 | O19: =SUM(O12) -> 0 | P19: =SUM(P12) -> 0 | T19: =$V$3+L11+L19 -> 10
A20: =OFFSET('0'!$B$112,($A$1-1)*10,$B20-1) -> -- | B20: =OFFSET('0'!$B$111,($A$1-1)*10,2) -> 3 | M20: =SUM(D20-E20) -> 0 | N20: =SUM(E20,M20) -> 0
M21: =SUM(D21-E21) -> 0 | N21: =SUM(E21,M21) -> 0
M22: =SUM(D22-E22) -> 0 | N22: =SUM(E22,M22) -> 0
M23: =SUM(D23-E23) -> 0 | N23: =SUM(E23,M23) -> 0
M24: =SUM(D24-E24) -> 0 | N24: =SUM(E24,M24) -> 0
M25: =SUM(D25-E25) -> 0 | N25: =SUM(E25,M25) -> 0
C26: Iš viso Lietuvoje: | D26: =SUM(D20:D25) -> 0 | E26: =SUM(E20:E25) -> 0 | F26: =SUM(F20:F25) -> 0 | G26: =SUM(G20:G25) -> 0 | H26: =SUM(H20:H25) -> 0 | I26: =SUM(I20:I25) -> 0 | J26: =SUM(J20:J25) -> 0 | K26: =SUM(K20:K25) -> 0 | ... N26: =SUM(N20:N25) -> 0
C27: dienos foto | D27: =SUM(D20:D25) -> 0 | E27: =SUM(E20:E25) -> 0 | F27: =SUM(F26:K26) -> 0 | L27: =SUM(L20:L25) -> 0 | M27: =SUM(M20:M25) -> 0 | N27: =SUM(N20:N25) -> 0 | O27: =SUM(O20) -> 0 | P27: =SUM(P20) -> 0 | T27: =$V$3++L11+L19+L27 -> 10
A28: =OFFSET('0'!$B$112,($A$1-1)*10,$B28-1) -> SS | B28: =OFFSET('0'!$B$111,($A$1-1)*10,3) -> 4 | M28: =SUM(D28-E28) -> 0 | N28: =SUM(E28,M28) -> 0
M29: =SUM(D29-E29) -> 0 | N29: =SUM(E29,M29) -> 0
M30: =SUM(D30-E30) -> 0 | N30: =SUM(E30,M30) -> 0
M31: =SUM(D31-E31) -> 0 | N31: =SUM(E31,M31) -> 0
M32: =SUM(D32-E32) -> 0 | N32: =SUM(E32,M32) -> 0
M33: =SUM(D33-E33) -> 0 | N33: =SUM(E33,M33) -> 0
C34: Iš viso Lietuvoje: | D34: =SUM(D28:D33) -> 0 | E34: =SUM(E28:E33) -> 0 | F34: =SUM(F28:F33) -> 0 | G34: =SUM(G28:G33) -> 0 | H34: =SUM(H28:H33) -> 0 | I34: =SUM(I28:I33) -> 0 | J34: =SUM(J28:J33) -> 0 | K34: =SUM(K28:K33) -> 0 | ... N34: =SUM(N28:N33) -> 0
C35: dienos foto | D35: =SUM(D28:D33) -> 0 | E35: =SUM(E28:E33) -> 0 | F35: =SUM(F34:K34) -> 0 | L35: =SUM(L28:L33) -> 0 | M35: =SUM(M28:M33) -> 0 | N35: =SUM(N28:N33) -> 0 | O35: =SUM(O28) -> 0 | P35: =SUM(P28) -> 0 | T35: =$V$3+L11+L19+L27+L35 -> 10
A36: =OFFSET('0'!$B$112,($A$1-1)*10,$B36-1) -> SV | B36: =OFFSET('0'!$B$111,($A$1-1)*10,4) -> 5 | M36: =SUM(D36-E36) -> 0 | N36: =SUM(E36,M36) -> 0
M37: =SUM(D37-E37) -> 0 | N37: =SUM(E37,M37) -> 0
M38: =SUM(D38-E38) -> 0 | N38: =SUM(E38,M38) -> 0
M39: =SUM(D39-E39) -> 0 | N39: =SUM(E39,M39) -> 0
M40: =SUM(D40-E40) -> 0 | N40: =SUM(E40,M40) -> 0
...

Sheet Gegužė
A1: 5
B2: Mėnesio diena | C2: Vardas, pavardė. Pamaina D/N | D2: Paimti ROIK pranešimai (skaičius) | E2: Apdorota | F2: INFORMUOTA | L2: Pasisavintų lėšų suma (visų pranešimų) | M2: Neapdorota (siųstos pajėgos) | N2: Kontrolinis | O2: Tikslinamos aplinkybės (M) | P2: Pradėta IT | Q2: Pastabos | T2: Kontr. Kasdienė eilutė (Žalos)
F3: Bankas | G3: RRT | H3: FNTT | I3: NKSC | J3: Facebook | K3: Kita/įrašyti | U3: Praeitų mėn. Žalos | V3: =SUM(V6:V9) -> 10
A4: =OFFSET('0'!$B$112,($A$1-1)*10,$B4-1) -> SV | B4: =OFFSET('0'!$B$111,($A$1-1)*10,0) -> 1 | L4: 5 | M4: =SUM(D4-E4) -> 0 | N4: =SUM(E4,M4) -> 0
M5: =SUM(D5-E5) -> 0 | N5: =SUM(E5,M5) -> 0 | U5: mėn.
M6: =SUM(D6-E6) -> 0 | N6: =SUM(E6,M6) -> 0 | U6: 1 | V6: =Sausis!L254 -> 1
M7: =SUM(D7-E7) -> 0 | N7: =SUM(E7,M7) -> 0 | U7: 2 | V7: =Vasaris!L254 -> 2
M8: =SUM(D8-E8) -> 0 | N8: =SUM(E8,M8) -> 0 | U8: 3 | V8: =Kovas!L254 -> 3
M9: =SUM(D9-E9) -> 0 | N9: =SUM(E9,M9) -> 0 | U9: 4 | V9: =Balandis!L254 -> 4
C10: Iš viso Lietuvoje: | D10: =SUM(D4:D9) -> 0 | E10: =SUM(E4:E9) -> 0 | F10: =SUM(F4:F9) -> 0 | G10: =SUM(G4:G9) -> 0 | H10: =SUM(H4:H9) -> 0 | I10: =SUM(I4:I9) -> 0 | J10: =SUM(J4:J9) -> 0 | K10: =SUM(K4:K9) -> 0 | ... N10: =SUM(N4:N9) -> 0 | U10: 5
C11: dienos foto | D11: =SUM(D4:D9) -> 0 | E11: =SUM(E4:E9) -> 0 | F11: =SUM(F10:K10) -> 0 | L11: =SUM(L4:L9) -> 5 | M11: =SUM(M4:M9) -> 0 | N11: =SUM(N4:N9) -> 0 | O11: =SUM(O4) -> 0 | P11: =SUM(P4) -> 0 | T11: =$V$3+L11 -> 15 | U11: 6
A12: =OFFSET('0'!$B$112,($A$1-1)*10,$B12-1) -> SS | B12: =OFFSET('0'!$B$111,($A$1-1)*10,1) -> 2 | M12: =SUM(D12-E12) -> 0 | N12: =SUM(E12,M12) -> 0 | U12: 7
M13: =SUM(D13-E13) -> 0 | N13: =SUM(E13,M13) -> 0 | U13: 8
M14: =SUM(D14-E14) -> 0 | N14: =SUM(E14,M14) -> 0 | U14: 9
M15: =SUM(D15-E15) -> 0 | N15: =SUM(E15,M15) -> 0 | U15: 10
M16: =SUM(D16-E16) -> 0 | N16: =SUM(E16,M16) -> 0 | U16: 11
M17: =SUM(D17-E17) -> 0 | N17: =SUM(E17,M17) -> 0
C18: Iš viso Lietuvoje: | D18: =SUM(D12:D17) -> 0 | E18: =SUM(E12:E17) -> 0 | F18: =SUM(F12:F17) -> 0 | G18: =SUM(G12:G17) -> 0 | H18: =SUM(H12:H17) -> 0 | I18: =SUM(I12:I17) -> 0 | J18: =SUM(J12:J17) -> 0 | K18: =SUM(K12:K17) -> 0 | ... N18: =SUM(N12:N17) -> 0
C19: dienos foto | D19: =SUM(D12:D17) -> 0 | E19: =SUM(E12:E17) -> 0 | F19: =SUM(F18:K18) -> 0 | L19: =SUM(L12:L17) -> 0 | M19: =SUM(M12:M17) -> 0 | N19: =SUM(N12:N17) -> 0 | O19: =SUM(O12) -> 0 | P19: =SUM(P12) -> 0 | T19: =$V$3+L11+L19 -> 15
A20: =OFFSET('0'!$B$112,($A$1-1)*10,$B20-1) -> SK | B20: =OFFSET('0'!$B$111,($A$1-1)*10,2) -> 3 | M20: =SUM(D20-E20) -> 0 | N20: =SUM(E20,M20) -> 0
M21: =SUM(D21-E21) -> 0 | N21: =SUM(E21,M21) -> 0
M22: =SUM(D22-E22) -> 0 | N22: =SUM(E22,M22) -> 0
M23: =SUM(D23-E23) -> 0 | N23: =SUM(E23,M23) -> 0
M24: =SUM(D24-E24) -> 0 | N24: =SUM(E24,M24) -> 0
M25: =SUM(D25-E25) -> 0 | N25: =SUM(E25,M25) -> 0
C26: Iš viso Lietuvoje: | D26: =SUM(D20:D25) -> 0 | E26: =SUM(E20:E25) -> 0 | F26: =SUM(F20:F25) -> 0 | G26: =SUM(G20:G25) -> 0 | H26: =SUM(H20:H25) -> 0 | I26: =SUM(I20:I25) -> 0 | J26: =SUM(J20:J25) -> 0 | K26: =SUM(K20:K25) -> 0 | ... N26: =SUM(N20:N25) -> 0
C27: dienos foto | D27: =SUM(D20:D25) -> 0 | E27: =SUM(E20:E25) -> 0 | F27: =SUM(F26:K26) -> 0 | L27: =SUM(L20:L25) -> 0 | M27: =SUM(M20:M25) -> 0 | N27: =SUM(N20:N25) -> 0 | O27: =SUM(O20) -> 0 | P27: =SUM(P20) -> 0 | T27: =$V$3++L11+L19+L27 -> 15
A28: =OFFSET('0'!$B$112,($A$1-1)*10,$B28-1) -> -- | B28: =OFFSET('0'!$B$111,($A$1-1)*10,3) -> 4 | M28: =SUM(D28-E28) -> 0 | N28: =SUM(E28,M28) -> 0
M29: =SUM(D29-E29) -> 0 | N29: =SUM(E29,M29) -> 0
M30: =SUM(D30-E30) -> 0 | N30: =SUM(E30,M30) -> 0
M31: =SUM(D31-E31) -> 0 | N31: =SUM(E31,M31) -> 0
M32: =SUM(D32-E32) -> 0 | N32: =SUM(E32,M32) -> 0
M33: =SUM(D33-E33) -> 0 | N33: =SUM(E33,M33) -> 0
C34: Iš viso Lietuvoje: | D34: =SUM(D28:D33) -> 0 | E34: =SUM(E28:E33) -> 0 | F34: =SUM(F28:F33) -> 0 | G34: =SUM(G28:G33) -> 0 | H34: =SUM(H28:H33) -> 0 | I34: =SUM(I28:I33) -> 0 | J34: =SUM(J28:J33) -> 0 | K34: =SUM(K28:K33) -> 0 | ... N34: =SUM(N28:N33) -> 0
C35: dienos foto | D35: =SUM(D28:D33) -> 0 | E35: =SUM(E28:E33) -> 0 | F35: =SUM(F34:K34) -> 0 | L35: =SUM(L28:L33) -> 0 | M35: =SUM(M28:M33) -> 0 | N35: =SUM(N28:N33) -> 0 | O35: =SUM(O28) -> 0 | P35: =SUM(P28) -> 0 | T35: =$V$3+L11+L19+L27+L35 -> 15
A36: =OFFSET('0'!$B$112,($A$1-1)*10,$B36-1) -> -- | B36: =OFFSET('0'!$B$111,($A$1-1)*10,4) -> 5 | M36: =SUM(D36-E36) -> 0 | N36: =SUM(E36,M36) -> 0
M37: =SUM(D37-E37) -> 0 | N37: =SUM(E37,M37) -> 0
M38: =SUM(D38-E38) -> 0 | N38: =SUM(E38,M38) -> 0
M39: =SUM(D39-E39) -> 0 | N39: =SUM(E39,M39) -> 0
M40: =SUM(D40-E40) -> 0 | N40: =SUM(E40,M40) -> 0
...

Sheet Birželis
A1: 6
B2: Mėnesio diena | C2: Vardas, pavardė. Pamaina D/N | D2: Paimti ROIK pranešimai (skaičius) | E2: Apdorota | F2: INFORMUOTA | L2: Pasisavintų lėšų suma (visų pranešimų) | M2: Neapdorota (siųstos pajėgos) | N2: Kontrolinis | O2: Tikslinamos aplinkybės (M) | P2: Pradėta IT | Q2: Pastabos | T2: Kontr. Kasdienė eilutė (Žalos)
F3: Bankas | G3: RRT | H3: FNTT | I3: NKSC | J3: Facebook | K3: Kita/įrašyti | U3: Praeitų mėn. Žalos | V3: =SUM(V6:V10) -> 15
A4: =OFFSET('0'!$B$112,($A$1-1)*10,$B4-1) -> -- | B4: =OFFSET('0'!$B$111,($A$1-1)*10,0) -> 1 | L4: 6 | M4: =SUM(D4-E4) -> 0 | N4: =SUM(E4,M4) -> 0
M5: =SUM(D5-E5) -> 0 | N5: =SUM(E5,M5) -> 0 | U5: mėn.
M6: =SUM(D6-E6) -> 0 | N6: =SUM(E6,M6) -> 0 | U6: 1 | V6: =Sausis!L254 -> 1
M7: =SUM(D7-E7) -> 0 | N7: =SUM(E7,M7) -> 0 | U7: 2 | V7: =Vasaris!L254 -> 2
M8: =SUM(D8-E8) -> 0 | N8: =SUM(E8,M8) -> 0 | U8: 3 | V8: =Kovas!L254 -> 3
M9: =SUM(D9-E9) -> 0 | N9: =SUM(E9,M9) -> 0 | U9: 4 | V9: =Balandis!L254 -> 4
C10: Iš viso Lietuvoje: | D10: =SUM(D4:D9) -> 0 | E10: =SUM(E4:E9) -> 0 | F10: =SUM(F4:F9) -> 0 | G10: =SUM(G4:G9) -> 0 | H10: =SUM(H4:H9) -> 0 | I10: =SUM(I4:I9) -> 0 | J10: =SUM(J4:J9) -> 0 | K10: =SUM(K4:K9) -> 0 | ... N10: =SUM(N4:N9) -> 0 | U10: 5 | V10: =Gegužė!L254 -> 5
C11: dienos foto | D11: =SUM(D4:D9) -> 0 | E11: =SUM(E4:E9) -> 0 | F11: =SUM(F10:K10) -> 0 | L11: =SUM(L4:L9) -> 6 | M11: =SUM(M4:M9) -> 0 | N11: =SUM(N4:N9) -> 0 | O11: =SUM(O4) -> 0 | P11: =SUM(P4) -> 0 | T11: =$V$3+L11 -> 21 | U11: 6
A12: =OFFSET('0'!$B$112,($A$1-1)*10,$B12-1) -> -- | B12: =OFFSET('0'!$B$111,($A$1-1)*10,1) -> 2 | M12: =SUM(D12-E12) -> 0 | N12: =SUM(E12,M12) -> 0 | U12: 7
M13: =SUM(D13-E13) -> 0 | N13: =SUM(E13,M13) -> 0 | U13: 8
M14: =SUM(D14-E14) -> 0 | N14: =SUM(E14,M14) -> 0 | U14: 9
M15: =SUM(D15-E15) -> 0 | N15: =SUM(E15,M15) -> 0 | U15: 10
M16: =SUM(D16-E16) -> 0 | N16: =SUM(E16,M16) -> 0 | U16: 11
M17: =SUM(D17-E17) -> 0 | N17: =SUM(E17,M17) -> 0
C18: Iš viso Lietuvoje: | D18: =SUM(D12:D17) -> 0 | E18: =SUM(E12:E17) -> 0 | F18: =SUM(F12:F17) -> 0 | G18: =SUM(G12:G17) -> 0 | H18: =SUM(H12:H17) -> 0 | I18: =SUM(I12:I17) -> 0 | J18: =SUM(J12:J17) -> 0 | K18: =SUM(K12:K17) -> 0 | ... N18: =SUM(N12:N17) -> 0
C19: dienos foto | D19: =SUM(D12:D17) -> 0 | E19: =SUM(E12:E17) -> 0 | F19: =SUM(F18:K18) -> 0 | L19: =SUM(L12:L17) -> 0 | M19: =SUM(M12:M17) -> 0 | N19: =SUM(N12:N17) -> 0 | O19: =SUM(O12) -> 0 | P19: =SUM(P12) -> 0 | T19: =$V$3+L11+L19 -> 21
A20: =OFFSET('0'!$B$112,($A$1-1)*10,$B20-1) -> -- | B20: =OFFSET('0'!$B$111,($A$1-1)*10,2) -> 3 | M20: =SUM(D20-E20) -> 0 | N20: =SUM(E20,M20) -> 0
M21: =SUM(D21-E21) -> 0 | N21: =SUM(E21,M21) -> 0
M22: =SUM(D22-E22) -> 0 | N22: =SUM(E22,M22) -> 0
M23: =SUM(D23-E23) -> 0 | N23: =SUM(E23,M23) -> 0
M24: =SUM(D24-E24) -> 0 | N24: =SUM(E24,M24) -> 0
M25: =SUM(D25-E25) -> 0 | N25: =SUM(E25,M25) -> 0
C26: Iš viso Lietuvoje: | D26: =SUM(D20:D25) -> 0 | E26: =SUM(E20:E25) -> 0 | F26: =SUM(F20:F25) -> 0 | G26: =SUM(G20:G25) -> 0 | H26: =SUM(H20:H25) -> 0 | I26: =SUM(I20:I25) -> 0 | J26: =SUM(J20:J25) -> 0 | K26: =SUM(K20:K25) -> 0 | ... N26: =SUM(N20:N25) -> 0
C27: dienos foto | D27: =SUM(D20:D25) -> 0 | E27: =SUM(E20:E25) -> 0 | F27: =SUM(F26:K26) -> 0 | L27: =SUM(L20:L25) -> 0 | M27: =SUM(M20:M25) -> 0 | N27: =SUM(N20:N25) -> 0 | O27: =SUM(O20) -> 0 | P27: =SUM(P20) -> 0 | T27: =$V$3++L11+L19+L27 -> 21
A28: =OFFSET('0'!$B$112,($A$1-1)*10,$B28-1) -> -- | B28: =OFFSET('0'!$B$111,($A$1-1)*10,3) -> 4 | M28: =SUM(D28-E28) -> 0 | N28: =SUM(E28,M28) -> 0
M29: =SUM(D29-E29) -> 0 | N29: =SUM(E29,M29) -> 0
M30: =SUM(D30-E30) -> 0 | N30: =SUM(E30,M30) -> 0
M31: =SUM(D31-E31) -> 0 | N31: =SUM(E31,M31) -> 0
M32: =SUM(D32-E32) -> 0 | N32: =SUM(E32,M32) -> 0
M33: =SUM(D33-E33) -> 0 | N33: =SUM(E33,M33) -> 0
C34: Iš viso Lietuvoje: | D34: =SUM(D28:D33) -> 0 | E34: =SUM(E28:E33) -> 0 | F34: =SUM(F28:F33) -> 0 | G34: =SUM(G28:G33) -> 0 | H34: =SUM(H28:H33) -> 0 | I34: =SUM(I28:I33) -> 0 | J34: =SUM(J28:J33) -> 0 | K34: =SUM(K28:K33) -> 0 | ... N34: =SUM(N28:N33) -> 0
C35: dienos foto | D35: =SUM(D28:D33) -> 0 | E35: =SUM(E28:E33) -> 0 | F35: =SUM(F34:K34) -> 0 | L35: =SUM(L28:L33) -> 0 | M35: =SUM(M28:M33) -> 0 | N35: =SUM(N28:N33) -> 0 | O35: =SUM(O28) -> 0 | P35: =SUM(P28) -> 0 | T35: =$V$3+L11+L19+L27+L35 -> 21
A36: =OFFSET('0'!$B$112,($A$1-1)*10,$B36-1) -> -- | B36: =OFFSET('0'!$B$111,($A$1-1)*10,4) -> 5 | M36: =SUM(D36-E36) -> 0 | N36: =SUM(E36,M36) -> 0
M37: =SUM(D37-E37) -> 0 | N37: =SUM(E37,M37) -> 0
M38: =SUM(D38-E38) -> 0 | N38: =SUM(E38,M38) -> 0
M39: =SUM(D39-E39) -> 0 | N39: =SUM(E39,M39) -> 0
M40: =SUM(D40-E40) -> 0 | N40: =SUM(E40,M40) -> 0
...

Sheet Liepa
A1: 7
B2: Mėnesio diena | C2: Vardas, pavardė. Pamaina D/N | D2: Paimti ROIK pranešimai (skaičius) | E2: Apdorota | F2: INFORMUOTA | L2: Pasisavintų lėšų suma (visų pranešimų) | M2: Neapdorota (siųstos pajėgos) | N2: Kontrolinis | O2: Tikslinamos aplinkybės (M) | P2: Pradėta IT | Q2: Pastabos | T2: Kontr. Kasdienė eilutė (Žalos)
F3: Bankas | G3: RRT | H3: FNTT | I3: NKSC | J3: Facebook | K3: Kita/įrašyti | U3: Praeitų mėn. Žalos | V3: =SUM(V6:V11) -> 21
A4: =OFFSET('0'!$B$112,($A$1-1)*10,$B4-1) -> -- | B4: =OFFSET('0'!$B$111,($A$1-1)*10,0) -> 1 | L4: 7 | M4: =SUM(D4-E4) -> 0 | N4: =SUM(E4,M4) -> 0
M5: =SUM(D5-E5) -> 0 | N5: =SUM(E5,M5) -> 0 | U5: mėn.
M6: =SUM(D6-E6) -> 0 | N6: =SUM(E6,M6) -> 0 | U6: 1 | V6: =Sausis!L254 -> 1
M7: =SUM(D7-E7) -> 0 | N7: =SUM(E7,M7) -> 0 | U7: 2 | V7: =Vasaris!L254 -> 2
M8: =SUM(D8-E8) -> 0 | N8: =SUM(E8,M8) -> 0 | U8: 3 | V8: =Kovas!L254 -> 3
M9: =SUM(D9-E9) -> 0 | N9: =SUM(E9,M9) -> 0 | U9: 4 | V9: =Balandis!L254 -> 4
C10: Iš viso Lietuvoje: | D10: =SUM(D4:D9) -> 0 | E10: =SUM(E4:E9) -> 0 | F10: =SUM(F4:F9) -> 0 | G10: =SUM(G4:G9) -> 0 | H10: =SUM(H4:H9) -> 0 | I10: =SUM(I4:I9) -> 0 | J10: =SUM(J4:J9) -> 0 | K10: =SUM(K4:K9) -> 0 | ... N10: =SUM(N4:N9) -> 0 | U10: 5 | V10: =Gegužė!L254 -> 5
C11: dienos foto | D11: =SUM(D4:D9) -> 0 | E11: =SUM(E4:E9) -> 0 | F11: =SUM(F10:K10) -> 0 | L11: =SUM(L4:L9) -> 7 | M11: =SUM(M4:M9) -> 0 | N11: =SUM(N4:N9) -> 0 | O11: =SUM(O4) -> 0 | P11: =SUM(P4) -> 0 | T11: =$V$3+L11 -> 28 | U11: 6 | V11: =Birželis!L254 -> 6
A12: =OFFSET('0'!$B$112,($A$1-1)*10,$B12-1) -> -- | B12: =OFFSET('0'!$B$111,($A$1-1)*10,1) -> 2 | M12: =SUM(D12-E12) -> 0 | N12: =SUM(E12,M12) -> 0 | U12: 7
M13: =SUM(D13-E13) -> 0 | N13: =SUM(E13,M13) -> 0 | U13: 8
M14: =SUM(D14-E14) -> 0 | N14: =SUM(E14,M14) -> 0 | U14: 9
M15: =SUM(D15-E15) -> 0 | N15: =SUM(E15,M15) -> 0 | U15: 10
M16: =SUM(D16-E16) -> 0 | N16: =SUM(E16,M16) -> 0 | U16: 11
M17: =SUM(D17-E17) -> 0 | N17: =SUM(E17,M17) -> 0
C18: Iš viso Lietuvoje: | D18: =SUM(D12:D17) -> 0 | E18: =SUM(E12:E17) -> 0 | F18: =SUM(F12:F17) -> 0 | G18: =SUM(G12:G17) -> 0 | H18: =SUM(H12:H17) -> 0 | I18: =SUM(I12:I17) -> 0 | J18: =SUM(J12:J17) -> 0 | K18: =SUM(K12:K17) -> 0 | ... N18: =SUM(N12:N17) -> 0
C19: dienos foto | D19: =SUM(D12:D17) -> 0 | E19: =SUM(E12:E17) -> 0 | F19: =SUM(F18:K18) -> 0 | L19: =SUM(L12:L17) -> 0 | M19: =SUM(M12:M17) -> 0 | N19: =SUM(N12:N17) -> 0 | O19: =SUM(O12) -> 0 | P19: =SUM(P12) -> 0 | T19: =$V$3+L11+L19 -> 28
A20: =OFFSET('0'!$B$112,($A$1-1)*10,$B20-1) -> -- | B20: =OFFSET('0'!$B$111,($A$1-1)*10,2) -> 3 | M20: =SUM(D20-E20) -> 0 | N20: =SUM(E20,M20) -> 0
M21: =SUM(D21-E21) -> 0 | N21: =SUM(E21,M21) -> 0
M22: =SUM(D22-E22) -> 0 | N22: =SUM(E22,M22) -> 0
M23: =SUM(D23-E23) -> 0 | N23: =SUM(E23,M23) -> 0
M24: =SUM(D24-E24) -> 0 | N24: =SUM(E24,M24) -> 0
M25: =SUM(D25-E25) -> 0 | N25: =SUM(E25,M25) -> 0
C26: Iš viso Lietuvoje: | D26: =SUM(D20:D25) -> 0 | E26: =SUM(E20:E25) -> 0 | F26: =SUM(F20:F25) -> 0 | G26: =SUM(G20:G25) -> 0 | H26: =SUM(H20:H25) -> 0 | I26: =SUM(I20:I25) -> 0 | J26: =SUM(J20:J25) -> 0 | K26: =SUM(K20:K25) -> 0 | ... N26: =SUM(N20:N25) -> 0
C27: dienos foto | D27: =SUM(D20:D25) -> 0 | E27: =SUM(E20:E25) -> 0 | F27: =SUM(F26:K26) -> 0 | L27: =SUM(L20:L25) -> 0 | M27: =SUM(M20:M25) -> 0 | N27: =SUM(N20:N25) -> 0 | O27: =SUM(O20) -> 0 | P27: =SUM(P20) -> 0 | T27: =$V$3++L11+L19+L27 -> 28
A28: =OFFSET('0'!$B$112,($A$1-1)*10,$B28-1) -> SS | B28: =OFFSET('0'!$B$111,($A$1-1)*10,3) -> 4 | M28: =SUM(D28-E28) -> 0 | N28: =SUM(E28,M28) -> 0
M29: =SUM(D29-E29) -> 0 | N29: =SUM(E29,M29) -> 0
M30: =SUM(D30-E30) -> 0 | N30: =SUM(E30,M30) -> 0
M31: =SUM(D31-E31) -> 0 | N31: =SUM(E31,M31) -> 0
M32: =SUM(D32-E32) -> 0 | N32: =SUM(E32,M32) -> 0
M33: =SUM(D33-E33) -> 0 | N33: =SUM(E33,M33) -> 0
C34: Iš viso Lietuvoje: | D34: =SUM(D28:D33) -> 0 | E34: =SUM(E28:E33) -> 0 | F34: =SUM(F28:F33) -> 0 | G34: =SUM(G28:G33) -> 0 | H34: =SUM(H28:H33) -> 0 | I34: =SUM(I28:I33) -> 0 | J34: =SUM(J28:J33) -> 0 | K34: =SUM(K28:K33) -> 0 | ... N34: =SUM(N28:N33) -> 0
C35: dienos foto | D35: =SUM(D28:D33) -> 0 | E35: =SUM(E28:E33) -> 0 | F35: =SUM(F34:K34) -> 0 | L35: =SUM(L28:L33) -> 0 | M35: =SUM(M28:M33) -> 0 | N35: =SUM(N28:N33) -> 0 | O35: =SUM(O28) -> 0 | P35: =SUM(P28) -> 0 | T35: =$V$3+L11+L19+L27+L35 -> 28
A36: =OFFSET('0'!$B$112,($A$1-1)*10,$B36-1) -> SK | B36: =OFFSET('0'!$B$111,($A$1-1)*10,4) -> 5 | M36: =SUM(D36-E36) -> 0 | N36: =SUM(E36,M36) -> 0
M37: =SUM(D37-E37) -> 0 | N37: =SUM(E37,M37) -> 0
M38: =SUM(D38-E38) -> 0 | N38: =SUM(E38,M38) -> 0
M39: =SUM(D39-E39) -> 0 | N39: =SUM(E39,M39) -> 0
M40: =SUM(D40-E40) -> 0 | N40: =SUM(E40,M40) -> 0
...

Sheet Rugpjūtis
A1: 8
B2: Mėnesio diena | C2: Vardas, pavardė. Pamaina D/N | D2: Paimti ROIK pranešimai (skaičius) | E2: Apdorota | F2: INFORMUOTA | L2: Pasisavintų lėšų suma (visų pranešimų) | M2: Neapdorota (siųstos pajėgos) | N2: Kontrolinis | O2: Tikslinamos aplinkybės (M) | P2: Pradėta IT | Q2: Pastabos | T2: Kontr. Kasdienė eilutė (Žalos)
F3: Bankas | G3: RRT | H3: FNTT | I3: NKSC | J3: Facebook | K3: Kita/įrašyti | U3: Praeitų mėn. Žalos | V3: =SUM(V6:V12) -> 28
A4: =OFFSET('0'!$B$112,($A$1-1)*10,$B4-1) -> SS | B4: =OFFSET('0'!$B$111,($A$1-1)*10,0) -> 1 | L4: 8 | M4: =SUM(D4-E4) -> 0 | N4: =SUM(E4,M4) -> 0
M5: =SUM(D5-E5) -> 0 | N5: =SUM(E5,M5) -> 0 | U5: mėn.
M6: =SUM(D6-E6) -> 0 | N6: =SUM(E6,M6) -> 0 | U6: 1 | V6: =Sausis!L254 -> 1
M7: =SUM(D7-E7) -> 0 | N7: =SUM(E7,M7) -> 0 | U7: 2 | V7: =Vasaris!L254 -> 2
M8: =SUM(D8-E8) -> 0 | N8: =SUM(E8,M8) -> 0 | U8: 3 | V8: =Kovas!L254 -> 3
M9: =SUM(D9-E9) -> 0 | N9: =SUM(E9,M9) -> 0 | U9: 4 | V9: =Balandis!L254 -> 4
C10: Iš viso Lietuvoje: | D10: =SUM(D4:D9) -> 0 | E10: =SUM(E4:E9) -> 0 | F10: =SUM(F4:F9) -> 0 | G10: =SUM(G4:G9) -> 0 | H10: =SUM(H4:H9) -> 0 | I10: =SUM(I4:I9) -> 0 | J10: =SUM(J4:J9) -> 0 | K10: =SUM(K4:K9) -> 0 | ... N10: =SUM(N4:N9) -> 0 | U10: 5 | V10: =Gegužė!L254 -> 5
C11: dienos foto | D11: =SUM(D4:D9) -> 0 | E11: =SUM(E4:E9) -> 0 | F11: =SUM(F10:K10) -> 0 | L11: =SUM(L4:L9) -> 8 | M11: =SUM(M4:M9) -> 0 | N11: =SUM(N4:N9) -> 0 | O11: =SUM(O4) -> 0 | P11: =SUM(P4) -> 0 | T11: =$V$3+L11 -> 36 | U11: 6 | V11: =Birželis!L254 -> 6
A12: =OFFSET('0'!$B$112,($A$1-1)*10,$B12-1) -> SK | B12: =OFFSET('0'!$B$111,($A$1-1)*10,1) -> 2 | M12: =SUM(D12-E12) -> 0 | N12: =SUM(E12,M12) -> 0 | U12: 7 | V12: =Liepa!L254 -> 7
M13: =SUM(D13-E13) -> 0 | N13: =SUM(E13,M13) -> 0 | U13: 8
M14: =SUM(D14-E14) -> 0 | N14: =SUM(E14,M14) -> 0 | U14: 9
M15: =SUM(D15-E15) -> 0 | N15: =SUM(E15,M15) -> 0 | U15: 10
M16: =SUM(D16-E16) -> 0 | N16: =SUM(E16,M16) -> 0 | U16: 11
M17: =SUM(D17-E17) -> 0 | N17: =SUM(E17,M17) -> 0
C18: Iš viso Lietuvoje: | D18: =SUM(D12:D17) -> 0 | E18: =SUM(E12:E17) -> 0 | F18: =SUM(F12:F17) -> 0 | G18: =SUM(G12:G17) -> 0 | H18: =SUM(H12:H17) -> 0 | I18: =SUM(I12:I17) -> 0 | J18: =SUM(J12:J17) -> 0 | K18: =SUM(K12:K17) -> 0 | ... N18: =SUM(N12:N17) -> 0
C19: dienos foto | D19: =SUM(D12:D17) -> 0 | E19: =SUM(E12:E17) -> 0 | F19: =SUM(F18:K18) -> 0 | L19: =SUM(L12:L17) -> 0 | M19: =SUM(M12:M17) -> 0 | N19: =SUM(N12:N17) -> 0 | O19: =SUM(O12) -> 0 | P19: =SUM(P12) -> 0 | T19: =$V$3+L11+L19 -> 36
A20: =OFFSET('0'!$B$112,($A$1-1)*10,$B20-1) -> -- | B20: =OFFSET('0'!$B$111,($A$1-1)*10,2) -> 3 | M20: =SUM(D20-E20) -> 0 | N20: =SUM(E20,M20) -> 0
M21: =SUM(D21-E21) -> 0 | N21: =SUM(E21,M21) -> 0
M22: =SUM(D22-E22) -> 0 | N22: =SUM(E22,M22) -> 0
M23: =SUM(D23-E23) -> 0 | N23: =SUM(E23,M23) -> 0
M24: =SUM(D24-E24) -> 0 | N24: =SUM(E24,M24) -> 0
M25: =SUM(D25-E25) -> 0 | N25: =SUM(E25,M25) -> 0
C26: Iš viso Lietuvoje: | D26: =SUM(D20:D25) -> 0 | E26: =SUM(E20:E25) -> 0 | F26: =SUM(F20:F25) -> 0 | G26: =SUM(G20:G25) -> 0 | H26: =SUM(H20:H25) -> 0 | I26: =SUM(I20:I25) -> 0 | J26: =SUM(J20:J25) -> 0 | K26: =SUM(K20:K25) -> 0 | ... N26: =SUM(N20:N25) -> 0
C27: dienos foto | D27: =SUM(D20:D25) -> 0 | E27: =SUM(E20:E25) -> 0 | F27: =SUM(F26:K26) -> 0 | L27: =SUM(L20:L25) -> 0 | M27: =SUM(M20:M25) -> 0 | N27: =SUM(N20:N25) -> 0 | O27: =SUM(O20) -> 0 | P27: =SUM(P20) -> 0 | T27: =$V$3++L11+L19+L27 -> 36
A28: =OFFSET('0'!$B$112,($A$1-1)*10,$B28-1) -> -- | B28: =OFFSET('0'!$B$111,($A$1-1)*10,3) -> 4 | M28: =SUM(D28-E28) -> 0 | N28: =SUM(E28,M28) -> 0
M29: =SUM(D29-E29) -> 0 | N29: =SUM(E29,M29) -> 0
M30: =SUM(D30-E30) -> 0 | N30: =SUM(E30,M30) -> 0
M31: =SUM(D31-E31) -> 0 | N31: =SUM(E31,M31) -> 0
M32: =SUM(D32-E32) -> 0 | N32: =SUM(E32,M32) -> 0
M33: =SUM(D33-E33) -> 0 | N33: =SUM(E33,M33) -> 0
C34: Iš viso Lietuvoje: | D34: =SUM(D28:D33) -> 0 | E34: =SUM(E28:E33) -> 0 | F34: =SUM(F28:F33) -> 0 | G34: =SUM(G28:G33) -> 0 | H34: =SUM(H28:H33) -> 0 | I34: =SUM(I28:I33) -> 0 | J34: =SUM(J28:J33) -> 0 | K34: =SUM(K28:K33) -> 0 | ... N34: =SUM(N28:N33) -> 0
C35: dienos foto | D35: =SUM(D28:D33) -> 0 | E35: =SUM(E28:E33) -> 0 | F35: =SUM(F34:K34) -> 0 | L35: =SUM(L28:L33) -> 0 | M35: =SUM(M28:M33) -> 0 | N35: =SUM(N28:N33) -> 0 | O35: =SUM(O28) -> 0 | P35: =SUM(P28) -> 0 | T35: =$V$3+L11+L19+L27+L35 -> 36
A36: =OFFSET('0'!$B$112,($A$1-1)*10,$B36-1) -> -- | B36: =OFFSET('0'!$B$111,($A$1-1)*10,4) -> 5 | M36: =SUM(D36-E36) -> 0 | N36: =SUM(E36,M36) -> 0
M37: =SUM(D37-E37) -> 0 | N37: =SUM(E37,M37) -> 0
M38: =SUM(D38-E38) -> 0 | N38: =SUM(E38,M38) -> 0
M39: =SUM(D39-E39) -> 0 | N39: =SUM(E39,M39) -> 0
M40: =SUM(D40-E40) -> 0 | N40: =SUM(E40,M40) -> 0
...

Sheet Rugsėjis
A1: 9
A2: 9 | B2: Mėnesio diena | C2: Vardas, pavardė. Pamaina D/N | D2: Paimti ROIK pranešimai (skaičius) | E2: Apdorota | F2: INFORMUOTA | L2: Pasisavintų lėšų suma (visų pranešimų) | M2: Neapdorota (siųstos pajėgos) | N2: Kontrolinis | O2: Tikslinamos aplinkybės (M) | P2: Pradėta IT | Q2: Pastabos | T2: Kontr. Kasdienė eilutė (Žalos)
F3: Bankas | G3: RRT | H3: FNTT | I3: NKSC | J3: Facebook | K3: Kita/įrašyti | U3: Praeitų mėn. Žalos | V3: =SUM(V6:V13) -> 36
A4: =OFFSET('0'!$B$112,($A$1-1)*10,$B4-1) -> -- | B4: =OFFSET('0'!$B$111,($A$1-1)*10,0) -> 1 | L4: 9 | M4: =SUM(D4-E4) -> 0 | N4: =SUM(E4,M4) -> 0
M5: =SUM(D5-E5) -> 0 | N5: =SUM(E5,M5) -> 0 | U5: mėn.
M6: =SUM(D6-E6) -> 0 | N6: =SUM(E6,M6) -> 0 | U6: 1 | V6: =Sausis!L254 -> 1
M7: =SUM(D7-E7) -> 0 | N7: =SUM(E7,M7) -> 0 | U7: 2 | V7: =Vasaris!L254 -> 2
M8: =SUM(D8-E8) -> 0 | N8: =SUM(E8,M8) -> 0 | U8: 3 | V8: =Kovas!L254 -> 3
M9: =SUM(D9-E9) -> 0 | N9: =SUM(E9,M9) -> 0 | U9: 4 | V9: =Balandis!L254 -> 4
C10: Iš viso Lietuvoje: | D10: =SUM(D4:D9) -> 0 | E10: =SUM(E4:E9) -> 0 | F10: =SUM(F4:F9) -> 0 | G10: =SUM(G4:G9) -> 0 | H10: =SUM(H4:H9) -> 0 | I10: =SUM(I4:I9) -> 0 | J10: =SUM(J4:J9) -> 0 | K10: =SUM(K4:K9) -> 0 | ... N10: =SUM(N4:N9) -> 0 | U10: 5 | V10: =Gegužė!L254 -> 5
C11: dienos foto | D11: =SUM(D4:D9) -> 0 | E11: =SUM(E4:E9) -> 0 | F11: =SUM(F10:K10) -> 0 | L11: =SUM(L4:L9) -> 9 | M11: =SUM(M4:M9) -> 0 | N11: =SUM(N4:N9) -> 0 | O11: =SUM(O4) -> 0 | P11: =SUM(P4) -> 0 | T11: =$V$3+L11 -> 45 | U11: 6 | V11: =Birželis!L254 -> 6
A12: =OFFSET('0'!$B$112,($A$1-1)*10,$B12-1) -> -- | B12: =OFFSET('0'!$B$111,($A$1-1)*10,1) -> 2 | M12: =SUM(D12-E12) -> 0 | N12: =SUM(E12,M12) -> 0 | U12: 7 | V12: =Liepa!L254 -> 7
M13: =SUM(D13-E13) -> 0 | N13: =SUM(E13,M13) -> 0 | U13: 8 | V13: =Rugpjūtis!L254 -> 8
M14: =SUM(D14-E14) -> 0 | N14: =SUM(E14,M14) -> 0 | U14: 9
M15: =SUM(D15-E15) -> 0 | N15: =SUM(E15,M15) -> 0 | U15: 10
M16: =SUM(D16-E16) -> 0 | N16: =SUM(E16,M16) -> 0 | U16: 11
M17: =SUM(D17-E17) -> 0 | N17: =SUM(E17,M17) -> 0
C18: Iš viso Lietuvoje: | D18: =SUM(D12:D17) -> 0 | E18: =SUM(E12:E17) -> 0 | F18: =SUM(F12:F17) -> 0 | G18: =SUM(G12:G17) -> 0 | H18: =SUM(H12:H17) -> 0 | I18: =SUM(I12:I17) -> 0 | J18: =SUM(J12:J17) -> 0 | K18: =SUM(K12:K17) -> 0 | ... N18: =SUM(N12:N17) -> 0
C19: dienos foto | D19: =SUM(D12:D17) -> 0 | E19: =SUM(E12:E17) -> 0 | F19: =SUM(F18:K18) -> 0 | L19: =SUM(L12:L17) -> 0 | M19: =SUM(M12:M17) -> 0 | N19: =SUM(N12:N17) -> 0 | O19: =SUM(O12) -> 0 | P19: =SUM(P12) -> 0 | T19: =$V$3+L11+L19 -> 45
A20: =OFFSET('0'!$B$112,($A$1-1)*10,$B20-1) -> -- | B20: =OFFSET('0'!$B$111,($A$1-1)*10,2) -> 3 | M20: =SUM(D20-E20) -> 0 | N20: =SUM(E20,M20) -> 0
M21: =SUM(D21-E21) -> 0 | N21: =SUM(E21,M21) -> 0
M22: =SUM(D22-E22) -> 0 | N22: =SUM(E22,M22) -> 0
M23: =SUM(D23-E23) -> 0 | N23: =SUM(E23,M23) -> 0
M24: =SUM(D24-E24) -> 0 | N24: =SUM(E24,M24) -> 0
M25: =SUM(D25-E25) -> 0 | N25: =SUM(E25,M25) -> 0
C26: Iš viso Lietuvoje: | D26: =SUM(D20:D25) -> 0 | E26: =SUM(E20:E25) -> 0 | F26: =SUM(F20:F25) -> 0 | G26: =SUM(G20:G25) -> 0 | H26: =SUM(H20:H25) -> 0 | I26: =SUM(I20:I25) -> 0 | J26: =SUM(J20:J25) -> 0 | K26: =SUM(K20:K25) -> 0 | ... N26: =SUM(N20:N25) -> 0
C27: dienos foto | D27: =SUM(D20:D25) -> 0 | E27: =SUM(E20:E25) -> 0 | F27: =SUM(F26:K26) -> 0 | L27: =SUM(L20:L25) -> 0 | M27: =SUM(M20:M25) -> 0 | N27: =SUM(N20:N25) -> 0 | O27: =SUM(O20) -> 0 | P27: =SUM(P20) -> 0 | T27: =$V$3++L11+L19+L27 -> 45
A28: =OFFSET('0'!$B$112,($A$1-1)*10,$B28-1) -> -- | B28: =OFFSET('0'!$B$111,($A$1-1)*10,3) -> 4 | M28: =SUM(D28-E28) -> 0 | N28: =SUM(E28,M28) -> 0
M29: =SUM(D29-E29) -> 0 | N29: =SUM(E29,M29) -> 0
M30: =SUM(D30-E30) -> 0 | N30: =SUM(E30,M30) -> 0
M31: =SUM(D31-E31) -> 0 | N31: =SUM(E31,M31) -> 0
M32: =SUM(D32-E32) -> 0 | N32: =SUM(E32,M32) -> 0
M33: =SUM(D33-E33) -> 0 | N33: =SUM(E33,M33) -> 0
C34: Iš viso Lietuvoje: | D34: =SUM(D28:D33) -> 0 | E34: =SUM(E28:E33) -> 0 | F34: =SUM(F28:F33) -> 0 | G34: =SUM(G28:G33) -> 0 | H34: =SUM(H28:H33) -> 0 | I34: =SUM(I28:I33) -> 0 | J34: =SUM(J28:J33) -> 0 | K34: =SUM(K28:K33) -> 0 | ... N34: =SUM(N28:N33) -> 0
C35: dienos foto | D35: =SUM(D28:D33) -> 0 | E35: =SUM(E28:E33) -> 0 | F35: =SUM(F34:K34) -> 0 | L35: =SUM(L28:L33) -> 0 | M35: =SUM(M28:M33) -> 0 | N35: =SUM(N28:N33) -> 0 | O35: =SUM(O28) -> 0 | P35: =SUM(P28) -> 0 | T35: =$V$3+L11+L19+L27+L35 -> 45
A36: =OFFSET('0'!$B$112,($A$1-1)*10,$B36-1) -> SS | B36: =OFFSET('0'!$B$111,($A$1-1)*10,4) -> 5 | M36: =SUM(D36-E36) -> 0 | N36: =SUM(E36,M36) -> 0
M37: =SUM(D37-E37) -> 0 | N37: =SUM(E37,M37) -> 0
M38: =SUM(D38-E38) -> 0 | N38: =SUM(E38,M38) -> 0
M39: =SUM(D39-E39) -> 0 | N39: =SUM(E39,M39) -> 0
M40: =SUM(D40-E40) -> 0 | N40: =SUM(E40,M40) -> 0
...

Sheet Spalis
A1: 10
B2: Mėnesio diena | C2: Vardas, pavardė. Pamaina D/N | D2: Paimti ROIK pranešimai (skaičius) | E2: Apdorota | F2: INFORMUOTA | L2: Pasisavintų lėšų suma (visų pranešimų) | M2: Neapdorota (siųstos pajėgos) | N2: Kontrolinis | O2: Tikslinamos aplinkybės (M) | P2: Pradėta IT | Q2: Pastabos | T2: Kontr. Kasdienė eilutė (Žalos)
F3: Bankas | G3: RRT | H3: FNTT | I3: NKSC | J3: Facebook | K3: Kita/įrašyti | U3: Praeitų mėn. Žalos | V3: =SUM(V6:V14) -> 45
A4: =OFFSET('0'!$B$112,($A$1-1)*10,$B4-1) -> -- | B4: =OFFSET('0'!$B$111,($A$1-1)*10,0) -> 1 | L4: 10 | M4: =SUM(D4-E4) -> 0 | N4: =SUM(E4,M4) -> 0
M5: =SUM(D5-E5) -> 0 | N5: =SUM(E5,M5) -> 0 | U5: mėn.
M6: =SUM(D6-E6) -> 0 | N6: =SUM(E6,M6) -> 0 | U6: 1 | V6: =Sausis!L254 -> 1
M7: =SUM(D7-E7) -> 0 | N7: =SUM(E7,M7) -> 0 | U7: 2 | V7: =Vasaris!L254 -> 2
M8: =SUM(D8-E8) -> 0 | N8: =SUM(E8,M8) -> 0 | U8: 3 | V8: =Kovas!L254 -> 3
M9: =SUM(D9-E9) -> 0 | N9: =SUM(E9,M9) -> 0 | U9: 4 | V9: =Balandis!L254 -> 4
C10: Iš viso Lietuvoje: | D10: =SUM(D4:D9) -> 0 | E10: =SUM(E4:E9) -> 0 | F10: =SUM(F4:F9) -> 0 | G10: =SUM(G4:G9) -> 0 | H10: =SUM(H4:H9) -> 0 | I10: =SUM(I4:I9) -> 0 | J10: =SUM(J4:J9) -> 0 | K10: =SUM(K4:K9) -> 0 | ... N10: =SUM(N4:N9) -> 0 | U10: 5 | V10: =Gegužė!L254 -> 5
C11: dienos foto | D11: =SUM(D4:D9) -> 0 | E11: =SUM(E4:E9) -> 0 | F11: =SUM(F10:K10) -> 0 | L11: =SUM(L4:L9) -> 10 | M11: =SUM(M4:M9) -> 0 | N11: =SUM(N4:N9) -> 0 | O11: =SUM(O4) -> 0 | P11: =SUM(P4) -> 0 | T11: =$V$3+L11 -> 55 | U11: 6 | V11: =Birželis!L254 -> 6
A12: =OFFSET('0'!$B$112,($A$1-1)*10,$B12-1) -> -- | B12: =OFFSET('0'!$B$111,($A$1-1)*10,1) -> 2 | M12: =SUM(D12-E12) -> 0 | N12: =SUM(E12,M12) -> 0 | U12: 7 | V12: =Liepa!L254 -> 7
M13: =SUM(D13-E13) -> 0 | N13: =SUM(E13,M13) -> 0 | U13: 8 | V13: =Rugpjūtis!L254 -> 8
M14: =SUM(D14-E14) -> 0 | N14: =SUM(E14,M14) -> 0 | U14: 9 | V14: =Rugsėjis!L254 -> 9
M15: =SUM(D15-E15) -> 0 | N15: =SUM(E15,M15) -> 0 | U15: 10
M16: =SUM(D16-E16) -> 0 | N16: =SUM(E16,M16) -> 0 | U16: 11
M17: =SUM(D17-E17) -> 0 | N17: =SUM(E17,M17) -> 0
C18: Iš viso Lietuvoje: | D18: =SUM(D12:D17) -> 0 | E18: =SUM(E12:E17) -> 0 | F18: =SUM(F12:F17) -> 0 | G18: =SUM(G12:G17) -> 0 | H18: =SUM(H12:H17) -> 0 | I18: =SUM(I12:I17) -> 0 | J18: =SUM(J12:J17) -> 0 | K18: =SUM(K12:K17) -> 0 | ... N18: =SUM(N12:N17) -> 0
C19: dienos foto | D19: =SUM(D12:D17) -> 0 | E19: =SUM(E12:E17) -> 0 | F19: =SUM(F18:K18) -> 0 | L19: =SUM(L12:L17) -> 0 | M19: =SUM(M12:M17) -> 0 | N19: =SUM(N12:N17) -> 0 | O19: =SUM(O12) -> 0 | P19: =SUM(P12) -> 0 | T19: =$V$3+L11+L19 -> 55
A20: =OFFSET('0'!$B$112,($A$1-1)*10,$B20-1) -> SS | B20: =OFFSET('0'!$B$111,($A$1-1)*10,2) -> 3 | M20: =SUM(D20-E20) -> 0 | N20: =SUM(E20,M20) -> 0
M21: =SUM(D21-E21) -> 0 | N21: =SUM(E21,M21) -> 0
M22: =SUM(D22-E22) -> 0 | N22: =SUM(E22,M22) -> 0
M23: =SUM(D23-E23) -> 0 | N23: =SUM(E23,M23) -> 0
M24: =SUM(D24-E24) -> 0 | N24: =SUM(E24,M24) -> 0
M25: =SUM(D25-E25) -> 0 | N25: =SUM(E25,M25) -> 0
C26: Iš viso Lietuvoje: | D26: =SUM(D20:D25) -> 0 | E26: =SUM(E20:E25) -> 0 | F26: =SUM(F20:F25) -> 0 | G26: =SUM(G20:G25) -> 0 | H26: =SUM(H20:H25) -> 0 | I26: =SUM(I20:I25) -> 0 | J26: =SUM(J20:J25) -> 0 | K26: =SUM(K20:K25) -> 0 | ... N26: =SUM(N20:N25) -> 0
