Workbook

Sheet 0
A1: sausio | B1: Sausis | C1: I | D1: 2025 | I1: 1 | AG1: 0 | AH1: ale | AI1: Jurijus Aleksejevas, D.
A2: vasario | B2: Vasaris | C2: II | D2: 2026 | I2: 16 | AG2: 0 | AH2: ale | AI2: Jurijus Aleksejevas, N.
A3: kovo | B3: Kovas | C3: III | D3: 2027 | I3: 11 | K3: =IF(B29=3,B28,"") | AG3: 0 | AH3: bac | AI3: Dalius Bacevičius, D.
A4: balandžio | B4: Balandis | C4: IV | D4: 2028 | K4: =IF(B29=4,B28,IF(K3=31,1,"")) -> 20 | AG4: 0 | AH4: bac | AI4: Dalius Bacevičius, N.
A5: gegužės | B5: Gegužė | D5: 2029 | I5: 1 | AG5: 0 | AH5: čep | AI5: Agnė Čepukė, D.
A6: birželio | B6: Birželis | D6: 2030 | I6: 26 | AG6: 0 | AH6: čep | AI6: Agnė Čepukė, N.
A7: liepos | B7: Liepa | D7: 2031 | I7: 6 | AG7: 0 | AH7: jok | AI7: Vitalija Jokubynienė, D.
A8: rugpjūčio | B8: Rugpjūtis | D8: 2032 | I8: 15 | AG8: 0 | AH8: jok | AI8: Vitalija Jokubynienė, N.
A9: rugsėjo | B9: Rugsėjis | D9: 2033 | AG9: 0 | AH9: kiu | AI9: Aidas Kiukys, D.
A10: spalio | B10: Spalis | D10: 2034 | AG10: 0 | AH10: kiu | AI10: Aidas Kiukys, N.
A11: lapkričio | B11: Lapkritis | D11: 2035 | I11: 1 | J11: 2 | AG11: 0 | AH11: mas | AI11: Evaldas Maskeliūnas, D.
A12: gruodžio | B12: Gruodis | D12: 2036 | I12: 24 | J12: 25 | K12: 26 | AG12: 0 | AH12: mas | AI12: Evaldas Maskeliūnas, N.
D13: 2037 | AG13: 0 | AH13: men | AI13: Laura Mendelienė, D.
D14: 2038 | AG14: 0 | AH14: men | AI14: Laura Mendelienė, N.
D15: 2039 | AG15: 0 | AH15: mer | AI15: Saulius Merkininkas, D.
D16: PASAULIO PAB. | AG16: 0 | AH16: mer | AI16: Saulius Merkininkas, N.
A17: Velyku skaiciuokle | AG17: 0 | AH17: pil | AI17: Jurgita Pilypaitienė, D.
AG18: 0 | AH18: pil | AI18: Jurgita Pilypaitienė, N.
A19: Metai | B19: =Dinamika!$B$1 -> 2025 | D19: Dienos eilutes | E19: 8 | AG19: 0 | AH19: saj | AI19: Giedrė Sajetaitė, D.
A20: a | B20: =MOD(B19,19) -> 11 | AG20: 0 | AH20: saj | AI20: Giedrė Sajetaitė, N.
A21: b | B21: =TRUNC(B19/4) -> 506 | AG21: 0 | AH21: šed | AI21: Vaidas Šeduikis, D.
A22: c | B22: =TRUNC(B21/25)+1 -> 21 | AG22: 0 | AH22: šed | AI22: Vaidas Šeduikis, N.
A23: d | B23: =TRUNC(B22*3/4) -> 15 | AG23: 0 | AH23: žur | AI23: Tomas Žuramskas, D.
A24: e1 | B24: =MOD((B20*19)-(TRUNC((B22*8+5)/25)+B23+15),30) -> 23 | AG24: 0 | AH24: žur | AI24: Tomas Žuramskas, N.
A25: e2 | B25: =B24+TRUNC((29578-B20-B24*32)/1024) -> 51 | AG25: 9 | AH25: kau | AI25: Kauno apskr. VPK
A26: e3 | B26: =B25-MOD((MOD(B19,7)+B21-B23+B25+2),7) -> 51 | AG26: 9 | AH26: mar | AI26: Marijampolės apskr. VPK Vilkaviškio r. PK
A27: d | B27: =TRUNC(B26/32) -> 1 | AG27: 9 | AH27: pan | AI27: Panevėžio apskr. VPK
A28: diena | B28: =B26-B27*31 -> 20 | AG28: 9 | AH28: vil | AI28: Vilniaus apskr. VPK
A29: menuo | B29: =B27+3 -> 4
A31: Velykos | B31: =DATE(B19,B29,B28) -> 45767
A109: Metai | B109: Menuo skaičium | C109: Dienų sk. | F109: Menuo
A110: =Dinamika!$B$1 -> 2025 | B110: 1 | C110: =DAY(EOMONTH(DATE(A110,B110,1),0)) -> 31 | F110: =CHOOSE($B110,$B$1,$B$2,$B$3,$B$4,$B$5,$B$6,$B$7,$B$8,$B$9,$B$10,$B$11,$B$12) -> Sausis
A111: =CHOOSE($B110,$B$1,$B$2,$B$3,$B$4,$B$5,$B$6,$B$7,$B$8,$B$9,$B$10,$B$11,$B$12) -> Sausis | B111: 1 | C111: =B111+1 -> 2 | D111: =C111+1 -> 3 | E111: =D111+1 -> 4 | F111: =E111+1 -> 5 | G111: =F111+1 -> 6 | H111: =G111+1 -> 7 | I111: =H111+1 -> 8 | J111: =I111+1 -> 9 | ... AC111: =AB111+1 -> 28 | AD111: =IF(ABS(AC111)<$C110,AC111+1,-AC111+1) -> 29 | AE111: =IF(ABS(AD111)<$C110,AD111+1,-AD111+1) -> 30 | AF111: =IF(ABS(AE111)<$C110,AE111+1,-AE111+1) -> 31
A112: =A111 -> Sausis | B112: =IF(B111>0,IF(OR(OFFSET($I$1,$B110-1,0)=B111,OFFSET($I$1,$B110-1,1)=B111,OFFSET($I$1,$B110-1,2)=B111),"SV",CHOOSE(WEEKDAY(DATE($A110,$B110,B111),2),"--","--","--","--","--","SS","SK")),"XX") -> SV | C112: =IF(C111>0,IF(OR(OFFSET($I$1,$B110-1,0)=C111,OFFSET($I$1,$B110-1,1)=C111,OFFSET($I$1,$B110-1,2)=C111),"SV",CHOOSE(WEEKDAY(DATE($A110,$B110,C111),2),"--","--","--","--","--","SS","SK")),"XX") -> -- | D112: =IF(D111>0,IF(OR(OFFSET($I$1,$B110-1,0)=D111,OFFSET($I$1,$B110-1,1)=D111,OFFSET($I$1,$B110-1,2)=D111),"SV",CHOOSE(WEEKDAY(DATE($A110,$B110,D111),2),"--","--","--","--","--","SS","SK")),"XX") -> -- | E112: =IF(E111>0,IF(OR(OFFSET($I$1,$B110-1,0)=E111,OFFSET($I$1,$B110-1,1)=E111,OFFSET($I$1,$B110-1,2)=E111),"SV",CHOOSE(WEEKDAY(DATE($A110,$B110,E111),2),"--","--","--","--","--","SS","SK")),"XX") -> SS | F112: =IF(F111>0,IF(OR(OFFSET($I$1,$B110-1,0)=F111,OFFSET($I$1,$B110-1,1)=F111,OFFSET($I$1,$B110-1,2)=F111),"SV",CHOOSE(WEEKDAY(DATE($A110,$B110,F111),2),"--","--","--","--","--","SS","SK")),"XX") -> SK | G112: =IF(G111>0,IF(OR(OFFSET($I$1,$B110-1,0)=G111,OFFSET($I$1,$B110-1,1)=G111,OFFSET($I$1,$B110-1,2)=G111),"SV",CHOOSE(WEEKDAY(DATE($A110,$B110,G111),2),"--","--","--","--","--","SS","SK")),"XX") -> -- | H112: =IF(H111>0,IF(OR(OFFSET($I$1,$B110-1,0)=H111,OFFSET($I$1,$B110-1,1)=H111,OFFSET($I$1,$B110-1,2)=H111),"SV",CHOOSE(WEEKDAY(DATE($A110,$B110,H111),2),"--","--","--","--","--","SS","SK")),"XX") -> -- | I112: =IF(I111>0,IF(OR(OFFSET($I$1,$B110-1,0)=I111,OFFSET($I$1,$B110-1,1)=I111,OFFSET($I$1,$B110-1,2)=I111),"SV",CHOOSE(WEEKDAY(DATE($A110,$B110,I111),2),"--","--","--","--","--","SS","SK")),"XX") -> -- | ... AF112: =IF(AF111>0,IF(OR(OFFSET($I$1,$B110-1,0)=AF111,OFFSET($I$1,$B110-1,1)=AF111,OFFSET($I$1,$B110-1,2)=AF111),"SV",CHOOSE(WEEKDAY(DATE($A110,$B110,AF111),2),"--","--","--","--","--","SS","SK")),"XX") -> --
A113: =ROW(Sausis!$A254)-1 -> 253 | B113: =ROW(Sausis!$A11)-1 -> 10 | C113: =ROW(Sausis!$A19)-1 -> 18 | D113: =ROW(Sausis!$A27)-1 -> 26 | E113: =ROW(Sausis!$A35)-1 -> 34 | F113: =ROW(Sausis!$A43)-1 -> 42 | G113: =ROW(Sausis!$A51)-1 -> 50 | H113: =ROW(Sausis!$A59)-1 -> 58 | I113: =ROW(Sausis!$A67)-1 -> 66 | J113: =ROW(Sausis!$A75)-1 -> 74 | K113: =ROW(Sausis!$A83)-1 -> 82 | L113: =ROW(Sausis!$A91)-1 -> 90 | M113: =ROW(Sausis!$A99)-1 -> 98 | N113: =ROW(Sausis!$A107)-1 -> 106 | O113: =ROW(Sausis!$A115)-1 -> 114 | P113: =ROW(Sausis!$A123)-1 -> 122 | Q113: =ROW(Sausis!$A131)-1 -> 130 | R113: =ROW(Sausis!$A139)-1 -> 138 | S113: =ROW(Sausis!$A147)-1 -> 146 | T113: =ROW(Sausis!$A155)-1 -> 154 | U113: =ROW(Sausis!$A163)-1 -> 162 | V113: =ROW(Sausis!$A171)-1 -> 170 | W113: =ROW(Sausis!$A179)-1 -> 178 | X113: =ROW(Sausis!$A187)-1 -> 186 | Y113: =ROW(Sausis!$A195)-1 -> 194 | Z113: =ROW(Sausis!$A203)-1 -> 202 | AA113: =ROW(Sausis!$A211)-1 -> 210 | AB113: =ROW(Sausis!$A219)-1 -> 218 | AC113: =ROW(Sausis!$A227)-1 -> 226 | AD113: =ROW(Sausis!$A235)-1 -> 234 | AE113: =ROW(Sausis!$A243)-1 -> 242 | AF113: =ROW(Sausis!$A251)-1 -> 250
A119: Metai | B119: Menuo skaičium | C119: Dienų sk. | F119: Menuo
A120: =Dinamika!$B$1 -> 2025 | B120: 2 | C120: =DAY(EOMONTH(DATE(A120,B120,1),0)) -> 28 | F120: =CHOOSE($B120,$B$1,$B$2,$B$3,$B$4,$B$5,$B$6,$B$7,$B$8,$B$9,$B$10,$B$11,$B$12) -> Vasaris
A121: =CHOOSE($B120,$B$1,$B$2,$B$3,$B$4,$B$5,$B$6,$B$7,$B$8,$B$9,$B$10,$B$11,$B$12) -> Vasaris | B121: 1 | C121: =B121+1 -> 2 | D121: =C121+1 -> 3 | E121: =D121+1 -> 4 | F121: =E121+1 -> 5 | G121: =F121+1 -> 6 | H121: =G121+1 -> 7 | I121: =H121+1 -> 8 | J121: =I121+1 -> 9 | ... AC121: =AB121+1 -> 28 | AD121: =IF(ABS(AC121)<$C120,AC121+1,-AC121+1) -> -27 | AE121: =IF(ABS(AD121)<$C120,AD121+1,-AD121+1) -> -26 | AF121: =IF(ABS(AE121)<$C120,AE121+1,-AE121+1) -> -25
A122: =A121 -> Vasaris | B122: =IF(B121>0,IF(OR(OFFSET($I$1,$B120-1,0)=B121,OFFSET($I$1,$B120-1,1)=B121,OFFSET($I$1,$B120-1,2)=B121),"SV",CHOOSE(WEEKDAY(DATE($A120,$B120,B121),2),"--","--","--","--","--","SS","SK")),"XX") -> SS | C122: =IF(C121>0,IF(OR(OFFSET($I$1,$B120-1,0)=C121,OFFSET($I$1,$B120-1,1)=C121,OFFSET($I$1,$B120-1,2)=C121),"SV",CHOOSE(WEEKDAY(DATE($A120,$B120,C121),2),"--","--","--","--","--","SS","SK")),"XX") -> SK | D122: =IF(D121>0,IF(OR(OFFSET($I$1,$B120-1,0)=D121,OFFSET($I$1,$B120-1,1)=D121,OFFSET($I$1,$B120-1,2)=D121),"SV",CHOOSE(WEEKDAY(DATE($A120,$B120,D121),2),"--","--","--","--","--","SS","SK")),"XX") -> -- | E122: =IF(E121>0,IF(OR(OFFSET($I$1,$B120-1,0)=E121,OFFSET($I$1,$B120-1,1)=E121,OFFSET($I$1,$B120-1,2)=E121),"SV",CHOOSE(WEEKDAY(DATE($A120,$B120,E121),2),"--","--","--","--","--","SS","SK")),"XX") -> -- | F122: =IF(F121>0,IF(OR(OFFSET($I$1,$B120-1,0)=F121,OFFSET($I$1,$B120-1,1)=F121,OFFSET($I$1,$B120-1,2)=F121),"SV",CHOOSE(WEEKDAY(DATE($A120,$B120,F121),2),"--","--","--","--","--","SS","SK")),"XX") -> -- | G122: =IF(G121>0,IF(OR(OFFSET($I$1,$B120-1,0)=G121,OFFSET($I$1,$B120-1,1)=G121,OFFSET($I$1,$B120-1,2)=G121),"SV",CHOOSE(WEEKDAY(DATE($A120,$B120,G121),2),"--","--","--","--","--","SS","SK")),"XX") -> -- | H122: =IF(H121>0,IF(OR(OFFSET($I$1,$B120-1,0)=H121,OFFSET($I$1,$B120-1,1)=H121,OFFSET($I$1,$B120-1,2)=H121),"SV",CHOOSE(WEEKDAY(DATE($A120,$B120,H121),2),"--","--","--","--","--","SS","SK")),"XX") -> -- | I122: =IF(I121>0,IF(OR(OFFSET($I$1,$B120-1,0)=I121,OFFSET($I$1,$B120-1,1)=I121,OFFSET($I$1,$B120-1,2)=I121),"SV",CHOOSE(WEEKDAY(DATE($A120,$B120,I121),2),"--","--","--","--","--","SS","SK")),"XX") -> SS | ... AF122: =IF(AF121>0,IF(OR(OFFSET($I$1,$B120-1,0)=AF121,OFFSET($I$1,$B120-1,1)=AF121,OFFSET($I$1,$B120-1,2)=AF121),"SV",CHOOSE(WEEKDAY(DATE($A120,$B120,AF121),2),"--","--","--","--","--","SS","SK")),"XX") -> XX
A123: =ROW(Vasaris!A251)-1 -> 250 | B123: =ROW(Vasaris!$A7)-1 -> 6 | C123: =ROW(Vasaris!$A15)-1 -> 14 | D123: =ROW(Vasaris!$A23)-1 -> 22 | E123: =ROW(Vasaris!$A31)-1 -> 30 | F123: =ROW(Vasaris!$A39)-1 -> 38 | G123: =ROW(Vasaris!$A47)-1 -> 46 | H123: =ROW(Vasaris!$A55)-1 -> 54 | I123: =ROW(Vasaris!$A63)-1 -> 62 | J123: =ROW(Vasaris!$A71)-1 -> 70 | K123: =ROW(Vasaris!$A79)-1 -> 78 | L123: =ROW(Vasaris!$A87)-1 -> 86 | M123: =ROW(Vasaris!$A95)-1 -> 94 | N123: =ROW(Vasaris!$A103)-1 -> 102 | O123: =ROW(Vasaris!$A111)-1 -> 110 | P123: =ROW(Vasaris!$A119)-1 -> 118 | Q123: =ROW(Vasaris!$A127)-1 -> 126 | R123: =ROW(Vasaris!$A135)-1 -> 134 | S123: =ROW(Vasaris!$A143)-1 -> 142 | T123: =ROW(Vasaris!$A151)-1 -> 150 | U123: =ROW(Vasaris!$A159)-1 -> 158 | V123: =ROW(Vasaris!$A168)-1 -> 167 | W123: =ROW(Vasaris!$A176)-1 -> 175 | X123: =ROW(Vasaris!$A184)-1 -> 183 | Y123: =ROW(Vasaris!$A192)-1 -> 191 | Z123: =ROW(Vasaris!$A200)-1 -> 199 | AA123: =ROW(Vasaris!$A208)-1 -> 207 | AB123: =ROW(Vasaris!$A216)-1 -> 215 | AC123: =ROW(Vasaris!$A224)-1 -> 223 | AD123: =ROW(Vasaris!$A232)-1 -> 231 | AE123: =ROW(Vasaris!$A240)-1 -> 239 | AF123: =ROW(Vasaris!$A248)-1 -> 247
...

Sheet Bendras metų
Q1: Psw:sukciai
C3: -1 | D3: <== + - prie šiandienos | U3: Praeitų mėn. Žalos | V3: =SUM(V6:V16,L253) -> 11082548
B4: Sukčiavimo pranešimų apdorojimas
B5: =CONCATENATE(YEAR(NOW()+C3)," m. ",OFFSET('0'!A1,MONTH(NOW()+C3)-1,0)," mėn. ",DAY(NOW()+C3)," d.") -> 2025 m. gruodžio mėn. 31 d. | U5: mėn.
C6: per praėjusią parą | D6: Iš viso nuo centro veiklos pradžios (2025-01-27) | U6: 1 | V6: =Sausis!L254 -> 46650.2
B7: Paimti ROIK pranešimai (skaičius) | C7: =INDIRECT(ADDRESS(OFFSET('0'!$B$113,(MONTH(NOW()+C3)-1)*10,DAY(NOW()+C3)-1)+1,4,4,TRUE,OFFSET('0'!$B$1,MONTH(NOW()+C3)-1,0))) -> 0 | D7: =Q23 -> 6815 | F7: C5, C7, C8, C9, C10, C11, C12, C13, C14, C15, C16, C17, C18 | I7: langelius nepildyti naktį dirbančiam darbuotojui nuo 00 val iki 5 val ryto | U7: 2 | V7: =Vasaris!L250 -> 993065.32
B8: Apdorota įvykių nuotoliu | C8: =INDIRECT(ADDRESS(OFFSET('0'!$B$113,(MONTH(NOW()+C3)-1)*10,DAY(NOW()+C3)-1)+1,5,4,TRUE,OFFSET('0'!$B$1,MONTH(NOW()+C3)-1,0))) -> 0 | D8: =Q24 -> 6543 | F8: Duomenys automatiškai persikelia iš kitų lentelių | U8: 3 | V8: =Kovas!L254 -> 3079849.4
B9: Tikslinamos aplinkybės (M) | C9: =INDIRECT(ADDRESS(OFFSET('0'!$B$113,(MONTH(NOW()+C3)-1)*10,DAY(NOW()+C3)-1)+1,15,4,TRUE,OFFSET('0'!$B$1,MONTH(NOW()+C3)-1,0))) -> 0 | D9: =Q25 -> 377 | U9: 4 | V9: =Balandis!L259 -> 3214494.9
B10: Pradėta IT | C10: =INDIRECT(ADDRESS(OFFSET('0'!$B$113,(MONTH(NOW()+C3)-1)*10,DAY(NOW()+C3)-1)+1,16,4,TRUE,OFFSET('0'!$B$1,MONTH(NOW()+C3)-1,0))) -> 0 | D10: =Q26 -> 997 | U10: 5 | V10: =Gegužė!L254 -> 3452913.4
B11: Informuotos kitos institucijos, iš jų: | C11: =INDIRECT(ADDRESS(OFFSET('0'!$B$113,(MONTH(NOW()+C3)-1)*10,DAY(NOW()+C3)-1)+1,6,4,TRUE,OFFSET('0'!$B$1,MONTH(NOW()+C3)-1,0))) -> 0 | D11: =Q27 -> 3374 | U11: 6 | V11: =Birželis!L254 -> 295574.6
B12: Bankas | C12: =INDIRECT(ADDRESS(OFFSET('0'!$B$113,(MONTH(NOW()+C3)-1)*10,DAY(NOW()+C3)-1),6,4,TRUE,OFFSET('0'!$B$1,MONTH(NOW()+C3)-1,0))) -> 0 | D12: =Q28 -> 1342 | U12: 7 | V12: =Liepa!L254 -> 0
B13: RRT | C13: =INDIRECT(ADDRESS(OFFSET('0'!$B$113,(MONTH(NOW()+C3)-1)*10,DAY(NOW()+C3)-1),7,4,TRUE,OFFSET('0'!$B$1,MONTH(NOW()+C3)-1,0))) -> 0 | D13: =Q29 -> 1287 | U13: 8 | V13: =Rugpjūtis!L254 -> 0
B14: FNTT | C14: =INDIRECT(ADDRESS(OFFSET('0'!$B$113,(MONTH(NOW()+C3)-1)*10,DAY(NOW()+C3)-1),8,4,TRUE,OFFSET('0'!$B$1,MONTH(NOW()+C3)-1,0))) -> 0 | D14: =Q30 -> 4 | U14: 9 | V14: =Rugsėjis!L254 -> 0
B15: NKSC | C15: =INDIRECT(ADDRESS(OFFSET('0'!$B$113,(MONTH(NOW()+C3)-1)*10,DAY(NOW()+C3)-1),9,4,TRUE,OFFSET('0'!$B$1,MONTH(NOW()+C3)-1,0))) -> 0 | D15: =Q31 -> 316 | U15: 10 | V15: =Spalis!L254 -> 0
B16: Facebook | C16: =INDIRECT(ADDRESS(OFFSET('0'!$B$113,(MONTH(NOW()+C3)-1)*10,DAY(NOW()+C3)-1),10,4,TRUE,OFFSET('0'!$B$1,MONTH(NOW()+C3)-1,0))) -> 0 | D16: =Q32 -> 410 | U16: 11 | V16: =Lapkritis!L254 -> 0
B17: Kita | C17: =INDIRECT(ADDRESS(OFFSET('0'!$B$113,(MONTH(NOW()+C3)-1)*10,DAY(NOW()+C3)-1),11,4,TRUE,OFFSET('0'!$B$1,MONTH(NOW()+C3)-1,0))) -> 0 | D17: =Q33 -> 15
B18: Pasisavintų lėšų suma, Eur (visų pranešimų) * | C18: =INDIRECT(ADDRESS(OFFSET('0'!$B$113,(MONTH(NOW()+C3)-1)*10,DAY(NOW()+C3)-1)+1,12,4,TRUE,OFFSET('0'!$B$1,MONTH(NOW()+C3)-1,0))) -> 0 | D18: =Q34 -> 11082548
B19: * Preliminari žala, pateikta pagal pirminę pranešėjų informaciją
D21: METŲ REZULTATAS
E22: Sausis | F22: Vasaris | G22: Kovas | H22: Balandis | I22: Gegužė | J22: Birželis | K22: Liepa | L22: Rugpjūtis | M22: Rugsėjis | N22: Spalis | O22: Lapkritis | P22: Gruodis | Q22: VISO | R22: VISO ANKŠČIAU
D23: Paimti ROIK pranešimai (skaičius) | E23: =Sausis!D253 -> 197 | F23: =Vasaris!D250 -> 843 | G23: =Kovas!D254 -> 1695 | H23: =Balandis!D259 -> 1844 | I23: =Gegužė!D254 -> 2122 | J23: =Birželis!D254 -> 114 | K23: =Liepa!D254 -> 0 | L23: =Rugpjūtis!D254 -> 0 | M23: =Rugsėjis!D254 -> 0 | N23: =Spalis!D254 -> 0 | O23: =Lapkritis!D254 -> 0 | P23: =Gruodis!D254 -> 0 | Q23: =SUM(E23:P23,R23) -> 6815
D24: Apdorota įvykių nuotoliu | E24: =Sausis!E253 -> 192 | F24: =Vasaris!E250 -> 815 | G24: =Kovas!E254 -> 1636 | H24: =Balandis!E259 -> 1770 | I24: =Gegužė!E254 -> 2020 | J24: =Birželis!E254 -> 110 | K24: =Liepa!E254 -> 0 | L24: =Rugpjūtis!E254 -> 0 | M24: =Rugsėjis!E254 -> 0 | N24: =Spalis!E254 -> 0 | O24: =Lapkritis!E254 -> 0 | P24: =Gruodis!E254 -> 0 | Q24: =SUM(E24:P24,R24) -> 6543
D25: Tikslinamos aplinkybės (M) | E25: =Sausis!O253 -> 59 | F25: =Vasaris!O250 -> 94 | G25: =Kovas!O253 -> 99 | H25: =Balandis!O258 -> 62 | I25: =Gegužė!O253 -> 59 | J25: =Birželis!O253 -> 4 | K25: =Liepa!O253 -> 0 | L25: =Rugpjūtis!O253 -> 0 | M25: =Rugsėjis!O253 -> 0 | N25: =Spalis!O253 -> 0 | O25: =Lapkritis!O253 -> 0 | P25: =Gruodis!O253 -> 0 | Q25: =SUM(E25:P25,R25) -> 377
D26: Pradėta IT | E26: =Sausis!P253 -> 301 | F26: =Vasaris!P250 -> 210 | G26: =Kovas!P250 -> 214 | H26: =Balandis!P258 -> 133 | I26: =Gegužė!P253 -> 139 | J26: =Birželis!P250 -> 0 | K26: =Liepa!P250 -> 0 | L26: =Rugpjūtis!P250 -> 0 | M26: =Rugsėjis!P250 -> 0 | N26: =Spalis!P250 -> 0 | O26: =Lapkritis!P250 -> 0 | P26: =Gruodis!P250 -> 0 | Q26: =SUM(E26:P26,R26) -> 997
D27: Informuotos kitos institucijos | E27: =Sausis!F254 -> 28 | F27: =Vasaris!F251 -> 184 | G27: =Kovas!F254 -> 457 | H27: =Balandis!F259 -> 1478 | I27: =Gegužė!F254 -> 1167 | J27: =Birželis!F254 -> 60 | K27: =Liepa!F254 -> 0 | L27: =Rugpjūtis!F254 -> 0 | M27: =Rugsėjis!F254 -> 0 | N27: =Spalis!F254 -> 0 | O27: =Lapkritis!F254 -> 0 | P27: =Gruodis!F254 -> 0 | Q27: =SUM(E27:P27,R27) -> 3374
D28: Bankas | E28: =Sausis!F253 -> 12 | F28: =Vasaris!F250 -> 88 | G28: =Kovas!F253 -> 271 | H28: =Balandis!F258 -> 605 | I28: =Gegužė!F253 -> 345 | J28: =Birželis!F253 -> 21 | K28: =Liepa!F253 -> 0 | L28: =Rugpjūtis!F253 -> 0 | M28: =Rugsėjis!F253 -> 0 | N28: =Spalis!F253 -> 0 | O28: =Lapkritis!F253 -> 0 | P28: =Gruodis!F253 -> 0 | Q28: =SUM(E28:P28,R28) -> 1342
D29: RRT | E29: =Sausis!G253 -> 0 | F29: =Vasaris!G250 -> 0 | G29: =Kovas!G253 -> 0 | H29: =Balandis!G258 -> 638 | I29: =Gegužė!G253 -> 632 | J29: =Birželis!G253 -> 17 | K29: =Liepa!G253 -> 0 | L29: =Rugpjūtis!G253 -> 0 | M29: =Rugsėjis!G253 -> 0 | N29: =Spalis!G253 -> 0 | O29: =Lapkritis!G253 -> 0 | P29: =Gruodis!G253 -> 0 | Q29: =SUM(E29:P29,R29) -> 1287
D30: FNTT | E30: =Sausis!H253 -> 0 | F30: =Vasaris!H250 -> 0 | G30: =Kovas!H253 -> 1 | H30: =Balandis!H258 -> 0 | I30: =Gegužė!H253 -> 3 | J30: =Birželis!H253 -> 0 | K30: =Liepa!H253 -> 0 | L30: =Rugpjūtis!H253 -> 0 | M30: =Rugsėjis!H253 -> 0 | N30: =Spalis!H253 -> 0 | O30: =Lapkritis!H253 -> 0 | P30: =Gruodis!H253 -> 0 | Q30: =SUM(E30:P30,R30) -> 4
D31: NKSC | E31: =Sausis!I253 -> 4 | F31: =Vasaris!I250 -> 31 | G31: =Kovas!I253 -> 60 | H31: =Balandis!I258 -> 108 | I31: =Gegužė!I253 -> 100 | J31: =Birželis!I253 -> 13 | K31: =Liepa!I253 -> 0 | L31: =Rugpjūtis!I253 -> 0 | M31: =Rugsėjis!I253 -> 0 | N31: =Spalis!I253 -> 0 | O31: =Lapkritis!I253 -> 0 | P31: =Gruodis!I253 -> 0 | Q31: =SUM(E31:P31,R31) -> 316
D32: Facebook | E32: =Sausis!J253 -> 8 | F32: =Vasaris!J250 -> 55 | G32: =Kovas!J253 -> 125 | H32: =Balandis!J258 -> 127 | I32: =Gegužė!J253 -> 86 | J32: =Birželis!$J253 -> 9 | K32: =Liepa!J253 -> 0 | L32: =Rugpjūtis!J253 -> 0 | M32: =Rugsėjis!J253 -> 0 | N32: =Spalis!J253 -> 0 | O32: =Lapkritis!J253 -> 0 | P32: =Gruodis!J253 -> 0 | Q32: =SUM(E32:P32,R32) -> 410
D33: Kita | E33: =Sausis!K253 -> 4 | F33: =Vasaris!K250 -> 10 | G33: =Kovas!K253 -> 0 | H33: =Balandis!K258 -> 0 | I33: =Gegužė!$K253 -> 1 | J33: =Birželis!K253 -> 0 | K33: =Liepa!K253 -> 0 | L33: =Rugpjūtis!K253 -> 0 | M33: =Rugsėjis!K253 -> 0 | N33: =Spalis!K253 -> 0 | O33: =Lapkritis!K253 -> 0 | P33: =Gruodis!K253 -> 0 | Q33: =SUM(E33:P33,R33) -> 15
D34: Pasisavintų lėšų suma (visų pranešimų) | E34: =Sausis!$L254 -> 46650.2 | F34: =Vasaris!L250 -> 993065.32 | G34: =Kovas!L254 -> 3079849.4 | H34: =Balandis!L259 -> 3214494.9 | I34: =Gegužė!L254 -> 3452913.4 | J34: =Birželis!L254 -> 295574.6 | K34: =Liepa!L254 -> 0 | L34: =Rugpjūtis!L254 -> 0 | M34: =Rugsėjis!L254 -> 0 | N34: =Spalis!L254 -> 0 | O34: =Lapkritis!L254 -> 0 | P34: =Gruodis!L254 -> 0 | Q34: =SUM(E34:P34,R34) -> 11082548
K36: METŲ REZULTATŲ LENTELĖS PVV3 DARBUOTOJAMS NEPILDYTI (turėtų skaičiuoti automatiškai)

Sheet Sausis
A1: 1
B2: Mėnesio diena | C2: Vardas, pavardė. Pamaina D/N | D2: Paimti ROIK pranešimai (skaičius) | E2: Apdorota | F2: INFORMUOTA | L2: Pasisavintų lėšų suma (visų pranešimų) | M2: Neapdorota (siųstos pajėgos) | N2: Kontrolinis | O2: Tikslinamos aplinkybės (M) | P2: Pradėta IT | Q2: Pastabos | T2: Kontr. Kasdienė eilutė (Žalos)
F3: Bankas | G3: RRT | H3: FNTT | I3: NKSC | J3: Facebook | K3: Kita/įrašyti
A4: =OFFSET('0'!$B$112,($A$1-1)*10,$B4-1) -> SV | B4: =OFFSET('0'!$B$111,($A$1-1)*10,0) -> 1 | M4: =SUM(D4-E4) -> 0 | N4: =SUM(E4,M4) -> 0
M5: =SUM(D5-E5) -> 0 | N5: =SUM(E5,M5) -> 0
M6: =SUM(D6-E6) -> 0 | N6: =SUM(E6,M6) -> 0
M7: =SUM(D7-E7) -> 0 | N7: =SUM(E7,M7) -> 0
M8: =SUM(D8-E8) -> 0 | N8: =SUM(E8,M8) -> 0
M9: =SUM(D9-E9) -> 0 | N9: =SUM(E9,M9) -> 0
C10: Iš viso Lietuvoje: | D10: =SUM(D4:D9) -> 0 | E10: =SUM(E4:E9) -> 0 | F10: =SUM(F4:F9) -> 0 | G10: =SUM(G4:G9) -> 0 | H10: =SUM(H4:H9) -> 0 | I10: =SUM(I4:I9) -> 0 | J10: =SUM(J4:J9) -> 0 | K10: =SUM(K4:K9) -> 0 | M10: =SUM(M4:M9) -> 0 | N10: =SUM(N4:N9) -> 0
C11: dienos foto | D11: =SUM(D4:D9) -> 0 | E11: =SUM(E4:E9) -> 0 | F11: =SUM(F10:K10) -> 0 | L11: =L10 -> 0 | M11: =SUM(M4:M9) -> 0 | N11: =SUM(N4:N9) -> 0 | O11: =SUM(O10) -> 0 | P11: =SUM(P10) -> 0 | T11: =$V$3+L11 -> 0
A12: =OFFSET('0'!$B$112,($A$1-1)*10,$B12-1) -> -- | B12: =OFFSET('0'!$B$111,($A$1-1)*10,1) -> 2 | M12: =SUM(D12-E12) -> 0 | N12: =SUM(E12,M12) -> 0
M13: =SUM(D13-E13) -> 0 | N13: =SUM(E13,M13) -> 0
M14: =SUM(D14-E14) -> 0 | N14: =SUM(E14,M14) -> 0
M15: =SUM(D15-E15) -> 0 | N15: =SUM(E15,M15) -> 0
M16: =SUM(D16-E16) -> 0 | N16: =SUM(E16,M16) -> 0
M17: =SUM(D17-E17) -> 0 | N17: =SUM(E17,M17) -> 0
C18: Iš viso Lietuvoje: | D18: =SUM(D12:D17) -> 0 | E18: =SUM(E12:E17) -> 0 | F18: =SUM(F12:F17) -> 0 | G18: =SUM(G12:G17) -> 0 | H18: =SUM(H12:H17) -> 0 | I18: =SUM(I12:I17) -> 0 | J18: =SUM(J12:J17) -> 0 | K18: =SUM(K12:K17) -> 0 | M18: =SUM(M12:M17) -> 0 | N18: =SUM(N12:N17) -> 0
C19: dienos foto | D19: =SUM(D12:D17) -> 0 | E19: =SUM(E12:E17) -> 0 | F19: =SUM(F18:K18) -> 0 | L19: =L18 -> 0 | M19: =SUM(M12:M17) -> 0 | N19: =SUM(N12:N17) -> 0 | O19: =SUM(O18) -> 0 | P19: =SUM(P18) -> 0 | T19: =$V$3+L11+L19 -> 0
A20: =OFFSET('0'!$B$112,($A$1-1)*10,$B20-1) -> -- | B20: =OFFSET('0'!$B$111,($A$1-1)*10,2) -> 3 | M20: =SUM(D20-E20) -> 0 | N20: =SUM(E20,M20) -> 0
M21: =SUM(D21-E21) -> 0 | N21: =SUM(E21,M21) -> 0
M22: =SUM(D22-E22) -> 0 | N22: =SUM(E22,M22) -> 0
M23: =SUM(D23-E23) -> 0 | N23: =SUM(E23,M23) -> 0
M24: =SUM(D24-E24) -> 0 | N24: =SUM(E24,M24) -> 0
M25: =SUM(D25-E25) -> 0 | N25: =SUM(E25,M25) -> 0
C26: Iš viso Lietuvoje: | D26: =SUM(D20:D25) -> 0 | E26: =SUM(E20:E25) -> 0 | F26: =SUM(F20:F25) -> 0 | G26: =SUM(G20:G25) -> 0 | H26: =SUM(H20:H25) -> 0 | I26: =SUM(I20:I25) -> 0 | J26: =SUM(J20:J25) -> 0 | K26: =SUM(K20:K25) -> 0 | M26: =SUM(M20:M25) -> 0 | N26: =SUM(N20:N25) -> 0
C27: dienos foto | D27: =SUM(D20:D25) -> 0 | E27: =SUM(E20:E25) -> 0 | F27: =SUM(F26:K26) -> 0 | L27: =L26 -> 0 | M27: =SUM(M20:M25) -> 0 | N27: =SUM(N20:N25) -> 0 | O27: =SUM(O26) -> 0 | P27: =SUM(P26) -> 0 | T27: =$V$3++L11+L19+L27 -> 0
A28: =OFFSET('0'!$B$112,($A$1-1)*10,$B28-1) -> SS | B28: =OFFSET('0'!$B$111,($A$1-1)*10,3) -> 4 | M28: =SUM(D28-E28) -> 0 | N28: =SUM(E28,M28) -> 0
M29: =SUM(D29-E29) -> 0 | N29: =SUM(E29,M29) -> 0
M30: =SUM(D30-E30) -> 0 | N30: =SUM(E30,M30) -> 0
M31: =SUM(D31-E31) -> 0 | N31: =SUM(E31,M31) -> 0
M32: =SUM(D32-E32) -> 0 | N32: =SUM(E32,M32) -> 0
M33: =SUM(D33-E33) -> 0 | N33: =SUM(E33,M33) -> 0
C34: Iš viso Lietuvoje: | D34: =SUM(D28:D33) -> 0 | E34: =SUM(E28:E33) -> 0 | F34: =SUM(F28:F33) -> 0 | G34: =SUM(G28:G33) -> 0 | H34: =SUM(H28:H33) -> 0 | I34: =SUM(I28:I33) -> 0 | J34: =SUM(J28:J33) -> 0 | K34: =SUM(K28:K33) -> 0 | M34: =SUM(M28:M33) -> 0 | N34: =SUM(N28:N33) -> 0
C35: dienos foto | D35: =SUM(D28:D33) -> 0 | E35: =SUM(E28:E33) -> 0 | F35: =SUM(F34:K34) -> 0 | L35: =L34 -> 0 | M35: =SUM(M28:M33) -> 0 | N35: =SUM(N28:N33) -> 0 | O35: =SUM(O34) -> 0 | P35: =SUM(P34) -> 0 | T35: =$V$3+L11+L19+L27+L35 -> 0
A36: =OFFSET('0'!$B$112,($A$1-1)*10,$B36-1) -> SK | B36: =OFFSET('0'!$B$111,($A$1-1)*10,4) -> 5 | M36: =SUM(D36-E36) -> 0 | N36: =SUM(E36,M36) -> 0
M37: =SUM(D37-E37) -> 0 | N37: =SUM(E37,M37) -> 0
M38: =SUM(D38-E38) -> 0 | N38: =SUM(E38,M38) -> 0
M39: =SUM(D39-E39) -> 0 | N39: =SUM(E39,M39) -> 0
M40: =SUM(D40-E40) -> 0 | N40: =SUM(E40,M40) -> 0
...

Sheet Vasaris
A1: 2
B2: Mėnesio diena | C2: Vardas, pavardė. Pamaina D/N | D2: Paimti ROIK pranešimai (skaičius) | E2: Apdorota | F2: INFORMUOTA | L2: Pasisavintų lėšų suma (visų pranešimų) | M2: Neapdorota (siųstos pajėgos) | N2: Kontrolinis | O2: Tikslinamos aplinkybės (M) | P2: Pradėta IT | Q2: Pastabos | T2: Kontr. Kasdienė eilutė (Žalos)
F3: Bankas | G3: RRT | H3: FNTT | I3: NKSC | J3: Facebook | K3: Kita/įrašyti | U3: Praeitų mėn. Žalos | V3: =SUM('Bendras metų'!V6) -> 46650.2
A4: =OFFSET('0'!$B$112,($A$1-1)*10,$B4-1) -> SS | B4: =OFFSET('0'!$B$111,($A$1-1)*10,0) -> 1 | D4: 7 | E4: 7 | J4: 1 | M4: =SUM(D4-E4) -> 0 | N4: =SUM(E4,M4) -> 7
M5: =SUM(D5-E5) -> 0 | N5: =SUM(E5,M5) -> 0
C6: Iš viso Lietuvoje: | D6: =SUM(D4:D5) -> 7 | E6: =SUM(E4:E5) -> 7 | F6: =SUM(F4:F5) -> 0 | G6: =SUM(G4:G5) -> 0 | H6: =SUM(H4:H5) -> 0 | I6: =SUM(I4:I5) -> 0 | J6: =SUM(J4:J5) -> 1 | K6: =SUM(K4:K5) -> 0 | ... N6: =SUM(N4:N5) -> 7 | P6: 55
C7: dienos foto | D7: =SUM(D4:D5) -> 7 | E7: =SUM(E4:E5) -> 7 | F7: =SUM(F6:K6) -> 1 | L7: =L6 -> 0 | M7: =SUM(M4:M5) -> 0 | N7: =SUM(N4:N5) -> 7 | O7: =SUM(O6) -> 0 | P7: =SUM(P6) -> 55 | T7: =$V$3+L7 -> 46650.2
A8: =OFFSET('0'!$B$112,($A$1-1)*10,$B8-1) -> SK | B8: =OFFSET('0'!$B$111,($A$1-1)*10,1) -> 2 | D8: 4 | E8: 4 | F8: 2 | J8: 1 | L8: 227 | M8: =SUM(D8-E8) -> 0 | N8: =SUM(E8,M8) -> 4
D9: 3 | E9: 3 | L9: 50 | M9: =SUM(D9-E9) -> 0 | N9: =SUM(E9,M9) -> 3
D10: 7 | E10: 6 | J10: 1 | L10: 35 | M10: =SUM(D10-E10) -> 1 | N10: =SUM(E10,M10) -> 7
D11: 4 | E11: 4 | F11: 2 | J11: 1 | L11: 14448.5 | M11: =SUM(D11-E11) -> 0 | N11: =SUM(E11,M11) -> 4
M12: =SUM(D12-E12) -> 0 | N12: =SUM(E12,M12) -> 0
M13: =SUM(D13-E13) -> 0 | N13: =SUM(E13,M13) -> 0
C14: Iš viso Lietuvoje: | D14: =SUM(D8:D13) -> 18 | E14: =SUM(E8:E13) -> 17 | F14: =SUM(F8:F13) -> 4 | G14: =SUM(G8:G13) -> 0 | H14: =SUM(H8:H13) -> 0 | I14: =SUM(I8:I13) -> 0 | J14: =SUM(J8:J13) -> 3 | K14: =SUM(K8:K13) -> 0 | ... N14: =SUM(N8:N13) -> 18
C15: dienos foto | D15: =SUM(D8:D13) -> 18 | E15: =SUM(E8:E13) -> 17 | F15: =SUM(F14:K14) -> 7 | L15: =L14 -> 14760.5 | M15: =SUM(M8:M13) -> 1 | N15: =SUM(N8:N13) -> 18 | O15: =SUM(O14) -> 0 | P15: =SUM(P14) -> 0 | T15: =$V$3+L7+L15 -> 61410.7
A16: =OFFSET('0'!$B$112,($A$1-1)*10,$B16-1) -> -- | B16: =OFFSET('0'!$B$111,($A$1-1)*10,2) -> 3 | D16: 4 | E16: 4 | F16: 2 | J16: 1 | L16: 53 | M16: =SUM(D16-E16) -> 0 | N16: =SUM(E16,M16) -> 4
D17: 29 | E17: 29 | F17: 2 | I17: 1 | J17: 1 | K17: 1 | L17: 1953.24 | M17: =SUM(D17-E17) -> 0 | N17: =SUM(E17,M17) -> 29
D18: 33 | E18: 30 | F18: 1 | J18: 1 | L18: 16760 | M18: =SUM(D18-E18) -> 3 | N18: =SUM(E18,M18) -> 33
D19: 27 | E19: 27 | F19: 2 | I19: 2 | L19: 4045.43 | M19: =SUM(D19-E19) -> 0 | N19: =SUM(E19,M19) -> 27
M20: =SUM(D20-E20) -> 0 | N20: =SUM(E20,M20) -> 0
M21: =SUM(D21-E21) -> 0 | N21: =SUM(E21,M21) -> 0
C22: Iš viso Lietuvoje: | D22: =SUM(D16:D21) -> 93 | E22: =SUM(E16:E21) -> 90 | F22: =SUM(F16:F21) -> 7 | G22: =SUM(G16:G21) -> 0 | H22: =SUM(H16:H21) -> 0 | I22: =SUM(I16:I21) -> 3 | J22: =SUM(J16:J21) -> 3 | K22: =SUM(K16:K21) -> 1 | ... N22: =SUM(N16:N21) -> 93
C23: dienos foto | D23: =SUM(D16:D21) -> 93 | E23: =SUM(E16:E21) -> 90 | F23: =SUM(F22:K22) -> 14 | L23: =L22 -> 22811.67 | M23: =SUM(M16:M21) -> 3 | N23: =SUM(N16:N21) -> 93 | O23: =SUM(O22) -> 0 | P23: =SUM(P22) -> 0 | T23: =$V$3+L7+L15+L23 -> 84222.37
A24: =OFFSET('0'!$B$112,($A$1-1)*10,$B24-1) -> -- | B24: =OFFSET('0'!$B$111,($A$1-1)*10,3) -> 4 | D24: 31 | E24: 31 | F24: 2 | I24: 1 | J24: 1 | K24: 3 | L24: 180 | M24: =SUM(D24-E24) -> 0 | N24: =SUM(E24,M24) -> 31
D25: 9 | E25: 9 | L25: 18506 | M25: =SUM(D25-E25) -> 0 | N25: =SUM(E25,M25) -> 9
D26: 26 | E26: 26 | F26: 5 | J26: 4 | L26: 997 | M26: =SUM(D26-E26) -> 0 | N26: =SUM(E26,M26) -> 26
D27: 30 | E27: 30 | F27: 3 | L27: 1015 | M27: =SUM(D27-E27) -> 0 | N27: =SUM(E27,M27) -> 30
M28: =SUM(D28-E28) -> 0 | N28: =SUM(E28,M28) -> 0
M29: =SUM(D29-E29) -> 0 | N29: =SUM(E29,M29) -> 0
C30: Iš viso Lietuvoje: | D30: =SUM(D24:D29) -> 96 | E30: =SUM(E24:E29) -> 96 | F30: =SUM(F24:F29) -> 10 | G30: =SUM(G24:G29) -> 0 | H30: =SUM(H24:H29) -> 0 | I30: =SUM(I24:I29) -> 1 | J30: =SUM(J24:J29) -> 5 | K30: =SUM(K24:K29) -> 3 | ... N30: =SUM(N24:N29) -> 96
C31: dienos foto | D31: =SUM(D24:D29) -> 96 | E31: =SUM(E24:E29) -> 96 | F31: =SUM(F30:K30) -> 19 | L31: =L30 -> 20698 | M31: =SUM(M24:M29) -> 0 | N31: =SUM(N24:N29) -> 96 | O31: =SUM(O30) -> 0 | P31: =SUM(P30) -> 0 | T31: =$V$3+L7+L15+L23+L31 -> 104920.37
A32: =OFFSET('0'!$B$112,($A$1-1)*10,$B32-1) -> -- | B32: =OFFSET('0'!$B$111,($A$1-1)*10,4) -> 5 | D32: 40 | E32: 39 | F32: 2 | L32: 2651.17 | M32: =SUM(D32-E32) -> 1 | N32: =SUM(E32,M32) -> 40
D33: 10 | E33: 9 | F33: 2 | I33: 1 | J33: 4 | K33: 1 | L33: 10762.29 | M33: =SUM(D33-E33) -> 1 | N33: =SUM(E33,M33) -> 10
D34: 49 | E34: 48 | F34: 2 | I34: 1 | J34: 4 | K34: 1 | L34: 44184.93 | M34: =SUM(D34-E34) -> 1 | N34: =SUM(E34,M34) -> 49
M35: =SUM(D35-E35) -> 0 | N35: =SUM(E35,M35) -> 0
M36: =SUM(D36-E36) -> 0 | N36: =SUM(E36,M36) -> 0
M37: =SUM(D37-E37) -> 0 | N37: =SUM(E37,M37) -> 0
C38: Iš viso Lietuvoje: | D38: =SUM(D32:D37) -> 99 | E38: =SUM(E32:E37) -> 96 | F38: =SUM(F32:F37) -> 6 | G38: =SUM(G32:G37) -> 0 | H38: =SUM(H32:H37) -> 0 | I38: =SUM(I32:I37) -> 2 | J38: =SUM(J32:J37) -> 8 | K38: =SUM(K32:K37) -> 2 | ... N38: =SUM(N32:N37) -> 99
C39: dienos foto | D39: =SUM(D32:D37) -> 99 | E39: =SUM(E32:E37) -> 96 | F39: =SUM(F38:K38) -> 18 | L39: =L38 -> 57598.39 | M39: =SUM(M32:M37) -> 3 | N39: =SUM(N32:N37) -> 99 | O39: =SUM(O38) -> 0 | P39: =SUM(P38) -> 0 | T39: =$V$3+L7+L15+L23+L31+L39 -> 162518.76
A40: =OFFSET('0'!$B$112,($A$1-1)*10,$B40-1) -> -- | B40: =OFFSET('0'!$B$111,($A$1-1)*10,5) -> 6 | D40: 17 | E40: 17 | F40: 1 | I40: 2 | K40: 1 | L40: 1937.67 | M40: =SUM(D40-E40) -> 0 | N40: =SUM(E40,M40) -> 17
...

Sheet Kovas
A1: 3
B2: Mėnesio diena | C2: Vardas, pavardė. Pamaina D/N | D2: Paimti ROIK pranešimai (skaičius) | E2: Apdorota | F2: INFORMUOTA | L2: Pasisavintų lėšų suma (visų pranešimų) | M2: Neapdorota (siųstos pajėgos) | N2: Kontrolinis | O2: Tikslinamos aplinkybės (M) | P2: Pradėta IT | Q2: Pastabos | T2: Kontr. Kasdienė eilutė (Žalos)
F3: Bankas | G3: RRT | H3: FNTT | I3: NKSC | J3: Facebook | K3: Kita/įrašyti | U3: Praeitų mėn. Žalos | V3: =SUM('Bendras metų'!V6:V7) -> 1039715.5
A4: =OFFSET('0'!$B$112,($A$1-1)*10,$B4-1) -> SS | B4: =OFFSET('0'!$B$111,($A$1-1)*10,0) -> 1 | C4: Jurijus Aleksejevas, N. | D4: 1 | E4: 1 | F4: 1 | L4: 20 | M4: =SUM(D4-E4) -> 0 | N4: =SUM(E4,M4) -> 1
C5: Vitalija Jokubynienė, D. | D5: 7 | E5: 7 | F5: 2 | I5: 2 | J5: 2 | L5: 1870 | M5: =SUM(D5-E5) -> 0 | N5: =SUM(E5,M5) -> 7
C6: Giedrė Sajetaitė, D. | D6: 9 | E6: 9 | F6: 4 | I6: 1 | J6: 2 | M6: =SUM(D6-E6) -> 0 | N6: =SUM(E6,M6) -> 9
C7: Tomas Žuramskas, N. | D7: 9 | E7: 9 | F7: 2 | M7: =SUM(D7-E7) -> 0 | N7: =SUM(E7,M7) -> 9
M8: =SUM(D8-E8) -> 0 | N8: =SUM(E8,M8) -> 0
M9: =SUM(D9-E9) -> 0 | N9: =SUM(E9,M9) -> 0
C10: Iš viso Lietuvoje: | D10: =SUM(D4:D9) -> 26 | E10: =SUM(E4:E9) -> 26 | F10: =SUM(F4:F9) -> 9 | G10: =SUM(G4:G9) -> 0 | H10: =SUM(H4:H9) -> 0 | I10: =SUM(I4:I9) -> 3 | J10: =SUM(J4:J9) -> 4 | K10: =SUM(K4:K9) -> 0 | L10: 5898.63 | M10: =SUM(M4:M9) -> 0 | N10: =SUM(N4:N9) -> 26
C11: dienos foto | D11: =SUM(D4:D9) -> 26 | E11: =SUM(E4:E9) -> 26 | F11: =SUM(F10:K10) -> 16 | L11: =L10 -> 5898.63 | M11: =SUM(M4:M9) -> 0 | N11: =SUM(N4:N9) -> 26 | O11: =SUM(O10) -> 0 | P11: =SUM(P10) -> 0 | T11: =$V$3+L11 -> 1045614.2
A12: =OFFSET('0'!$B$112,($A$1-1)*10,$B12-1) -> SK | B12: =OFFSET('0'!$B$111,($A$1-1)*10,1) -> 2 | C12: Tomas Žuramskas, N. | D12: 0 | E12: 0 | M12: =SUM(D12-E12) -> 0 | N12: =SUM(E12,M12) -> 0
C13: Vitalija Jokubynienė, D. | D13: 3 | E13: 3 | F13: 1 | I13: 1 | L13: 20 | M13: =SUM(D13-E13) -> 0 | N13: =SUM(E13,M13) -> 3
C14: Laura Mendelienė, D. | D14: 4 | E14: 4 | L14: 8000 | M14: =SUM(D14-E14) -> 0 | N14: =SUM(E14,M14) -> 4
C15: Jurgita Pilypaitienė, N. | D15: 5 | E15: 5 | F15: 1 | I15: 1 | J15: 2 | L15: 470 | M15: =SUM(D15-E15) -> 0 | N15: =SUM(E15,M15) -> 5
M16: =SUM(D16-E16) -> 0 | N16: =SUM(E16,M16) -> 0
M17: =SUM(D17-E17) -> 0 | N17: =SUM(E17,M17) -> 0
C18: Iš viso Lietuvoje: | D18: =SUM(D12:D17) -> 12 | E18: =SUM(E12:E17) -> 12 | F18: =SUM(F12:F17) -> 2 | G18: =SUM(G12:G17) -> 0 | H18: =SUM(H12:H17) -> 0 | I18: =SUM(I12:I17) -> 2 | J18: =SUM(J12:J17) -> 2 | K18: =SUM(K12:K17) -> 0 | L18: 8490 | M18: =SUM(M12:M17) -> 0 | N18: =SUM(N12:N17) -> 12
C19: dienos foto | D19: =SUM(D12:D17) -> 12 | E19: =SUM(E12:E17) -> 12 | F19: =SUM(F18:K18) -> 6 | L19: =L18 -> 8490 | M19: =SUM(M12:M17) -> 0 | N19: =SUM(N12:N17) -> 12 | O19: =SUM(O18) -> 0 | P19: =SUM(P18) -> 0 | T19: =$V$3+L11+L19 -> 1054104.1
A20: =OFFSET('0'!$B$112,($A$1-1)*10,$B20-1) -> -- | B20: =OFFSET('0'!$B$111,($A$1-1)*10,2) -> 3 | C20: Jurgita Pilypaitienė, N. | D20: 1 | E20: 1 | F20: 1 | J20: 1 | L20: 100 | M20: =SUM(D20-E20) -> 0 | N20: =SUM(E20,M20) -> 1
C21: Vaidas Šeduikis, D. | D21: 22 | E21: 21 | F21: 3 | J21: 1 | M21: =SUM(D21-E21) -> 1 | N21: =SUM(E21,M21) -> 22
C22: Laura Mendelienė, D. | D22: 21 | E22: 20 | F22: 2 | L22: 15726.73 | M22: =SUM(D22-E22) -> 1 | N22: =SUM(E22,M22) -> 21
C23: Vitalija Jokubynienė, N. | D23: 8 | E23: 8 | F23: 4 | I23: 1 | J23: 1 | L23: 83094.9 | M23: =SUM(D23-E23) -> 0 | N23: =SUM(E23,M23) -> 8
M24: =SUM(D24-E24) -> 0 | N24: =SUM(E24,M24) -> 0
M25: =SUM(D25-E25) -> 0 | N25: =SUM(E25,M25) -> 0
C26: Iš viso Lietuvoje: | D26: =SUM(D20:D25) -> 52 | E26: =SUM(E20:E25) -> 50 | F26: =SUM(F20:F25) -> 10 | G26: =SUM(G20:G25) -> 0 | H26: =SUM(H20:H25) -> 0 | I26: =SUM(I20:I25) -> 1 | J26: =SUM(J20:J25) -> 3 | K26: =SUM(K20:K25) -> 0 | L26: 237146.93 | M26: =SUM(M20:M25) -> 2 | N26: =SUM(N20:N25) -> 52
C27: dienos foto | D27: =SUM(D20:D25) -> 52 | E27: =SUM(E20:E25) -> 50 | F27: =SUM(F26:K26) -> 14 | L27: =L26 -> 237146.93 | M27: =SUM(M20:M25) -> 2 | N27: =SUM(N20:N25) -> 52 | O27: =SUM(O26) -> 0 | P27: =SUM(P26) -> 0 | T27: =$V$3++L11+L19+L27 -> 1291251.1
A28: =OFFSET('0'!$B$112,($A$1-1)*10,$B28-1) -> -- | B28: =OFFSET('0'!$B$111,($A$1-1)*10,3) -> 4 | C28: Vitalija Jokubynienė, N. | D28: 1 | E28: 1 | L28: 43.98 | M28: =SUM(D28-E28) -> 0 | N28: =SUM(E28,M28) -> 1
C29: Saulius Merkininkas, D. | D29: 20 | E29: 20 | F29: 5 | I29: 1 | J29: 2 | L29: 10257.5 | M29: =SUM(D29-E29) -> 0 | N29: =SUM(E29,M29) -> 20
C30: Vaidas Šeduikis, D. | D30: 16 | E30: 16 | F30: 1 | J30: 1 | L30: 266.74 | M30: =SUM(D30-E30) -> 0 | N30: =SUM(E30,M30) -> 16
C31: Jurgita Pilypaitienė, D. | D31: 17 | E31: 16 | F31: 4 | J31: 1 | L31: 33937.72 | M31: =SUM(D31-E31) -> 1 | N31: =SUM(E31,M31) -> 17 | Q31: 14-16 val. pas gydytojus
C32: Laura Mendelienė, N. | D32: 10 | E32: 10 | F32: 2 | J32: 1 | L32: 26447 | M32: =SUM(D32-E32) -> 0 | N32: =SUM(E32,M32) -> 10
M33: =SUM(D33-E33) -> 0 | N33: =SUM(E33,M33) -> 0
C34: Iš viso Lietuvoje: | D34: =SUM(D28:D33) -> 64 | E34: =SUM(E28:E33) -> 63 | F34: =SUM(F28:F33) -> 12 | G34: =SUM(G28:G33) -> 0 | H34: =SUM(H28:H33) -> 0 | I34: =SUM(I28:I33) -> 1 | J34: =SUM(J28:J33) -> 5 | K34: =SUM(K28:K33) -> 0 | L34: 107906.3 | M34: =SUM(M28:M33) -> 1 | N34: =SUM(N28:N33) -> 64
C35: dienos foto | D35: =SUM(D28:D33) -> 64 | E35: =SUM(E28:E33) -> 63 | F35: =SUM(F34:K34) -> 18 | L35: =L34 -> 107906.3 | M35: =SUM(M28:M33) -> 1 | N35: =SUM(N28:N33) -> 64 | O35: =SUM(O34) -> 0 | P35: =SUM(P34) -> 0 | T35: =$V$3+L11+L19+L27+L35 -> 1399157.4
A36: =OFFSET('0'!$B$112,($A$1-1)*10,$B36-1) -> -- | B36: =OFFSET('0'!$B$111,($A$1-1)*10,4) -> 5 | C36: Laura Mendelienė, N. | D36: 1 | E36: 1 | F36: 1 | M36: =SUM(D36-E36) -> 0 | N36: =SUM(E36,M36) -> 1
C37: Saulius Merkininkas, D. | D37: 31 | E37: 31 | F37: 5 | I37: 1 | J37: 2 | L37: 6160.99 | M37: =SUM(D37-E37) -> 0 | N37: =SUM(E37,M37) -> 31
C38: Jurgita Pilypaitienė, D. | D38: 29 | E38: 27 | F38: 2 | I38: 1 | J38: 1 | L38: 879.13 | M38: =SUM(D38-E38) -> 2 | N38: =SUM(E38,M38) -> 29
C39: Vaidas Šeduikis, N. | D39: 11 | E39: 11 | F39: 3 | I39: 1 | J39: 1 | M39: =SUM(D39-E39) -> 0 | N39: =SUM(E39,M39) -> 11
M40: =SUM(D40-E40) -> 0 | N40: =SUM(E40,M40) -> 0
...

Sheet Balandis
A1: 4
B2: Mėnesio diena | C2: Vardas, pavardė. Pamaina D/N | D2: Paimti ROIK pranešimai (skaičius) | E2: Apdorota | F2: INFORMUOTA | L2: Pasisavintų lėšų suma (visų pranešimų) | M2: Neapdorota (siųstos pajėgos) | N2: Kontrolinis | O2: Tikslinamos aplinkybės (M) | P2: Pradėta IT | Q2: Pastabos | T2: Kontr. Kasdienė eilutė (Žalos)
F3: Bankas | G3: RRT | H3: FNTT | I3: NKSC | J3: Facebook | K3: Kita/įrašyti | U3: Praeitų mėn. Žalos | V3: =SUM('Bendras metų'!V6:V8) -> 4119564.9
A4: =OFFSET('0'!$B$112,($A$1-1)*10,$B4-1) -> -- | B4: =OFFSET('0'!$B$111,($A$1-1)*10,0) -> 1 | C4: Vaidas Šeduikis, N. | D4: 14 | E4: 12 | F4: 6 | J4: 4 | M4: =SUM(D4-E4) -> 2 | N4: =SUM(E4,M4) -> 14
C5: Aidas Kiukys, D. | D5: 5 | E5: 5 | I5: 1 | M5: =SUM(D5-E5) -> 0 | N5: =SUM(E5,M5) -> 5
C6: Jurijus Aleksejevas, D. | D6: 1 | E6: 1 | M6: =SUM(D6-E6) -> 0 | N6: =SUM(E6,M6) -> 1
C7: Laura Mendelienė, D. | D7: 4 | E7: 3 | M7: =SUM(D7-E7) -> 1 | N7: =SUM(E7,M7) -> 4
C8: Laura Mendelienė, D. | D8: 17 | E8: 16 | F8: 4 | M8: =SUM(D8-E8) -> 1 | N8: =SUM(E8,M8) -> 17
C9: Giedrė Sajetaitė, D. | D9: 23 | E9: 23 | F9: 4 | J9: 3 | M9: =SUM(D9-E9) -> 0 | N9: =SUM(E9,M9) -> 23
C10: Vaidas Šeduikis, N. | M10: =SUM(D10-E10) -> 0 | N10: =SUM(E10,M10) -> 0
C11: Iš viso Lietuvoje: | D11: =SUM(D4:D10) -> 64 | E11: =SUM(E4:E10) -> 60 | F11: =SUM(F4:F10) -> 14 | G11: =SUM(G4:G10) -> 0 | H11: =SUM(H4:H10) -> 0 | I11: =SUM(I4:I10) -> 1 | J11: =SUM(J4:J10) -> 7 | K11: =SUM(K4:K10) -> 0 | L11: 84414.55 | M11: =SUM(M4:M10) -> 4 | N11: =SUM(N4:N10) -> 64 | O11: 6 | P11: 15
C12: dienos foto | D12: =SUM(D4:D10) -> 64 | E12: =SUM(E4:E10) -> 60 | F12: =SUM(F11:K11) -> 22 | L12: =L11 -> 84414.55 | M12: =SUM(M4:M10) -> 4 | N12: =SUM(N4:N10) -> 64 | O12: =SUM(O11) -> 6 | P12: =SUM(P11) -> 15 | T12: =$V$3+L12 -> 4203979.5
A13: =OFFSET('0'!$B$112,($A$1-1)*10,$B13-1) -> -- | B13: =OFFSET('0'!$B$111,($A$1-1)*10,1) -> 2 | C13: Vaidas Šeduikis, N. | D13: 1 | E13: 1 | F13: 1 | M13: =SUM(D13-E13) -> 0 | N13: =SUM(E13,M13) -> 1
C14: Jurijus Aleksejevas, D. | D14: 3 | E14: 3 | F14: 1 | I14: 2 | J14: 1 | L14: 1100 | M14: =SUM(D14-E14) -> 0 | N14: =SUM(E14,M14) -> 3
C15: Aidas Kiukys, D. | D15: 5 | E15: 5 | M15: =SUM(D15-E15) -> 0 | N15: =SUM(E15,M15) -> 5
C16: Dalius Bacevičius, D. | D16: 8 | E16: 8 | L16: 11000 | M16: =SUM(D16-E16) -> 0 | N16: =SUM(E16,M16) -> 8
C17: Evaldas Maskeliūnas, D. | D17: 3 | E17: 2 | F17: 1 | J17: 1 | L17: 230140 | M17: =SUM(D17-E17) -> 1 | N17: =SUM(E17,M17) -> 3
C18: Laura Mendelienė, D. | D18: 13 | E18: 13 | F18: 1 | I18: 1 | L18: 22673 | M18: =SUM(D18-E18) -> 0 | N18: =SUM(E18,M18) -> 13
C19: Saulius Merkininkas, D. | D19: 14 | E19: 13 | L19: 20461.43 | M19: =SUM(D19-E19) -> 1 | N19: =SUM(E19,M19) -> 14
C20: Giedrė Sajetaitė, N. | D20: 16 | E20: 16 | F20: 3 | L20: 277972.71 | M20: =SUM(D20-E20) -> 0 | N20: =SUM(E20,M20) -> 16
C21: Iš viso Lietuvoje: | D21: =SUM(D13:D20) -> 63 | E21: =SUM(E13:E20) -> 61 | F21: =SUM(F13:F20) -> 7 | G21: =SUM(G13:G20) -> 0 | H21: =SUM(H13:H20) -> 0 | I21: =SUM(I13:I20) -> 3 | J21: =SUM(J13:J20) -> 2 | K21: =SUM(K13:K20) -> 0 | ... N21: =SUM(N13:N20) -> 63 | O21: 9 | P21: 6
C22: dienos foto | D22: =SUM(D13:D20) -> 63 | E22: =SUM(E13:E20) -> 61 | F22: =SUM(F21:K21) -> 12 | L22: =L21 -> 563347.14 | M22: =SUM(M13:M20) -> 2 | N22: =SUM(N13:N20) -> 63 | O22: =SUM(O21) -> 9 | P22: =SUM(P21) -> 6 | T22: =$V$3+L12+L22 -> 4767326.6
A23: =OFFSET('0'!$B$112,($A$1-1)*10,$B23-1) -> -- | B23: =OFFSET('0'!$B$111,($A$1-1)*10,2) -> 3 | C23: Giedrė Sajetaitė, N. | D23: 3 | E23: 3 | M23: =SUM(D23-E23) -> 0 | N23: =SUM(E23,M23) -> 3
C24: Dalius Bacevičius, D. | D24: 9 | E24: 9 | J24: 1 | L24: 23 | M24: =SUM(D24-E24) -> 0 | N24: =SUM(E24,M24) -> 9
C25: Aidas Kiukys, D. | D25: 10 | E25: 9 | F25: 2 | I25: 1 | J25: 1 | L25: 200 | M25: =SUM(D25-E25) -> 1 | N25: =SUM(E25,M25) -> 10
C26: Jurijus Aleksejevas, D. | D26: 3 | E26: 3 | M26: =SUM(D26-E26) -> 0 | N26: =SUM(E26,M26) -> 3
C27: Tomas Žuramskas, D. | D27: 9 | E27: 9 | F27: 3 | I27: 1 | L27: 10173 | M27: =SUM(D27-E27) -> 0 | N27: =SUM(E27,M27) -> 9
C28: Jurgita Pilypaitienė, D. | D28: 15 | E28: 15 | F28: 3 | I28: 1 | L28: 13090.98 | M28: =SUM(D28-E28) -> 0 | N28: =SUM(E28,M28) -> 15
C29: Evaldas Maskeliūnas, D. | D29: 9 | E29: 9 | F29: 1 | L29: 65 | M29: =SUM(D29-E29) -> 0 | N29: =SUM(E29,M29) -> 9
C30: Saulius Merkininkas, N. | D30: 8 | E30: 8 | F30: 3 | J30: 2 | L30: 330 | M30: =SUM(D30-E30) -> 0 | N30: =SUM(E30,M30) -> 8
C31: Iš viso Lietuvoje: | D31: =SUM(D23:D30) -> 66 | E31: =SUM(E23:E30) -> 65 | F31: =SUM(F23:F30) -> 12 | G31: =SUM(G23:G30) -> 0 | H31: =SUM(H23:H30) -> 0 | I31: =SUM(I23:I30) -> 3 | J31: =SUM(J23:J30) -> 4 | K31: =SUM(K23:K30) -> 0 | L31: 240993.72 | M31: =SUM(M23:M30) -> 1 | N31: =SUM(N23:N30) -> 66 | O31: 5 | P31: 5
C32: dienos foto | D32: =SUM(D23:D30) -> 66 | E32: =SUM(E23:E30) -> 65 | F32: =SUM(F31:K31) -> 19 | L32: =L31 -> 240993.72 | M32: =SUM(M23:M30) -> 1 | N32: =SUM(N23:N30) -> 66 | O32: =SUM(O31) -> 5 | P32: =SUM(P31) -> 5 | T32: =$V$3++L12+L22+L32 -> 5008320.3
A33: =OFFSET('0'!$B$112,($A$1-1)*10,$B33-1) -> -- | B33: =OFFSET('0'!$B$111,($A$1-1)*10,3) -> 4 | C33: Saulius Merkininkas, N. | D33: 2 | E33: 2 | F33: 1 | L33: 1280 | M33: =SUM(D33-E33) -> 0 | N33: =SUM(E33,M33) -> 2
C34: Aidas Kiukys, D. | D34: 11 | E34: 11 | F34: 1 | J34: 1 | L34: 1300 | M34: =SUM(D34-E34) -> 0 | N34: =SUM(E34,M34) -> 11
C35: Evaldas Maskeliūnas, D. | D35: 7 | E35: 7 | F35: 1 | I35: 1 | L35: 838 | M35: =SUM(D35-E35) -> 0 | N35: =SUM(E35,M35) -> 7
C36: Vaidas Šeduikis, D. | D36: 14 | E36: 13 | F36: 1 | J36: 1 | M36: =SUM(D36-E36) -> 1 | N36: =SUM(E36,M36) -> 14
C37: Jurgita Pilypaitienė, D. | D37: 16 | E37: 15 | F37: 1 | L37: 6860 | M37: =SUM(D37-E37) -> 1 | N37: =SUM(E37,M37) -> 16
C38: Tomas Žuramskas, N. | D38: 6 | E38: 5 | M38: =SUM(D38-E38) -> 1 | N38: =SUM(E38,M38) -> 6
C39: Iš viso Lietuvoje: | D39: =SUM(D33:D38) -> 56 | E39: =SUM(E33:E38) -> 53 | F39: =SUM(F33:F38) -> 5 | G39: =SUM(G33:G38) -> 0 | H39: =SUM(H33:H38) -> 0 | I39: =SUM(I33:I38) -> 1 | J39: =SUM(J33:J38) -> 2 | K39: =SUM(K33:K38) -> 0 | L39: 56684.25 | M39: =SUM(M33:M38) -> 3 | N39: =SUM(N33:N38) -> 56 | O39: 4 | P39: 6
C40: dienos foto | D40: =SUM(D33:D38) -> 56 | E40: =SUM(E33:E38) -> 53 | F40: =SUM(F39:K39) -> 8 | L40: =L39 -> 56684.25 | M40: =SUM(M33:M38) -> 3 | N40: =SUM(N33:N38) -> 56 | O40: =SUM(O39) -> 4 | P40: =SUM(P39) -> 6 | T40: =$V$3+L12+L22+L32+L40 -> 5065004.6
...

Sheet Gegužė
A1: 5
B2: Mėnesio diena | C2: Vardas, pavardė. Pamaina D/N | D2: Paimti ROIK pranešimai (skaičius) | E2: Apdorota | F2: INFORMUOTA | L2: Pasisavintų lėšų suma (visų pranešimų) | M2: Neapdorota (siųstos pajėgos) | N2: Kontrolinis | O2: Tikslinamos aplinkybės (M) | P2: Pradėta IT | Q2: Pastabos | T2: Kontr. Kasdienė eilutė (Žalos)
F3: Bankas | G3: RRT | H3: FNTT | I3: NKSC | J3: Facebook | K3: Kita/įrašyti | U3: Praeitų mėn. Žalos | V3: =SUM('Bendras metų'!V6:V9) -> 7334059.8
A4: =OFFSET('0'!$B$112,($A$1-1)*10,$B4-1) -> SV | B4: =OFFSET('0'!$B$111,($A$1-1)*10,0) -> 1 | C4: Aidas Kiukys, N. | D4: 1 | E4: 1 | M4: =SUM(D4-E4) -> 0 | N4: =SUM(E4,M4) -> 1
C5: Jurgita Pilypaitienė, D. | D5: 14 | E5: 13 | F5: 1 | G5: 1 | L5: 18516.35 | M5: =SUM(D5-E5) -> 1 | N5: =SUM(E5,M5) -> 14
C6: Laura Mendelienė, D. | D6: 13 | E6: 13 | F6: 4 | G6: 6 | M6: =SUM(D6-E6) -> 0 | N6: =SUM(E6,M6) -> 13
C7: Tomas Žuramskas, D. | D7: 15 | E7: 15 | F7: 4 | G7: 3 | I7: 2 | J7: 1 | M7: =SUM(D7-E7) -> 0 | N7: =SUM(E7,M7) -> 15
C8: Evaldas Maskeliūnas, N. | D8: 11 | E8: 11 | F8: 3 | G8: 1 | M8: =SUM(D8-E8) -> 0 | N8: =SUM(E8,M8) -> 11
M9: =SUM(D9-E9) -> 0 | N9: =SUM(E9,M9) -> 0
C10: Iš viso Lietuvoje: | D10: =SUM(D4:D9) -> 54 | E10: =SUM(E4:E9) -> 53 | F10: =SUM(F4:F9) -> 12 | G10: =SUM(G4:G9) -> 11 | H10: =SUM(H4:H9) -> 0 | I10: =SUM(I4:I9) -> 2 | J10: =SUM(J4:J9) -> 1 | K10: =SUM(K4:K9) -> 0 | L10: 54053.34 | M10: =SUM(M4:M9) -> 1 | N10: =SUM(N4:N9) -> 54 | O10: 0 | P10: 2
C11: dienos foto | D11: =SUM(D4:D9) -> 54 | E11: =SUM(E4:E9) -> 53 | F11: =SUM(F10:K10) -> 26 | L11: =L10 -> 54053.34 | M11: =SUM(M4:M9) -> 1 | N11: =SUM(N4:N9) -> 54 | O11: =SUM(O10) -> 0 | P11: =SUM(P10) -> 2 | T11: =$V$3+L11 -> 7388113.2
A12: =OFFSET('0'!$B$112,($A$1-1)*10,$B12-1) -> -- | B12: =OFFSET('0'!$B$111,($A$1-1)*10,1) -> 2 | C12: Evaldas Maskeliūnas, N. | D12: 1 | E12: 1 | M12: =SUM(D12-E12) -> 0 | N12: =SUM(E12,M12) -> 1
C13: Jurgita Pilypaitienė, D. | D13: 28 | E13: 26 | F13: 3 | G13: 2 | I13: 3 | L13: 10406.1 | M13: =SUM(D13-E13) -> 2 | N13: =SUM(E13,M13) -> 28
C14: Vaidas Šeduikis, D. | D14: 34 | E14: 33 | F14: 8 | G14: 21 | I14: 3 | J14: 1 | M14: =SUM(D14-E14) -> 1 | N14: =SUM(E14,M14) -> 34
C15: Laura Mendelienė, N. | D15: 11 | E15: 11 | F15: 3 | G15: 1 | M15: =SUM(D15-E15) -> 0 | N15: =SUM(E15,M15) -> 11
M16: =SUM(D16-E16) -> 0 | N16: =SUM(E16,M16) -> 0
M17: =SUM(D17-E17) -> 0 | N17: =SUM(E17,M17) -> 0
C18: Iš viso Lietuvoje: | D18: =SUM(D12:D17) -> 74 | E18: =SUM(E12:E17) -> 71 | F18: =SUM(F12:F17) -> 14 | G18: =SUM(G12:G17) -> 24 | H18: =SUM(H12:H17) -> 0 | I18: =SUM(I12:I17) -> 6 | J18: =SUM(J12:J17) -> 1 | K18: =SUM(K12:K17) -> 0 | L18: 59724.29 | M18: =SUM(M12:M17) -> 3 | N18: =SUM(N12:N17) -> 74 | O18: 5 | P18: 4
C19: dienos foto | D19: =SUM(D12:D17) -> 74 | E19: =SUM(E12:E17) -> 71 | F19: =SUM(F18:K18) -> 45 | L19: =L18 -> 59724.29 | M19: =SUM(M12:M17) -> 3 | N19: =SUM(N12:N17) -> 74 | O19: =SUM(O18) -> 5 | P19: =SUM(P18) -> 4 | T19: =$V$3+L11+L19 -> 7447837.4
A20: =OFFSET('0'!$B$112,($A$1-1)*10,$B20-1) -> SS | B20: =OFFSET('0'!$B$111,($A$1-1)*10,2) -> 3 | C20: Laura Mendelienė, N. | D20: 0 | E20: 0 | M20: =SUM(D20-E20) -> 0 | N20: =SUM(E20,M20) -> 0
C21: Saulius Merkininkas, D. | D21: 15 | E21: 14 | F21: 6 | J21: 1 | M21: =SUM(D21-E21) -> 1 | N21: =SUM(E21,M21) -> 15
C22: Vaidas Šeduikis, D. | D22: 12 | E22: 12 | F22: 3 | G22: 1 | I22: 1 | M22: =SUM(D22-E22) -> 0 | N22: =SUM(E22,M22) -> 12
C23: Jurgita Pilypaitienė, N. | D23: 11 | E23: 9 | F23: 4 | I23: 2 | M23: =SUM(D23-E23) -> 2 | N23: =SUM(E23,M23) -> 11
M24: =SUM(D24-E24) -> 0 | N24: =SUM(E24,M24) -> 0
M25: =SUM(D25-E25) -> 0 | N25: =SUM(E25,M25) -> 0
C26: Iš viso Lietuvoje: | D26: =SUM(D20:D25) -> 38 | E26: =SUM(E20:E25) -> 35 | F26: =SUM(F20:F25) -> 13 | G26: =SUM(G20:G25) -> 1 | H26: =SUM(H20:H25) -> 0 | I26: =SUM(I20:I25) -> 3 | J26: =SUM(J20:J25) -> 1 | K26: =SUM(K20:K25) -> 0 | L26: 72817.81 | M26: =SUM(M20:M25) -> 3 | N26: =SUM(N20:N25) -> 38 | O26: 1 | P26: 2
C27: dienos foto | D27: =SUM(D20:D25) -> 38 | E27: =SUM(E20:E25) -> 35 | F27: =SUM(F26:K26) -> 18 | L27: =L26 -> 72817.81 | M27: =SUM(M20:M25) -> 3 | N27: =SUM(N20:N25) -> 38 | O27: =SUM(O26) -> 1 | P27: =SUM(P26) -> 2 | T27: =$V$3++L11+L19+L27 -> 7520655.3
A28: =OFFSET('0'!$B$112,($A$1-1)*10,$B28-1) -> SK | B28: =OFFSET('0'!$B$111,($A$1-1)*10,3) -> 4 | C28: Jurgita Pilypaitienė, N. | D28: 3 | E28: 1 | F28: 1 | M28: =SUM(D28-E28) -> 2 | N28: =SUM(E28,M28) -> 3
C29: Saulius Merkininkas, D. | D29: 10 | E29: 10 | F29: 2 | I29: 1 | J29: 1 | M29: =SUM(D29-E29) -> 0 | N29: =SUM(E29,M29) -> 10
C30: Giedrė Sajetaitė, D. | D30: 11 | E30: 11 | F30: 3 | G30: 6 | I30: 2 | M30: =SUM(D30-E30) -> 0 | N30: =SUM(E30,M30) -> 11
C31: Vaidas Šeduikis, N. | D31: 9 | E31: 9 | F31: 2 | M31: =SUM(D31-E31) -> 0 | N31: =SUM(E31,M31) -> 9
M32: =SUM(D32-E32) -> 0 | N32: =SUM(E32,M32) -> 0
M33: =SUM(D33-E33) -> 0 | N33: =SUM(E33,M33) -> 0
C34: Iš viso Lietuvoje: | D34: =SUM(D28:D33) -> 33 | E34: =SUM(E28:E33) -> 31 | F34: =SUM(F28:F33) -> 8 | G34: =SUM(G28:G33) -> 6 | H34: =SUM(H28:H33) -> 0 | I34: =SUM(I28:I33) -> 3 | J34: =SUM(J28:J33) -> 1 | K34: =SUM(K28:K33) -> 0 | L34: 20859.01 | M34: =SUM(M28:M33) -> 2 | N34: =SUM(N28:N33) -> 33
C35: dienos foto | D35: =SUM(D28:D33) -> 33 | E35: =SUM(E28:E33) -> 31 | F35: =SUM(F34:K34) -> 18 | L35: =L34 -> 20859.01 | M35: =SUM(M28:M33) -> 2 | N35: =SUM(N28:N33) -> 33 | O35: =SUM(O34) -> 0 | P35: =SUM(P34) -> 0 | T35: =$V$3+L11+L19+L27+L35 -> 7541514.3
A36: =OFFSET('0'!$B$112,($A$1-1)*10,$B36-1) -> -- | B36: =OFFSET('0'!$B$111,($A$1-1)*10,4) -> 5 | C36: Vaidas Šeduikis, N. | D36: 2 | E36: 2 | M36: =SUM(D36-E36) -> 0 | N36: =SUM(E36,M36) -> 2
C37: Evaldas Maskeliūnas, D. | D37: 23 | E37: 22 | F37: 1 | G37: 5 | I37: 1 | M37: =SUM(D37-E37) -> 1 | N37: =SUM(E37,M37) -> 23
C38: Tomas Žuramskas, D. | D38: 21 | E38: 21 | F38: 9 | G38: 4 | I38: 1 | J38: 2 | M38: =SUM(D38-E38) -> 0 | N38: =SUM(E38,M38) -> 21
C39: Giedrė Sajetaitė, D. | D39: 28 | E39: 28 | F39: 4 | G39: 16 | J39: 6 | M39: =SUM(D39-E39) -> 0 | N39: =SUM(E39,M39) -> 28
C40: Saulius Merkininkas, N. | D40: 12 | E40: 11 | F40: 3 | G40: 4 | J40: 1 | M40: =SUM(D40-E40) -> 1 | N40: =SUM(E40,M40) -> 12
...

Sheet Birželis
A1: 6
B2: Mėnesio diena | C2: Vardas, pavardė. Pamaina D/N | D2: Paimti ROIK pranešimai (skaičius) | E2: Apdorota | F2: INFORMUOTA | L2: Pasisavintų lėšų suma (visų pranešimų) | M2: Neapdorota (siųstos pajėgos) | N2: Kontrolinis | O2: Tikslinamos aplinkybės (M) | P2: Pradėta IT | Q2: Pastabos | T2: Kontr. Kasdienė eilutė (Žalos)
F3: Bankas | G3: RRT | H3: FNTT | I3: NKSC | J3: Facebook | K3: Kita/įrašyti | U3: Praeitų mėn. Žalos | V3: =SUM('Bendras metų'!V6:V10) -> 10786973
A4: =OFFSET('0'!$B$112,($A$1-1)*10,$B4-1) -> SK | B4: =OFFSET('0'!$B$111,($A$1-1)*10,0) -> 1 | C4: Vaidas Šeduikis, N. | D4: 1 | E4: 1 | F4: 1 | J4: 1 | M4: =SUM(D4-E4) -> 0 | N4: =SUM(E4,M4) -> 1
C5: Tomas Žuramskas, D. | D5: 4 | E5: 3 | J5: 1 | M5: =SUM(D5-E5) -> 1 | N5: =SUM(E5,M5) -> 4
C6: Saulius Merkininkas, D. | D6: 6 | E6: 6 | F6: 1 | M6: =SUM(D6-E6) -> 0 | N6: =SUM(E6,M6) -> 6
C7: Jurijus Aleksejevas, N. | D7: 11 | E7: 11 | F7: 6 | I7: 4 | J7: 2 | M7: =SUM(D7-E7) -> 0 | N7: =SUM(E7,M7) -> 11
M8: =SUM(D8-E8) -> 0 | N8: =SUM(E8,M8) -> 0
M9: =SUM(D9-E9) -> 0 | N9: =SUM(E9,M9) -> 0
C10: Iš viso Lietuvoje: | D10: =SUM(D4:D9) -> 22 | E10: =SUM(E4:E9) -> 21 | F10: =SUM(F4:F9) -> 8 | G10: =SUM(G4:G9) -> 0 | H10: =SUM(H4:H9) -> 0 | I10: =SUM(I4:I9) -> 4 | J10: =SUM(J4:J9) -> 4 | K10: =SUM(K4:K9) -> 0 | L10: 34315.27 | M10: =SUM(M4:M9) -> 1 | N10: =SUM(N4:N9) -> 22 | O10: 0 | P10: 2
C11: dienos foto | D11: =SUM(D4:D9) -> 22 | E11: =SUM(E4:E9) -> 21 | F11: =SUM(F10:K10) -> 16 | L11: =L10 -> 34315.27 | M11: =SUM(M4:M9) -> 1 | N11: =SUM(N4:N9) -> 22 | O11: =SUM(O10) -> 0 | P11: =SUM(P10) -> 2 | T11: =$V$3+L11 -> 10821288
A12: =OFFSET('0'!$B$112,($A$1-1)*10,$B12-1) -> -- | B12: =OFFSET('0'!$B$111,($A$1-1)*10,1) -> 2 | C12: Jurijus Aleksejevas, N. | D12: 2 | E12: 2 | F12: 1 | M12: =SUM(D12-E12) -> 0 | N12: =SUM(E12,M12) -> 2
C13: Tomas Žuramskas, D. | D13: 28 | E13: 27 | F13: 5 | G13: 6 | I13: 3 | J13: 3 | M13: =SUM(D13-E13) -> 1 | N13: =SUM(E13,M13) -> 28
C14: Aidas Kiukys, D. | D14: 42 | E14: 40 | F14: 3 | G14: 10 | I14: 4 | M14: =SUM(D14-E14) -> 2 | N14: =SUM(E14,M14) -> 42
C15: Saulius Merkininkas, N. | D15: 19 | E15: 19 | F15: 4 | G15: 1 | I15: 2 | J15: 2 | M15: =SUM(D15-E15) -> 0 | N15: =SUM(E15,M15) -> 19
M16: =SUM(D16-E16) -> 0 | N16: =SUM(E16,M16) -> 0
M17: =SUM(D17-E17) -> 0 | N17: =SUM(E17,M17) -> 0
C18: Iš viso Lietuvoje: | D18: =SUM(D12:D17) -> 91 | E18: =SUM(E12:E17) -> 88 | F18: =SUM(F12:F17) -> 13 | G18: =SUM(G12:G17) -> 17 | H18: =SUM(H12:H17) -> 0 | I18: =SUM(I12:I17) -> 9 | J18: =SUM(J12:J17) -> 5 | K18: =SUM(K12:K17) -> 0 | L18: 261259.33 | M18: =SUM(M12:M17) -> 3 | N18: =SUM(N12:N17) -> 91 | O18: 4 | P18: 8
C19: dienos foto | D19: =SUM(D12:D17) -> 91 | E19: =SUM(E12:E17) -> 88 | F19: =SUM(F18:K18) -> 44 | L19: =L18 -> 261259.33 | M19: =SUM(M12:M17) -> 3 | N19: =SUM(N12:N17) -> 91 | O19: =SUM(O18) -> 4 | P19: =SUM(P18) -> 8 | T19: =$V$3+L11+L19 -> 11082548
A20: =OFFSET('0'!$B$112,($A$1-1)*10,$B20-1) -> -- | B20: =OFFSET('0'!$B$111,($A$1-1)*10,2) -> 3 | C20: Saulius Merkininkas, N. | D20: 1 | E20: 1 | M20: =SUM(D20-E20) -> 0 | N20: =SUM(E20,M20) -> 1
M21: =SUM(D21-E21) -> 0 | N21: =SUM(E21,M21) -> 0
M22: =SUM(D22-E22) -> 0 | N22: =SUM(E22,M22) -> 0
M23: =SUM(D23-E23) -> 0 | N23: =SUM(E23,M23) -> 0
M24: =SUM(D24-E24) -> 0 | N24: =SUM(E24,M24) -> 0
M25: =SUM(D25-E25) -> 0 | N25: =SUM(E25,M25) -> 0
C26: Iš viso Lietuvoje: | D26: =SUM(D20:D25) -> 1 | E26: =SUM(E20:E25) -> 1 | F26: =SUM(F20:F25) -> 0 | G26: =SUM(G20:G25) -> 0 | H26: =SUM(H20:H25) -> 0 | I26: =SUM(I20:I25) -> 0 | J26: =SUM(J20:J25) -> 0 | K26: =SUM(K20:K25) -> 0 | M26: =SUM(M20:M25) -> 0 | N26: =SUM(N20:N25) -> 1
C27: dienos foto | D27: =SUM(D20:D25) -> 1 | E27: =SUM(E20:E25) -> 1 | F27: =SUM(F26:K26) -> 0 | L27: =L26 -> 0 | M27: =SUM(M20:M25) -> 0 | N27: =SUM(N20:N25) -> 1 | O27: =SUM(O26) -> 0 | P27: =SUM(P26) -> 0 | T27: =$V$3++L11+L19+L27 -> 11082548
A28: =OFFSET('0'!$B$112,($A$1-1)*10,$B28-1) -> -- | B28: =OFFSET('0'!$B$111,($A$1-1)*10,3) -> 4 | M28: =SUM(D28-E28) -> 0 | N28: =SUM(E28,M28) -> 0
M29: =SUM(D29-E29) -> 0 | N29: =SUM(E29,M29) -> 0
M30: =SUM(D30-E30) -> 0 | N30: =SUM(E30,M30) -> 0
M31: =SUM(D31-E31) -> 0 | N31: =SUM(E31,M31) -> 0
M32: =SUM(D32-E32) -> 0 | N32: =SUM(E32,M32) -> 0
M33: =SUM(D33-E33) -> 0 | N33: =SUM(E33,M33) -> 0
C34: Iš viso Lietuvoje: | D34: =SUM(D28:D33) -> 0 | E34: =SUM(E28:E33) -> 0 | F34: =SUM(F28:F33) -> 0 | G34: =SUM(G28:G33) -> 0 | H34: =SUM(H28:H33) -> 0 | I34: =SUM(I28:I33) -> 0 | J34: =SUM(J28:J33) -> 0 | K34: =SUM(K28:K33) -> 0 | M34: =SUM(M28:M33) -> 0 | N34: =SUM(N28:N33) -> 0
C35: dienos foto | D35: =SUM(D28:D33) -> 0 | E35: =SUM(E28:E33) -> 0 | F35: =SUM(F34:K34) -> 0 | L35: =L34 -> 0 | M35: =SUM(M28:M33) -> 0 | N35: =SUM(N28:N33) -> 0 | O35: =SUM(O34) -> 0 | P35: =SUM(P34) -> 0 | T35: =$V$3+L11+L19+L27+L35 -> 11082548
A36: =OFFSET('0'!$B$112,($A$1-1)*10,$B36-1) -> -- | B36: =OFFSET('0'!$B$111,($A$1-1)*10,4) -> 5 | M36: =SUM(D36-E36) -> 0 | N36: =SUM(E36,M36) -> 0
M37: =SUM(D37-E37) -> 0 | N37: =SUM(E37,M37) -> 0
M38: =SUM(D38-E38) -> 0 | N38: =SUM(E38,M38) -> 0
M39: =SUM(D39-E39) -> 0 | N39: =SUM(E39,M39) -> 0
M40: =SUM(D40-E40) -> 0 | N40: =SUM(E40,M40) -> 0
...

Sheet Liepa
A1: 7
B2: Mėnesio diena | C2: Vardas, pavardė. Pamaina D/N | D2: Paimti ROIK pranešimai (skaičius) | E2: Apdorota | F2: INFORMUOTA | L2: Pasisavintų lėšų suma (visų pranešimų) | M2: Neapdorota (siųstos pajėgos) | N2: Kontrolinis | O2: Tikslinamos aplinkybės (M) | P2: Pradėta IT | Q2: Pastabos | T2: Kontr. Kasdienė eilutė (Žalos)
F3: Bankas | G3: RRT | H3: FNTT | I3: NKSC | J3: Facebook | K3: Kita/įrašyti | U3: Praeitų mėn. Žalos | V3: =SUM('Bendras metų'!V6:V11) -> 11082548
A4: =OFFSET('0'!$B$112,($A$1-1)*10,$B4-1) -> -- | B4: =OFFSET('0'!$B$111,($A$1-1)*10,0) -> 1 | M4: =SUM(D4-E4) -> 0 | N4: =SUM(E4,M4) -> 0
C5: Jurijus Aleksejevas, D. | M5: =SUM(D5-E5) -> 0 | N5: =SUM(E5,M5) -> 0
C6: Laura Mendelienė, D. | M6: =SUM(D6-E6) -> 0 | N6: =SUM(E6,M6) -> 0
C7: Aidas Kiukys, N. | M7: =SUM(D7-E7) -> 0 | N7: =SUM(E7,M7) -> 0
M8: =SUM(D8-E8) -> 0 | N8: =SUM(E8,M8) -> 0
M9: =SUM(D9-E9) -> 0 | N9: =SUM(E9,M9) -> 0
C10: Iš viso Lietuvoje: | D10: =SUM(D4:D9) -> 0 | E10: =SUM(E4:E9) -> 0 | F10: =SUM(F4:F9) -> 0 | G10: =SUM(G4:G9) -> 0 | H10: =SUM(H4:H9) -> 0 | I10: =SUM(I4:I9) -> 0 | J10: =SUM(J4:J9) -> 0 | K10: =SUM(K4:K9) -> 0 | M10: =SUM(M4:M9) -> 0 | N10: =SUM(N4:N9) -> 0
C11: dienos foto | D11: =SUM(D4:D9) -> 0 | E11: =SUM(E4:E9) -> 0 | F11: =SUM(F10:K10) -> 0 | L11: =L10 -> 0 | M11: =SUM(M4:M9) -> 0 | N11: =SUM(N4:N9) -> 0 | O11: =SUM(O10) -> 0 | P11: =SUM(P10) -> 0 | T11: =$V$3+L11 -> 11082548
A12: =OFFSET('0'!$B$112,($A$1-1)*10,$B12-1) -> -- | B12: =OFFSET('0'!$B$111,($A$1-1)*10,1) -> 2 | C12: Aidas Kiukys, N. | M12: =SUM(D12-E12) -> 0 | N12: =SUM(E12,M12) -> 0
M13: =SUM(D13-E13) -> 0 | N13: =SUM(E13,M13) -> 0
M14: =SUM(D14-E14) -> 0 | N14: =SUM(E14,M14) -> 0
M15: =SUM(D15-E15) -> 0 | N15: =SUM(E15,M15) -> 0
M16: =SUM(D16-E16) -> 0 | N16: =SUM(E16,M16) -> 0
M17: =SUM(D17-E17) -> 0 | N17: =SUM(E17,M17) -> 0
C18: Iš viso Lietuvoje: | D18: =SUM(D12:D17) -> 0 | E18: =SUM(E12:E17) -> 0 | F18: =SUM(F12:F17) -> 0 | G18: =SUM(G12:G17) -> 0 | H18: =SUM(H12:H17) -> 0 | I18: =SUM(I12:I17) -> 0 | J18: =SUM(J12:J17) -> 0 | K18: =SUM(K12:K17) -> 0 | M18: =SUM(M12:M17) -> 0 | N18: =SUM(N12:N17) -> 0
C19: dienos foto | D19: =SUM(D12:D17) -> 0 | E19: =SUM(E12:E17) -> 0 | F19: =SUM(F18:K18) -> 0 | L19: =L18 -> 0 | M19: =SUM(M12:M17) -> 0 | N19: =SUM(N12:N17) -> 0 | O19: =SUM(O18) -> 0 | P19: =SUM(P18) -> 0 | T19: =$V$3+L11+L19 -> 11082548
A20: =OFFSET('0'!$B$112,($A$1-1)*10,$B20-1) -> -- | B20: =OFFSET('0'!$B$111,($A$1-1)*10,2) -> 3 | M20: =SUM(D20-E20) -> 0 | N20: =SUM(E20,M20) -> 0
M21: =SUM(D21-E21) -> 0 | N21: =SUM(E21,M21) -> 0
M22: =SUM(D22-E22) -> 0 | N22: =SUM(E22,M22) -> 0
M23: =SUM(D23-E23) -> 0 | N23: =SUM(E23,M23) -> 0
M24: =SUM(D24-E24) -> 0 | N24: =SUM(E24,M24) -> 0
M25: =SUM(D25-E25) -> 0 | N25: =SUM(E25,M25) -> 0
C26: Iš viso Lietuvoje: | D26: =SUM(D20:D25) -> 0 | E26: =SUM(E20:E25) -> 0 | F26: =SUM(F20:F25) -> 0 | G26: =SUM(G20:G25) -> 0 | H26: =SUM(H20:H25) -> 0 | I26: =SUM(I20:I25) -> 0 | J26: =SUM(J20:J25) -> 0 | K26: =SUM(K20:K25) -> 0 | M26: =SUM(M20:M25) -> 0 | N26: =SUM(N20:N25) -> 0
C27: dienos foto | D27: =SUM(D20:D25) -> 0 | E27: =SUM(E20:E25) -> 0 | F27: =SUM(F26:K26) -> 0 | L27: =L26 -> 0 | M27: =SUM(M20:M25) -> 0 | N27: =SUM(N20:N25) -> 0 | O27: =SUM(O26) -> 0 | P27: =SUM(P26) -> 0 | T27: =$V$3++L11+L19+L27 -> 11082548
A28: =OFFSET('0'!$B$112,($A$1-1)*10,$B28-1) -> -- | B28: =OFFSET('0'!$B$111,($A$1-1)*10,3) -> 4 | M28: =SUM(D28-E28) -> 0 | N28: =SUM(E28,M28) -> 0
M29: =SUM(D29-E29) -> 0 | N29: =SUM(E29,M29) -> 0
M30: =SUM(D30-E30) -> 0 | N30: =SUM(E30,M30) -> 0
M31: =SUM(D31-E31) -> 0 | N31: =SUM(E31,M31) -> 0
M32: =SUM(D32-E32) -> 0 | N32: =SUM(E32,M32) -> 0
M33: =SUM(D33-E33) -> 0 | N33: =SUM(E33,M33) -> 0
C34: Iš viso Lietuvoje: | D34: =SUM(D28:D33) -> 0 | E34: =SUM(E28:E33) -> 0 | F34: =SUM(F28:F33) -> 0 | G34: =SUM(G28:G33) -> 0 | H34: =SUM(H28:H33) -> 0 | I34: =SUM(I28:I33) -> 0 | J34: =SUM(J28:J33) -> 0 | K34: =SUM(K28:K33) -> 0 | M34: =SUM(M28:M33) -> 0 | N34: =SUM(N28:N33) -> 0
C35: dienos foto | D35: =SUM(D28:D33) -> 0 | E35: =SUM(E28:E33) -> 0 | F35: =SUM(F34:K34) -> 0 | L35: =L34 -> 0 | M35: =SUM(M28:M33) -> 0 | N35: =SUM(N28:N33) -> 0 | O35: =SUM(O34) -> 0 | P35: =SUM(P34) -> 0 | T35: =$V$3+L11+L19+L27+L35 -> 11082548
A36: =OFFSET('0'!$B$112,($A$1-1)*10,$B36-1) -> SS | B36: =OFFSET('0'!$B$111,($A$1-1)*10,4) -> 5 | M36: =SUM(D36-E36) -> 0 | N36: =SUM(E36,M36) -> 0
M37: =SUM(D37-E37) -> 0 | N37: =SUM(E37,M37) -> 0
M38: =SUM(D38-E38) -> 0 | N38: =SUM(E38,M38) -> 0
M39: =SUM(D39-E39) -> 0 | N39: =SUM(E39,M39) -> 0
M40: =SUM(D40-E40) -> 0 | N40: =SUM(E40,M40) -> 0
...

Sheet Rugpjūtis
A1: 8
B2: Mėnesio diena | C2: Vardas, pavardė. Pamaina D/N | D2: Paimti ROIK pranešimai (skaičius) | E2: Apdorota | F2: INFORMUOTA | L2: Pasisavintų lėšų suma (visų pranešimų) | M2: Neapdorota (siųstos pajėgos) | N2: Kontrolinis | O2: Tikslinamos aplinkybės (M) | P2: Pradėta IT | Q2: Pastabos | T2: Kontr. Kasdienė eilutė (Žalos)
F3: Bankas | G3: RRT | H3: FNTT | I3: NKSC | J3: Facebook | K3: Kita/įrašyti | U3: Praeitų mėn. Žalos | V3: =SUM('Bendras metų'!V6:V12) -> 11082548
A4: =OFFSET('0'!$B$112,($A$1-1)*10,$B4-1) -> -- | B4: =OFFSET('0'!$B$111,($A$1-1)*10,0) -> 1 | C4: Jurijus Aleksej, N. | M4: =SUM(D4-E4) -> 0 | N4: =SUM(E4,M4) -> 0
M5: =SUM(D5-E5) -> 0 | N5: =SUM(E5,M5) -> 0
M6: =SUM(D6-E6) -> 0 | N6: =SUM(E6,M6) -> 0
M7: =SUM(D7-E7) -> 0 | N7: =SUM(E7,M7) -> 0
M8: =SUM(D8-E8) -> 0 | N8: =SUM(E8,M8) -> 0
M9: =SUM(D9-E9) -> 0 | N9: =SUM(E9,M9) -> 0
C10: Iš viso Lietuvoje: | D10: =SUM(D4:D9) -> 0 | E10: =SUM(E4:E9) -> 0 | F10: =SUM(F4:F9) -> 0 | G10: =SUM(G4:G9) -> 0 | H10: =SUM(H4:H9) -> 0 | I10: =SUM(I4:I9) -> 0 | J10: =SUM(J4:J9) -> 0 | K10: =SUM(K4:K9) -> 0 | M10: =SUM(M4:M9) -> 0 | N10: =SUM(N4:N9) -> 0
C11: dienos foto | D11: =SUM(D4:D9) -> 0 | E11: =SUM(E4:E9) -> 0 | F11: =SUM(F10:K10) -> 0 | L11: =L10 -> 0 | M11: =SUM(M4:M9) -> 0 | N11: =SUM(N4:N9) -> 0 | O11: =SUM(O10) -> 0 | P11: =SUM(P10) -> 0 | T11: =$V$3+L11 -> 11082548
A12: =OFFSET('0'!$B$112,($A$1-1)*10,$B12-1) -> SS | B12: =OFFSET('0'!$B$111,($A$1-1)*10,1) -> 2 | M12: =SUM(D12-E12) -> 0 | N12: =SUM(E12,M12) -> 0
M13: =SUM(D13-E13) -> 0 | N13: =SUM(E13,M13) -> 0
M14: =SUM(D14-E14) -> 0 | N14: =SUM(E14,M14) -> 0
M15: =SUM(D15-E15) -> 0 | N15: =SUM(E15,M15) -> 0
M16: =SUM(D16-E16) -> 0 | N16: =SUM(E16,M16) -> 0
M17: =SUM(D17-E17) -> 0 | N17: =SUM(E17,M17) -> 0
C18: Iš viso Lietuvoje: | D18: =SUM(D12:D17) -> 0 | E18: =SUM(E12:E17) -> 0 | F18: =SUM(F12:F17) -> 0 | G18: =SUM(G12:G17) -> 0 | H18: =SUM(H12:H17) -> 0 | I18: =SUM(I12:I17) -> 0 | J18: =SUM(J12:J17) -> 0 | K18: =SUM(K12:K17) -> 0 | M18: =SUM(M12:M17) -> 0 | N18: =SUM(N12:N17) -> 0
C19: dienos foto | D19: =SUM(D12:D17) -> 0 | E19: =SUM(E12:E17) -> 0 | F19: =SUM(F18:K18) -> 0 | L19: =L18 -> 0 | M19: =SUM(M12:M17) -> 0 | N19: =SUM(N12:N17) -> 0 | O19: =SUM(O18) -> 0 | P19: =SUM(P18) -> 0 | T19: =$V$3+L11+L19 -> 11082548
A20: =OFFSET('0'!$B$112,($A$1-1)*10,$B20-1) -> SK | B20: =OFFSET('0'!$B$111,($A$1-1)*10,2) -> 3 | M20: =SUM(D20-E20) -> 0 | N20: =SUM(E20,M20) -> 0
M21: =SUM(D21-E21) -> 0 | N21: =SUM(E21,M21) -> 0
M22: =SUM(D22-E22) -> 0 | N22: =SUM(E22,M22) -> 0
M23: =SUM(D23-E23) -> 0 | N23: =SUM(E23,M23) -> 0
M24: =SUM(D24-E24) -> 0 | N24: =SUM(E24,M24) -> 0
M25: =SUM(D25-E25) -> 0 | N25: =SUM(E25,M25) -> 0
C26: Iš viso Lietuvoje: | D26: =SUM(D20:D25) -> 0 | E26: =SUM(E20:E25) -> 0 | F26: =SUM(F20:F25) -> 0 | G26: =SUM(G20:G25) -> 0 | H26: =SUM(H20:H25) -> 0 | I26: =SUM(I20:I25) -> 0 | J26: =SUM(J20:J25) -> 0 | K26: =SUM(K20:K25) -> 0 | M26: =SUM(M20:M25) -> 0 | N26: =SUM(N20:N25) -> 0
